Workbook

Sheet README
B2: Blockmediary — 5-Year Financial Model, Launch Path & Runway
B3: Programmable documentary escrow for SME cross-border trade. UAE launch-path and commercial refresh: 11 Aug 2026.
B5: TABLE OF CONTENTS | D5: Tabs are ordered the way the business reads: what it is, whether we can trade, how it earns, whether it works.
B6: Click any tab name to jump to it.
B7: START HERE
B8: 1 | C8: README | D8: Orientation, table of contents, open issues.
B9: 2 | C9: Dashboard | D9: The headline: raise, break-even, path to profitability.
B11: CAN WE TRADE, AND WHEN
B12: 3 | C12: Launch Readiness | D12: DIFC partner-led pilot timing, VARA scale stage, fees and restricted capital.
B14: HOW THE MONEY IS MADE
B15: 4 | C15: Tier Economics | D15: Revenue and cost per deal, split by document verification tier.
B16: 5 | C16: Revenue Risk Add-Ons | D16: Add-on revenue streams and the retained-risk costs set against them.
B18: DOES IT WORK
B19: 6 | C19: P&L 5yr | D19: Five-year profit and loss for the active scenario and launch path.
B20: 7 | C20: Cash Flow Statement | D20: 60-month cash flow: runway, funding, break-even month.
B21: 8 | C21: Scenario Engine | D21: Low / Base / High side by side. How wide is the range of outcomes.
B23: WHAT IT RESTS ON
B24: 9 | C24: Assumptions | D24: Every input in the model. The control panel — edit blue cells here.
B25: 10 | C25: Startup 6mo | D25: One-off launch spend before the business is trading.
B26: 11 | C26: Sensitivity | D26: Ranked view of the assumptions that most affect funding, margin and growth.
B27: 12 | C27: Risk Register | D27: Key legal, regulatory, commercial and operating assumptions that still need validation.
B28: 13 | C28: Driver Tables | D28: Research ranges and source notes supporting the model's cost and revenue inputs.
B30: SUPPORTING CHECKS & APPENDICES
B31: 14 | C31: Model Checks | D31: Mechanical tie-outs; must read PASS before figures are used.
B32: 15 | C32: Client Funds Memo | D32: Safeguarded client-funds balances and holding-period sensitivity; excluded from operating cash.
B40: SCOPE
B41: Blockmediary is a documentary escrow and document-verification service. It is not a lending or financing product.
B42: This workbook is an indicative university idea-presentation model, not a business-loan application, regulatory filing, legal opinion or investment commitment.
B43: Amounts are readable planning approximations. Client funds remain safeguarded and excluded from operating cash, revenue and runway.
B45: HOW TO USE
B46: 1. Edit blue inputs in Assumptions and Launch Readiness. Yellow cells are key presentation controls; formulas and linked values update automatically.
B47: 2. Assumptions!C4 selects commercial performance: 1=Low, 2=Base, 3=High. The delivered presentation default is Base.
B48: 3. Launch Readiness!B5 selects timing: 1=Early, 2=Base, 3=Delayed. The route is fixed as DIFC partner-led pilot followed by VARA expansion.
B49: 4. Startup 6mo holds core pre-revenue build costs. Launch Readiness separately times partner/DIFC pilot costs, future VARA fees and restricted capital.
B50: 5. P&L 5yr, Cash Flow Statement and Model Checks provide economics, runway and integrity; supporting tabs retain sources, sensitivities, risks and safeguarding detail.
B52: CURRENCY
B53: Model base currency = GBP (£). USD-priced vendors (Anthropic, AWS, Vercel, KYC, gas) are converted at the FX rate in Assumptions (GBPUSD).
... B64: • Confirm the final regulatory perimeter, custody/settlement responsibilities and partner fees with UAE counsel and the regulated partner.

Sheet Dashboard
B2: ■ FINANCIAL MODEL DASHBOARD
B4: The base case funds a partner-led DIFC pilot in Month 12, with VARA expansion and restricted capital shown separately.
B6: Base cases shown. Inputs: Assumptions!C4 and Launch Readiness!B5. Y4/Y5 acquisition intensity is flagged in P&L 5yr.
R9: Pitch deck metrics linked to model
C10: ="£"&ROUND('Launch Readiness'!$E$12/1000000,1)&"m" -> £2.8m | G10: ="Month "&'Launch Readiness'!$E$6 -> Month 12 | K10: ="£"&ROUND(AVERAGE(S38,S37,S36),0) -> £688 | O10: ="£"&ROUND('P&L 5yr'!$G$18/1000000,1)&"m" -> £17.8m | R10: Slide | S10: Metric | T10: Model value | U10: Pitch-copy output | V10: Source / model link | W10: Deck slot
C11: Initial operating funding need (3-month reserve) | G11: First paying pilot customer | K11: Projected Steady State CAC | O11: Y5 annual revenue — Base commercial case | R11: 7 | S11: Settlement fee range | T11: =ROUND(MIN(Assumptions!$F$70:$F$72)*100,1)&"%-"&ROUND(MAX(Assumptions!$F$70:$F$72)*100,1)&"%" -> 0.8%-3% | U11: =T11&" per trade, tier-dependent" -> 0.8%-3% per trade, tier-dependent | V11: Assumptions!F73:F75 | W11: Business model card A
C12: monthly operating deficit plus reserve; future VARA capital excluded | G12: Base partner-led DIFC pilot timing | K12: AI-enabled staffing ramp targets <=250 gross new customers per Sales/BD/CS FTE | O12: accepted commercial assumptions and UAE launch timing | R12: 7 | S12: Blended gross margin | T12: =ROUND('Scenario Engine'!$H$49*100,0)&"%-"&ROUND('Scenario Engine'!$L$49*100,0)&"%" -> 71%-79% | U12: =T12&" blended gross margin, base Y1-Y5" -> 71%-79% blended gross margin, base Y1-Y5 | V12: Scenario Engine!$H$49:$L$49 | W12: Bottom KPI
C13: Base path to profitability (£m) | K13: Funding stack (£m) | R13: 7 | S13: Average ticket | T13: ="GBP "&ROUND('Scenario Engine'!$H$9/1000,0)&"K -> GBP "&ROUND('Scenario Engine'!$J$9/1000,0)&"K" -> GBP 31K -> GBP 38K | U13: =T13&" average ticket, Y1 to Y3; GBP "&ROUND('Scenario Engine'!$L$9/1000,0)&"K by Y5" -> GBP 31K -> GBP 38K average ticket, Y1 to Y3; GBP 48K by Y5 | V13: Scenario Engine!$H$9:$L$9 | W13: Bottom KPI
B14: Revenue and EBITDA in GBP millions, Base commercial case. | C14: Revenue scales before the payroll/opex curve catches up. | I14: Initial funding stack in GBP millions; future VARA capital is excluded. | K14: Monthly-model deficit, reserve and restricted capital. | R14: 7 | S14: Processed deals | T14: =ROUND('Scenario Engine'!$H$8,0)&" -> "&ROUND('Scenario Engine'!$J$8,0) -> 3 -> 2000 | U14: =T14&" processed deals, Y1 to Y3 base case" -> 3 -> 2000 processed deals, Y1 to Y3 base case | V14: Scenario Engine!$H$8:$J$8 | W14: Bottom KPI
R15: 11 | S15: Y3 annual revenue range | T15: ="GBP "&ROUND('Scenario Engine'!$D$30/1000000,1)&"M-"&ROUND('Scenario Engine'!$P$30/1000000,1)&"M" -> GBP 1.1M-1.9M | U15: =T15&" Y3 annual revenue; base GBP "&ROUND('Scenario Engine'!$J$30/1000000,1)&"M" -> GBP 1.1M-1.9M Y3 annual revenue; base GBP 1.4M | V15: Scenario Engine!D30/J30/P30 | W15: Top KPI card
R16: 11 | S16: Y3 active customers range | T16: =ROUND('Scenario Engine'!$D$62,0)&"-"&ROUND('Scenario Engine'!$P$62,0) -> 480-320 | U16: =T16&" Y3 active customers; base "&ROUND('Scenario Engine'!$J$62,0) -> 480-320 Y3 active customers; base 333 | V16: Scenario Engine!D62/J62/P62 | W16: Top KPI card
R17: 11 | S17: Monthly cash-flow breakeven | T17: ='Cash Flow Statement'!$B$46 -> Y4 M8 | U17: ="Base monthly cash-flow break-even: "&T17&"; scenario range "&'Cash Flow Statement'!$B$47&" to "&'Cash Flow Statement'!$B$45 -> Base monthly cash-flow break-even: Y4 M8; scenario range Y4 M4 to Beyond Month 60 | V17: Cash Flow Statement!B45:B47 | W17: Top KPI card
R18: 11 | S18: Initial funding need | T18: ="GBP "&ROUND('Launch Readiness'!$E$12/1000000,2)&"M" -> GBP 2.84M | U18: =T18&" initial operating funding; future VARA capital shown separately" -> GBP 2.84M initial operating funding; future VARA capital shown separately | V18: Launch Readiness!F12 | W18: Top KPI card
R19: 11 | S19: Blended escrow take rate | T19: =IFERROR(ROUND('Tier Economics'!$E$12/'Tier Economics'!$E$9*100,1)&"% / "&ROUND('Tier Economics'!$M$12/'Tier Economics'!$M$9*100,1)&"% / "&ROUND('Tier Economics'!$U$12/'Tier Economics'!$U$9*100,1)&"%","n/a - no Year 1 volume on this launch path") -> 2% / 1.3% / 1% | U19: =IFERROR(IF(LEFT(T19,3)="n/a",T19,T19&" blended escrow take rate, base Y1 / Y3 / Y5"),"n/a - no Year 1 volume on this launch path") -> 2% / 1.3% / 1% blended escrow take rate, base Y1 / Y3 / Y5 | V19: Tier Economics total escrow fee / GMV | W19: Key assumptions
R20: 11 | S20: Tier A adoption | T20: =ROUND(Assumptions!$D$61*100,0)&"% -> "&ROUND(Assumptions!$D$152*100,0)&"%" -> 15% -> 70% | U20: =T20&" Tier A eBL mix, base Y1 to Y5" -> 15% -> 70% Tier A eBL mix, base Y1 to Y5 | V20: Assumptions!D64,D160 | W20: Key assumptions
R21: 13 | S21: Initial operating funding | T21: ="GBP "&ROUND('Launch Readiness'!$E$12/1000000,2)&"M" -> GBP 2.84M | U21: =T21&" initial operating funding need" -> GBP 2.84M initial operating funding need | V21: Launch Readiness!F12 | W21: Total seed raise
C22: Monthly cumulative operating cash (£m) | R22: 13 | S22: Engineering & product | T22: =ROUND($M$58*100,0)&"% GBP "&ROUND($L$58/1000,0)&"K" -> 19% GBP 532K | U22: =T22 -> 19% GBP 532K | V22: Dashboard!J58:M58 | W22: Use of funds
B23: Ending cash balance in GBP millions at 6-month checkpoints. | C23: Six-month checkpoints avoid unreadable 60-label charts. | K23: Scenario readout | R23: 13 | S23: Ops, people & G&A | T23: =ROUND($M$59*100,0)&"% GBP "&ROUND($L$59/1000,0)&"K" -> 35% GBP 991K | U23: =T23 -> 35% GBP 991K | V23: Dashboard!J59:M59 | W23: Use of funds
J24: Break-even timing and funding gap by scenario. | K24: Break-even timing and funding gap by case. | R24: 13 | S24: Compliance, legal & regulatory | T24: =ROUND($M$60*100,0)&"% GBP "&ROUND($L$60/1000,0)&"K" -> 34% GBP 967K | U24: =T24 -> 34% GBP 967K | V24: Dashboard!J60:M60 | W24: Use of funds
J25: Case | K25: Monthly BE | L25: Peak gap | M25: M60 cash | N25: Funding ask | R25: 13 | S25: GTM & acquisition | T25: =ROUND($M$61*100,0)&"% GBP "&ROUND($L$61/1000,0)&"K" -> 6% GBP 159K | U25: =T25 -> 6% GBP 159K | V25: Dashboard!J61:M61 | W25: Use of funds
J26: Low | K26: ='Cash Flow Statement'!B45 -> Beyond Month 60 | L26: ='Cash Flow Statement'!C45/1000000 -> 3.915862 | M26: ='Cash Flow Statement'!D45/1000000 -> -2.924278 | N26: ='Cash Flow Statement'!F45/1000000 -> 4.106889 | R26: 13 | S26: Working capital + contingency | T26: =ROUND($M$62*100,0)&"% GBP "&ROUND($L$62/1000,0)&"K" -> 7% GBP 191K | U26: =T26 -> 7% GBP 191K | V26: Dashboard!J62:M62 | W26: Use of funds
J27: Base | K27: ='Cash Flow Statement'!B46 -> Y4 M8 | L27: ='Cash Flow Statement'!C46/1000000 -> 2.649418 | M27: ='Cash Flow Statement'!D46/1000000 -> 12.947967 | N27: ='Cash Flow Statement'!F46/1000000 -> 2.840446 | R27: 13 | S27: Future VARA restricted capital | T27: ="GBP "&ROUND('Launch Readiness'!$E$17/1000,0)&"K" -> GBP 319K | U27: =T27&" future scale-stage restricted capital; excluded from initial operating ask" -> GBP 319K future scale-stage restricted capital; excluded from initial operating ask | V27: Launch Readiness!F17 | W27: Scale-stage callout
J28: High | K28: ='Cash Flow Statement'!B47 -> Y4 M4 | L28: ='Cash Flow Statement'!C47/1000000 -> 1.946199 | M28: ='Cash Flow Statement'!D47/1000000 -> 33.92171 | N28: ='Cash Flow Statement'!F47/1000000 -> 2.137226
J29: ="- Base reaches monthly cash-flow break-even in "&'Cash Flow Statement'!$B$46&"; High reaches "&'Cash Flow Statement'!$B$47&"." -> - Base reaches monthly cash-flow break-even in Y4 M8; High reaches Y4 M4.
J30: ="- Low reaches monthly cash-flow break-even in "&'Cash Flow Statement'!$B$45&"; base Month 60 operating cash is GBP "&ROUND('Cash Flow Statement'!$D$46/1000000,1)&"M." -> - Low reaches monthly cash-flow break-even in Beyond Month 60; base Month 60 operating cash is GBP 12.9M. | R30: IMPLIED CUSTOMER ACQUISITION COST — FIVE-YEAR VIEW
J31: • No lending spread, FX trading revenue, or balance-sheet credit risk is modelled. | R31: Loaded Sales/BD/CS compensation + marketing + CRM ÷ gross new customers. Y1 includes the launch build-out.
J32: • Tier C paper collection is a priced fallback, not the strategic scale path.
J33: • Base Y4/Y5 volume is a planning target; acquisition capacity is flagged in P&L 5yr. | R33: Year | S33: Implied CAC | V33: Gross new customers | X33: New customers / Sales FTE | Z33: Capacity readout
R34: Y1 | S34: =IFERROR((('P&L 5yr'!C$36*Assumptions!$F$51*('P&L 5yr'!C$42/'P&L 5yr'!C$38))+'P&L 5yr'!C$49+'P&L 5yr'!C$53)/'P&L 5yr'!C$83,0) -> 50632.764 | V34: ='P&L 5yr'!C$83 -> 1 | X34: =IFERROR('P&L 5yr'!C$83/'P&L 5yr'!C$36,0) -> 3 | Z34: =IF(X34>Assumptions!$F$182,"Above capacity","Within capacity") -> Within capacity
R35: Y2 | S35: =IFERROR((('P&L 5yr'!D$36*Assumptions!$F$51*('P&L 5yr'!D$42/'P&L 5yr'!D$38))+'P&L 5yr'!D$49+'P&L 5yr'!D$53)/'P&L 5yr'!D$83,0) -> 1458.5782 | V35: ='P&L 5yr'!D$83 -> 124.1 | X35: =IFERROR('P&L 5yr'!D$83/'P&L 5yr'!D$36,0) -> 62.05 | Z35: =IF(X35>Assumptions!$F$182,"Above capacity","Within capacity") -> Within capacity
R36: Y3 | S36: =IFERROR((('P&L 5yr'!E$36*Assumptions!$F$51*('P&L 5yr'!E$42/'P&L 5yr'!E$38))+'P&L 5yr'!E$49+'P&L 5yr'!E$53)/'P&L 5yr'!E$83,0) -> 1231.8872 | V36: ='P&L 5yr'!E$83 -> 220.83333 | X36: =IFERROR('P&L 5yr'!E$83/'P&L 5yr'!E$36,0) -> 73.611111 | Z36: =IF(X36>Assumptions!$F$182,"Above capacity","Within capacity") -> Within capacity
R37: Y4 | S37: =IFERROR((('P&L 5yr'!F$36*Assumptions!$F$51*('P&L 5yr'!F$42/'P&L 5yr'!F$38))+'P&L 5yr'!F$49+'P&L 5yr'!F$53)/'P&L 5yr'!F$83,0) -> 346.62475 | V37: ='P&L 5yr'!F$83 -> 1575 | X37: =IFERROR('P&L 5yr'!F$83/'P&L 5yr'!F$36,0) -> 225 | Z37: =IF(X37>Assumptions!$F$182,"Above capacity","Within capacity") -> Within capacity
R38: Y5 | S38: =IFERROR((('P&L 5yr'!G$36*Assumptions!$F$51*('P&L 5yr'!G$42/'P&L 5yr'!G$38))+'P&L 5yr'!G$49+'P&L 5yr'!G$53)/'P&L 5yr'!G$83,0) -> 485.56011 | V38: ='P&L 5yr'!G$83 -> 1312.5 | X38: =IFERROR('P&L 5yr'!G$83/'P&L 5yr'!G$36,0) -> 164.0625 | Z38: =IF(X38>Assumptions!$F$182,"Above capacity","Within capacity") -> Within capacity
R39: Y1 is intentionally high: one acquired customer carries the launch-year commercial build-out.
R40: Planning cross-check, not observed CAC. AI-enabled staffing ramp targets <=250 gross new customers per Sales/BD/CS FTE (Assumptions C191:G191).
B56: Base path helper | F56: Use of funds helper | J56: Use of funds allocation helper
B57: Year | C57: Revenue | D57: EBITDA | F57: Category | G57: Amount | J57: Category | K57: Pre-scale cost driver | L57: Amount | M57: Share
B58: Y1 | C58: ='Scenario Engine'!$H$30/1000000 -> 0.00244905 | D58: ='Scenario Engine'!$H$57/1000000 -> -0.76236644 | F58: Peak operating deficit | G58: ='Cash Flow Statement'!$H$4/1000000 -> 2.649419 | J58: Engineering & product | K58: =SUM('P&L 5yr'!$C$34:$E$34)*Assumptions!$F$50+SUM('P&L 5yr'!$C$44:$E$47)+SUM('Startup 6mo'!$F$23:$F$28) -> 689360 | L58: =MAX(0,'Launch Readiness'!$E$12-$L$62)*K58/SUM($K$58:$K$61) -> 532484.9 | M58: =L58/'Launch Readiness'!$E$12 -> 0.18746524
B59: Y2 | C59: ='Scenario Engine'!$I$30/1000000 -> 0.404549 | D59: ='Scenario Engine'!$I$57/1000000 -> -0.83424883 | F59: Operating reserve | G59: ='P&L 5yr'!$G$65/1000000 -> 0.191027 | J59: Ops, people & G&A | K59: =SUM('P&L 5yr'!$C$33:$E$33)*Assumptions!$F$49+SUM('P&L 5yr'!$C$39:$E$41)+SUM('P&L 5yr'!$C$48:$E$48,'P&L 5yr'!$C$50:$E$50,'P&L 5yr'!$C$54:$E$55)+SUM('Startup 6mo'!$F$7:$F$10,'Startup 6mo'!$F$37:$F$39) -> 1282926.3 | L59: =MAX(0,'Launch Readiness'!$E$12-$L$62)*K59/SUM($K$58:$K$61) -> 990975.54 | M59: =L59/'Launch Readiness'!$E$12 -> 0.34888026
B60: Y3 | C60: ='Scenario Engine'!$J$30/1000000 -> 1.387904 | D60: ='Scenario Engine'!$J$57/1000000 -> -0.37845458 | F60: Initial restricted capital | G60: ='Launch Readiness'!$E$10/1000000 -> 0 | J60: Compliance, legal & regulatory | K60: =SUM('P&L 5yr'!$C$35:$E$35)*Assumptions!$F$51+SUM('P&L 5yr'!$C$51:$E$52)+SUM('Startup 6mo'!$F$12:$F$21) -> 1251615.8 | L60: =MAX(0,'Launch Readiness'!$E$12-$L$62)*K60/SUM($K$58:$K$61) -> 966790.25 | M60: =L60/'Launch Readiness'!$E$12 -> 0.34036565
...

Sheet Launch Readiness
A1: LAUNCH READINESS — DIFC PARTNER PILOT TO VARA SCALE
A2: Presentation planning model. Base case assumes a paid partner-led DIFC pilot in Month 12 and later VARA expansion; all permissions and fees remain subject to UAE counsel, partner and regulator confirmation.
A4: DECISION INPUTS | D4: ACTIVE BASE-CASE OUTPUTS
A5: Timing case (1=Early, 2=Base, 3=Delayed) | B5: 2 | D5: Route | E5: DIFC partner-led pilot → VARA expansion
A6: Operating reserve (months) | B6: 3 | D6: First paying pilot | E6: =MAX($C$50:$C$55)+1 -> 12
A7: Cash receipt lag (months) | B7: 1 | D7: Pre-revenue period | E7: =MAX(0,$E$6-1) -> 11
A8: DIFC / regulated-partner pilot one-off (£)**** | B8: 60000 | D8: Pilot regulatory / onboarding one-off | E8: =$B$8 -> 60000
A9: Partner-pilot annual fees and oversight (£)**** | B9: 67000 | D9: Pilot annual partner / regulatory run-rate | E9: =$B$9 -> 67000
A10: Pre-pilot share of partner run-rate | B10: 0.35 | D10: Initial restricted capital | E10: =0 -> 0
A11: Partner onboarding / application start month | B11: 2 | D11: First cash receipt | E11: =$E$6+$B$7 -> 13
A12: VARA application fee placeholder* (AED) | B12: 200000 | D12: Initial operating funding need | E12: =ROUND(MAX('P&L 5yr'!$C$66:$G$66)+$E$10,0) -> 2840446
A13: VARA annual supervision placeholder** (AED) | B13: 480000 | D13: Average pre-revenue operating burn | E13: =ROUND(-SUM('Cash Flow Statement'!$B$19:INDEX('Cash Flow Statement'!$B$19:$BI$19,1,MAX(1,$E$7)))/MAX(1,$E$7),0) -> 90941
A14: VARA restricted-capital placeholder*** (AED) | B14: 1500000 | D14: VARA scale target | E14: =INDEX($F$21:$F$23,$B$5) -> 30 | F14: VARA application start | G14: =INDEX($G$21:$G$23,$B$5) -> 18
A15: AED per USD***** | B15: 3.6725 | D15: Future VARA application fees | E15: =ROUND($B$12/(Assumptions!$F$8*$B$15),0) -> 42546
D16: Future VARA annual supervision | E16: =ROUND($B$13/(Assumptions!$F$8*$B$15),0) -> 102110
D17: Future VARA restricted capital | E17: =ROUND($B$14/(Assumptions!$F$8*$B$15),0) -> 319095
A19: TIMING CASES — ONE SEQUENTIAL UAE ROUTE
A20: Case | B20: Timing | C20: Latest pilot gate finish | D20: First paid pilot | E20: First receipt | F20: VARA target | G20: VARA application start | H20: Planning interpretation
A21: 1 | B21: Early | C21: 8 | D21: =C21+1 -> 9 | E21: =D21+$B$7 -> 10 | F21: 24 | G21: 12 | H21: Sensitivity: faster partner and regulator approvals.
A22: 2 | B22: Base | C22: 11 | D22: =C22+1 -> 12 | E22: =D22+$B$7 -> 13 | F22: 30 | G22: 18 | H22: Presentation base: one year to first paid pilot, then VARA scale.
A23: 3 | B23: Delayed | C23: 17 | D23: =C23+1 -> 18 | E23: =D23+$B$7 -> 19 | F23: 36 | G23: 24 | H23: Sensitivity: rework, partner conditions or regulatory delay.
A24: LAUNCH PHASING BY MODEL YEAR
A25: Metric | B25: Year 1 | C25: Year 2 | D25: Year 3 | E25: Year 4 | F25: Year 5
A26: Revenue-active months | B26: =MAX(0,MIN(12,12*(COLUMN()-1)-$E$6+1)) -> 1 | C26: =MAX(0,MIN(12,12*(COLUMN()-1)-$E$6+1)) -> 12 | D26: =MAX(0,MIN(12,12*(COLUMN()-1)-$E$6+1)) -> 12 | E26: =MAX(0,MIN(12,12*(COLUMN()-1)-$E$6+1)) -> 12 | F26: =MAX(0,MIN(12,12*(COLUMN()-1)-$E$6+1)) -> 12
A27: Pre-revenue months | B27: =MAX(0,MIN(12,$E$7-12*(COLUMN()-2))) -> 11 | C27: =MAX(0,MIN(12,$E$7-12*(COLUMN()-2))) -> 0 | D27: =MAX(0,MIN(12,$E$7-12*(COLUMN()-2))) -> 0 | E27: =MAX(0,MIN(12,$E$7-12*(COLUMN()-2))) -> 0 | F27: =MAX(0,MIN(12,$E$7-12*(COLUMN()-2))) -> 0
A28: Revenue activity factor | B28: =B26/12 -> 0.083333333 | C28: =C26/12 -> 1 | D28: =D26/12 -> 1 | E28: =E26/12 -> 1 | F28: =F26/12 -> 1 | G28: 0
A29: Partner / application phase months | B29: =MAX(0,MIN(12*(COLUMN()-1),$E$6-1)-MAX(12*(COLUMN()-2)+1,$B$11)+1) -> 10 | C29: =MAX(0,MIN(12*(COLUMN()-1),$E$6-1)-MAX(12*(COLUMN()-2)+1,$B$11)+1) -> 0 | D29: =MAX(0,MIN(12*(COLUMN()-1),$E$6-1)-MAX(12*(COLUMN()-2)+1,$B$11)+1) -> 0 | E29: =MAX(0,MIN(12*(COLUMN()-1),$E$6-1)-MAX(12*(COLUMN()-2)+1,$B$11)+1) -> 0 | F29: =MAX(0,MIN(12*(COLUMN()-1),$E$6-1)-MAX(12*(COLUMN()-2)+1,$B$11)+1) -> 0 | G29: 0
A30: Pre-pilot partner cost factor | B30: =B29/12 -> 0.83333333 | C30: =C29/12 -> 0 | D30: =D29/12 -> 0 | E30: =E29/12 -> 0 | F30: =F29/12 -> 0 | G30: 0
A31: VARA operating months | B31: =MAX(0,MIN(12,12*(COLUMN()-1)-$E$14+1)) -> 0 | C31: =MAX(0,MIN(12,12*(COLUMN()-1)-$E$14+1)) -> 0 | D31: =MAX(0,MIN(12,12*(COLUMN()-1)-$E$14+1)) -> 7 | E31: =MAX(0,MIN(12,12*(COLUMN()-1)-$E$14+1)) -> 12 | F31: =MAX(0,MIN(12,12*(COLUMN()-1)-$E$14+1)) -> 12 | G31: 0
A32: VARA annual fee factor | B32: =B31/12 -> 0 | C32: =C31/12 -> 0 | D32: =D31/12 -> 0.58333333 | E32: =E31/12 -> 1 | F32: =F31/12 -> 1
A33: VARA application fee timing | B33: =IF(AND($G$14>=12*(COLUMN()-2)+1,$G$14<=12*(COLUMN()-1)),1,0) -> 0 | C33: =IF(AND($G$14>=12*(COLUMN()-2)+1,$G$14<=12*(COLUMN()-1)),1,0) -> 1 | D33: =IF(AND($G$14>=12*(COLUMN()-2)+1,$G$14<=12*(COLUMN()-1)),1,0) -> 0 | E33: =IF(AND($G$14>=12*(COLUMN()-2)+1,$G$14<=12*(COLUMN()-1)),1,0) -> 0 | F33: =IF(AND($G$14>=12*(COLUMN()-2)+1,$G$14<=12*(COLUMN()-1)),1,0) -> 0
A34: Partner-pilot annual fee factor | B34: =MAX(0,B26-B31)/12 -> 0.083333333 | C34: =MAX(0,C26-C31)/12 -> 1 | D34: =MAX(0,D26-D31)/12 -> 0.41666667 | E34: =MAX(0,E26-E31)/12 -> 0 | F34: =MAX(0,F26-F31)/12 -> 0
A36: WORKFORCE TIMING — EXPLICIT AND INDEPENDENT OF LAUNCH DATE
A37: Role | B37: Start month | C37: Cost treatment | D37: Year 1 | E37: Year 2 | F37: Year 3 | G37: Year 4 | H37: Year 5
A38: Founders | B38: 1 | C38: Core team from Month 1 | D38: =MAX(0,MIN(12,12*(COLUMN()-3)-$B38+1))/12 -> 1 | E38: =MAX(0,MIN(12,12*(COLUMN()-3)-$B38+1))/12 -> 1 | F38: =MAX(0,MIN(12,12*(COLUMN()-3)-$B38+1))/12 -> 1 | G38: =MAX(0,MIN(12,12*(COLUMN()-3)-$B38+1))/12 -> 1 | H38: =MAX(0,MIN(12,12*(COLUMN()-3)-$B38+1))/12 -> 1
A39: Engineering | B39: 5 | C39: Production hardening; not delayed by launch case | D39: =MAX(0,MIN(12,12*(COLUMN()-3)-$B39+1))/12 -> 0.66666667 | E39: =MAX(0,MIN(12,12*(COLUMN()-3)-$B39+1))/12 -> 1 | F39: =MAX(0,MIN(12,12*(COLUMN()-3)-$B39+1))/12 -> 1 | G39: =MAX(0,MIN(12,12*(COLUMN()-3)-$B39+1))/12 -> 1 | H39: =MAX(0,MIN(12,12*(COLUMN()-3)-$B39+1))/12 -> 1
A40: Compliance | B40: 1 | C40: Internal control ownership from Month 1 | D40: =MAX(0,MIN(12,12*(COLUMN()-3)-$B40+1))/12 -> 1 | E40: =MAX(0,MIN(12,12*(COLUMN()-3)-$B40+1))/12 -> 1 | F40: =MAX(0,MIN(12,12*(COLUMN()-3)-$B40+1))/12 -> 1 | G40: =MAX(0,MIN(12,12*(COLUMN()-3)-$B40+1))/12 -> 1 | H40: =MAX(0,MIN(12,12*(COLUMN()-3)-$B40+1))/12 -> 1
A41: Sales | B41: 9 | C41: Pilot contracting and commercial preparation | D41: =MAX(0,MIN(12,12*(COLUMN()-3)-$B41+1))/12 -> 0.33333333 | E41: =MAX(0,MIN(12,12*(COLUMN()-3)-$B41+1))/12 -> 1 | F41: =MAX(0,MIN(12,12*(COLUMN()-3)-$B41+1))/12 -> 1 | G41: =MAX(0,MIN(12,12*(COLUMN()-3)-$B41+1))/12 -> 1 | H41: =MAX(0,MIN(12,12*(COLUMN()-3)-$B41+1))/12 -> 1
A48: CUSTOMER-LAUNCH CRITICAL PATH
A49: Workstream | B49: Start month | C49: Finish month | D49: Customer-blocking? | E49: Readout
...

Sheet Tier Economics
A1: Tier Economics - revenue, cost and risk by document-intake tier
A3: Metric | B3: Tier A eBL Y1 | C3: Tier B API Y1 | D3: Tier C Paper Y1 | E3: Total Y1 | F3: Tier A eBL Y2 | G3: Tier B API Y2 | H3: Tier C Paper Y2 | I3: Total Y2 | J3: Tier A eBL Y3 | K3: Tier B API Y3 | L3: Tier C Paper Y3 | M3: Total Y3 | N3: Tier A eBL Y4 | O3: Tier B API Y4 | P3: Tier C Paper Y4 | Q3: Total Y4 | R3: Tier A eBL Y5 | S3: Tier B API Y5 | T3: Tier C Paper Y5 | U3: Total Y5
A4: Tier mix | B4: =Assumptions!$F$61 -> 0.15 | C4: =Assumptions!$F$62 -> 0.45 | D4: =Assumptions!$F$63 -> 0.4 | E4: =SUM(B4:D4) -> 1 | F4: =Assumptions!$F$64 -> 0.3 | G4: =Assumptions!$F$65 -> 0.45 | H4: =Assumptions!$F$66 -> 0.25 | I4: =SUM(F4:H4) -> 1 | J4: =Assumptions!$F$67 -> 0.45 | K4: =Assumptions!$F$68 -> 0.4 | L4: =Assumptions!$F$69 -> 0.15 | M4: =SUM(J4:L4) -> 1 | N4: =Assumptions!$F$149 -> 0.6 | O4: =Assumptions!$F$150 -> 0.32 | P4: =Assumptions!$F$151 -> 0.08 | Q4: =SUM(N4:P4) -> 1 | R4: =Assumptions!$F$152 -> 0.7 | S4: =Assumptions!$F$153 -> 0.25 | T4: =Assumptions!$F$154 -> 0.05 | U4: =SUM(R4:T4) -> 1
A5: Deals | B5: ='P&L 5yr'!$C$7*B4 -> 0.45 | C5: ='P&L 5yr'!$C$7*C4 -> 1.35 | D5: ='P&L 5yr'!$C$7*D4 -> 1.2 | E5: =SUM(B5:D5) -> 3 | F5: ='P&L 5yr'!$D$7*F4 -> 150 | G5: ='P&L 5yr'!$D$7*G4 -> 225 | H5: ='P&L 5yr'!$D$7*H4 -> 125 | I5: =SUM(F5:H5) -> 500 | J5: ='P&L 5yr'!$E$7*J4 -> 900 | K5: ='P&L 5yr'!$E$7*K4 -> 800 | L5: ='P&L 5yr'!$E$7*L4 -> 300 | M5: =SUM(J5:L5) -> 2000 | N5: ='P&L 5yr'!$F$7*N4 -> 9000 | O5: ='P&L 5yr'!$F$7*O4 -> 4800 | P5: ='P&L 5yr'!$F$7*P4 -> 1200 | Q5: =SUM(N5:P5) -> 15000 | R5: ='P&L 5yr'!$G$7*R4 -> 21000 | S5: ='P&L 5yr'!$G$7*S4 -> 7500 | T5: ='P&L 5yr'!$G$7*T4 -> 1500 | U5: =SUM(R5:T5) -> 30000
A6: Docs per deal | B6: =Assumptions!$F$103 -> 3 | C6: =Assumptions!$F$104 -> 6 | D6: =Assumptions!$F$105 -> 9 | E6: =IF(E5=0,0,E7/E5) -> 6.75 | F6: =Assumptions!$F$103 -> 3 | G6: =Assumptions!$F$104 -> 6 | H6: =Assumptions!$F$105 -> 9 | I6: =IF(I5=0,0,I7/I5) -> 5.85 | J6: =Assumptions!$F$103 -> 3 | K6: =Assumptions!$F$104 -> 6 | L6: =Assumptions!$F$105 -> 9 | M6: =IF(M5=0,0,M7/M5) -> 5.1 | N6: =Assumptions!$F$103 -> 3 | O6: =Assumptions!$F$104 -> 6 | P6: =Assumptions!$F$105 -> 9 | Q6: =IF(Q5=0,0,Q7/Q5) -> 4.44 | R6: =Assumptions!$F$103 -> 3 | S6: =Assumptions!$F$104 -> 6 | T6: =Assumptions!$F$105 -> 9 | U6: =IF(U5=0,0,U7/U5) -> 4.05
A7: Documents processed | B7: =B5*B6 -> 1.35 | C7: =C5*C6 -> 8.1 | D7: =D5*D6 -> 10.8 | E7: =SUM(B7:D7) -> 20.25 | F7: =F5*F6 -> 450 | G7: =G5*G6 -> 1350 | H7: =H5*H6 -> 1125 | I7: =SUM(F7:H7) -> 2925 | J7: =J5*J6 -> 2700 | K7: =K5*K6 -> 4800 | L7: =L5*L6 -> 2700 | M7: =SUM(J7:L7) -> 10200 | N7: =N5*N6 -> 27000 | O7: =O5*O6 -> 28800 | P7: =P5*P6 -> 10800 | Q7: =SUM(N7:P7) -> 66600 | R7: =R5*R6 -> 63000 | S7: =S5*S6 -> 45000 | T7: =T5*T6 -> 13500 | U7: =SUM(R7:T7) -> 121500
A8: Avg deal value* | B8: =Assumptions!$F$162 -> 35000 | C8: =Assumptions!$F$164 -> 30000 | D8: =Assumptions!$F$166 -> 30000 | E8: =IF(E5=0,0,E9/E5) -> 30750 | F8: =Assumptions!$F$162*(1+Assumptions!$F$163)^1 -> 38500 | G8: =Assumptions!$F$164*(1+Assumptions!$F$165)^1 -> 32400 | H8: =Assumptions!$F$166*(1+Assumptions!$F$167)^1 -> 31500 | I8: =IF(I5=0,0,I9/I5) -> 34005 | J8: =Assumptions!$F$162*(1+Assumptions!$F$163)^2 -> 42350 | K8: =Assumptions!$F$164*(1+Assumptions!$F$165)^2 -> 34992 | L8: =Assumptions!$F$166*(1+Assumptions!$F$167)^2 -> 33075 | M8: =IF(M5=0,0,M9/M5) -> 38015.55 | N8: =Assumptions!$F$162*(1+Assumptions!$F$163)^3 -> 46585 | O8: =Assumptions!$F$164*(1+Assumptions!$F$165)^3 -> 37791.36 | P8: =Assumptions!$F$166*(1+Assumptions!$F$167)^3 -> 34728.75 | Q8: =IF(Q5=0,0,Q9/Q5) -> 42822.535 | R8: =Assumptions!$F$162*(1+Assumptions!$F$163)^4 -> 51243.5 | S8: =Assumptions!$F$164*(1+Assumptions!$F$165)^4 -> 40814.669 | T8: =Assumptions!$F$166*(1+Assumptions!$F$167)^4 -> 36465.188 | U8: =IF(U5=0,0,U9/U5) -> 47897.377
A9: GMV | B9: =B5*B8 -> 15750 | C9: =C5*C8 -> 40500 | D9: =D5*D8 -> 36000 | E9: =SUM(B9:D9) -> 92250 | F9: =F5*F8 -> 5775000 | G9: =G5*G8 -> 7290000 | H9: =H5*H8 -> 3937500 | I9: =SUM(F9:H9) -> 17002500 | J9: =J5*J8 -> 38115000 | K9: =K5*K8 -> 27993600 | L9: =L5*L8 -> 9922500 | M9: =SUM(J9:L9) -> 76031100 | N9: =N5*N8 -> 4.19265e+08 | O9: =O5*O8 -> 1.8139853e+08 | P9: =P5*P8 -> 41674500 | Q9: =SUM(N9:P9) -> 6.4233803e+08 | R9: =R5*R8 -> 1.0761135e+09 | S9: =S5*S8 -> 3.0611002e+08 | T9: =T5*T8 -> 54697781 | U9: =SUM(R9:T9) -> 1.4369213e+09
A10: Escrow take rate** | B10: =Assumptions!$F$70 -> 0.008 | C10: =Assumptions!$F$71 -> 0.015 | D10: =Assumptions!$F$72 -> 0.03 | E10: =IF(E9=0,0,SUM(B9*B10,C9*C10,D9*D10)/E9) -> 0.019658537 | F10: =Assumptions!$F$70 -> 0.008 | G10: =Assumptions!$F$71 -> 0.015 | H10: =Assumptions!$F$72 -> 0.03 | I10: =IF(I9=0,0,SUM(F9*F10,G9*G10,H9*H10)/I9) -> 0.016096162 | J10: =Assumptions!$F$70 -> 0.008 | K10: =Assumptions!$F$71 -> 0.015 | L10: =Assumptions!$F$72 -> 0.03 | M10: =IF(M9=0,0,SUM(J9*J10,K9*K10,L9*L10)/M9) -> 0.013448431 | N10: =Assumptions!$F$70 -> 0.008 | O10: =Assumptions!$F$71 -> 0.015 | P10: =Assumptions!$F$72 -> 0.03 | Q10: =IF(Q9=0,0,SUM(N9*N10,O9*O10,P9*P10)/Q9) -> 0.011404171 | R10: =Assumptions!$F$70 -> 0.008 | S10: =Assumptions!$F$71 -> 0.015 | T10: =Assumptions!$F$72 -> 0.03 | U10: =IF(U9=0,0,SUM(R9*R10,S9*S10,T9*T10)/U9) -> 0.010328674
A11: Minimum escrow fee*** | B11: =Assumptions!$F$73 -> 150 | C11: =Assumptions!$F$74 -> 250 | D11: =Assumptions!$F$75 -> 500 | E11: =IF(E5=0,0,SUM(B5*B11,C5*C11,D5*D11)/E5) -> 335 | F11: =Assumptions!$F$73 -> 150 | G11: =Assumptions!$F$74 -> 250 | H11: =Assumptions!$F$75 -> 500 | I11: =IF(I5=0,0,SUM(F5*F11,G5*G11,H5*H11)/I5) -> 282.5 | J11: =Assumptions!$F$73 -> 150 | K11: =Assumptions!$F$74 -> 250 | L11: =Assumptions!$F$75 -> 500 | M11: =IF(M5=0,0,SUM(J5*J11,K5*K11,L5*L11)/M5) -> 242.5 | N11: =Assumptions!$F$73 -> 150 | O11: =Assumptions!$F$74 -> 250 | P11: =Assumptions!$F$75 -> 500 | Q11: =IF(Q5=0,0,SUM(N5*N11,O5*O11,P5*P11)/Q5) -> 210 | R11: =Assumptions!$F$73 -> 150 | S11: =Assumptions!$F$74 -> 250 | T11: =Assumptions!$F$75 -> 500 | U11: =IF(U5=0,0,SUM(R5*R11,S5*S11,T5*T11)/U5) -> 192.5
A12: Escrow fee revenue | B12: =B5*MAX(B8*B10,B11) -> 126 | C12: =C5*MAX(C8*C10,C11) -> 607.5 | D12: =D5*MAX(D8*D10,D11) -> 1080 | E12: =SUM(B12:D12) -> 1813.5 | F12: =F5*MAX(F8*F10,F11) -> 46200 | G12: =G5*MAX(G8*G10,G11) -> 109350 | H12: =H5*MAX(H8*H10,H11) -> 118125 | I12: =SUM(F12:H12) -> 273675 | J12: =J5*MAX(J8*J10,J11) -> 304920 | K12: =K5*MAX(K8*K10,K11) -> 419904 | L12: =L5*MAX(L8*L10,L11) -> 297675 | M12: =SUM(J12:L12) -> 1022499 | N12: =N5*MAX(N8*N10,N11) -> 3354120 | O12: =O5*MAX(O8*O10,O11) -> 2720977.9 | P12: =P5*MAX(P8*P10,P11) -> 1250235 | Q12: =SUM(N12:P12) -> 7325332.9 | R12: =R5*MAX(R8*R10,R11) -> 8608908 | S12: =S5*MAX(S8*S10,S11) -> 4591650.2 | T12: =T5*MAX(T8*T10,T11) -> 1640933.4 | U12: =SUM(R12:T12) -> 14841492
A13: Doc/review fee per deal | B13: =Assumptions!$F$76 -> 25 | C13: =Assumptions!$F$77 -> 90 | D13: =Assumptions!$F$78 -> 300 | E13: =IF(E5=0,0,SUM(B5*B13,C5*C13,D5*D13)/E5) -> 164.25 | F13: =Assumptions!$F$76 -> 25 | G13: =Assumptions!$F$77 -> 90 | H13: =Assumptions!$F$78 -> 300 | I13: =IF(I5=0,0,SUM(F5*F13,G5*G13,H5*H13)/I5) -> 123 | J13: =Assumptions!$F$76 -> 25 | K13: =Assumptions!$F$77 -> 90 | L13: =Assumptions!$F$78 -> 300 | M13: =IF(M5=0,0,SUM(J5*J13,K5*K13,L5*L13)/M5) -> 92.25 | N13: =Assumptions!$F$76 -> 25 | O13: =Assumptions!$F$77 -> 90 | P13: =Assumptions!$F$78 -> 300 | Q13: =IF(Q5=0,0,SUM(N5*N13,O5*O13,P5*P13)/Q5) -> 67.8 | R13: =Assumptions!$F$76 -> 25 | S13: =Assumptions!$F$77 -> 90 | T13: =Assumptions!$F$78 -> 300 | U13: =IF(U5=0,0,SUM(R5*R13,S5*S13,T5*T13)/U5) -> 55
A14: Doc/review revenue | B14: =B5*B13 -> 11.25 | C14: =C5*C13 -> 121.5 | D14: =D5*D13 -> 360 | E14: =SUM(B14:D14) -> 492.75 | F14: =F5*F13 -> 3750 | G14: =G5*G13 -> 20250 | H14: =H5*H13 -> 37500 | I14: =SUM(F14:H14) -> 61500 | J14: =J5*J13 -> 22500 | K14: =K5*K13 -> 72000 | L14: =L5*L13 -> 90000 | M14: =SUM(J14:L14) -> 184500 | N14: =N5*N13 -> 225000 | O14: =O5*O13 -> 432000 | P14: =P5*P13 -> 360000 | Q14: =SUM(N14:P14) -> 1017000 | R14: =R5*R13 -> 525000 | S14: =S5*S13 -> 675000 | T14: =T5*T13 -> 450000 | U14: =SUM(R14:T14) -> 1650000
A15: Dispute rate | B15: =Assumptions!$F$91 -> 0.04 | C15: =Assumptions!$F$92 -> 0.1 | D15: =Assumptions!$F$93 -> 0.2 | E15: =IF(E5=0,0,E16/E5) -> 0.131 | F15: =Assumptions!$F$91 -> 0.04 | G15: =Assumptions!$F$92 -> 0.1 | H15: =Assumptions!$F$93 -> 0.2 | I15: =IF(I5=0,0,I16/I5) -> 0.107 | J15: =Assumptions!$F$91 -> 0.04 | K15: =Assumptions!$F$92 -> 0.1 | L15: =Assumptions!$F$93 -> 0.2 | M15: =IF(M5=0,0,M16/M5) -> 0.088 | N15: =Assumptions!$F$91 -> 0.04 | O15: =Assumptions!$F$92 -> 0.1 | P15: =Assumptions!$F$93 -> 0.2 | Q15: =IF(Q5=0,0,Q16/Q5) -> 0.072 | R15: =Assumptions!$F$91 -> 0.04 | S15: =Assumptions!$F$92 -> 0.1 | T15: =Assumptions!$F$93 -> 0.2 | U15: =IF(U5=0,0,U16/U5) -> 0.063
A16: Disputed deals | B16: =B5*B15 -> 0.018 | C16: =C5*C15 -> 0.135 | D16: =D5*D15 -> 0.24 | E16: =SUM(B16:D16) -> 0.393 | F16: =F5*F15 -> 6 | G16: =G5*G15 -> 22.5 | H16: =H5*H15 -> 25 | I16: =SUM(F16:H16) -> 53.5 | J16: =J5*J15 -> 36 | K16: =K5*K15 -> 80 | L16: =L5*L15 -> 60 | M16: =SUM(J16:L16) -> 176 | N16: =N5*N15 -> 360 | O16: =O5*O15 -> 480 | P16: =P5*P15 -> 240 | Q16: =SUM(N16:P16) -> 1080 | R16: =R5*R15 -> 840 | S16: =S5*S15 -> 750 | T16: =T5*T15 -> 300 | U16: =SUM(R16:T16) -> 1890
A17: Dispute/amendment fee | B17: =Assumptions!$F$79 -> 100 | C17: =Assumptions!$F$80 -> 200 | D17: =Assumptions!$F$81 -> 500 | E17: =IF(E16=0,0,SUM(B16*B17,C16*C17,D16*D17)/E16) -> 378.62595 | F17: =Assumptions!$F$79 -> 100 | G17: =Assumptions!$F$80 -> 200 | H17: =Assumptions!$F$81 -> 500 | I17: =IF(I16=0,0,SUM(F16*F17,G16*G17,H16*H17)/I16) -> 328.97196 | J17: =Assumptions!$F$79 -> 100 | K17: =Assumptions!$F$80 -> 200 | L17: =Assumptions!$F$81 -> 500 | M17: =IF(M16=0,0,SUM(J16*J17,K16*K17,L16*L17)/M16) -> 281.81818 | N17: =Assumptions!$F$79 -> 100 | O17: =Assumptions!$F$80 -> 200 | P17: =Assumptions!$F$81 -> 500 | Q17: =IF(Q16=0,0,SUM(N16*N17,O16*O17,P16*P17)/Q16) -> 233.33333 | R17: =Assumptions!$F$79 -> 100 | S17: =Assumptions!$F$80 -> 200 | T17: =Assumptions!$F$81 -> 500 | U17: =IF(U16=0,0,SUM(R16*R17,S16*S17,T16*T17)/U16) -> 203.1746
A18: Dispute/amendment revenue | B18: =B16*B17 -> 1.8 | C18: =C16*C17 -> 27 | D18: =D16*D17 -> 120 | E18: =SUM(B18:D18) -> 148.8 | F18: =F16*F17 -> 600 | G18: =G16*G17 -> 4500 | H18: =H16*H17 -> 12500 | I18: =SUM(F18:H18) -> 17600 | J18: =J16*J17 -> 3600 | K18: =K16*K17 -> 16000 | L18: =L16*L17 -> 30000 | M18: =SUM(J18:L18) -> 49600 | N18: =N16*N17 -> 36000 | O18: =O16*O17 -> 96000 | P18: =P16*P17 -> 120000 | Q18: =SUM(N18:P18) -> 252000 | R18: =R16*R17 -> 84000 | S18: =S16*S17 -> 150000 | T18: =T16*T17 -> 150000 | U18: =SUM(R18:T18) -> 384000
A19: External eBL/API/paper cost | B19: =B5*Assumptions!$F$82 -> 1.35 | C19: =C5*Assumptions!$F$83 -> 13.5 | D19: =D5*Assumptions!$F$84 -> 180 | E19: =SUM(B19:D19) -> 194.85 | F19: =F5*Assumptions!$F$82 -> 450 | G19: =G5*Assumptions!$F$83 -> 2250 | H19: =H5*Assumptions!$F$84 -> 18750 | I19: =SUM(F19:H19) -> 21450 | J19: =J5*Assumptions!$F$82 -> 2700 | K19: =K5*Assumptions!$F$83 -> 8000 | L19: =L5*Assumptions!$F$84 -> 45000 | M19: =SUM(J19:L19) -> 55700 | N19: =N5*Assumptions!$F$82 -> 27000 | O19: =O5*Assumptions!$F$83 -> 48000 | P19: =P5*Assumptions!$F$84 -> 180000 | Q19: =SUM(N19:P19) -> 255000 | R19: =R5*Assumptions!$F$82 -> 63000 | S19: =S5*Assumptions!$F$83 -> 75000 | T19: =T5*Assumptions!$F$84 -> 225000 | U19: =SUM(R19:T19) -> 363000
A20: Human review cost | B20: =B5*Assumptions!$F$85 -> 1.35 | C20: =C5*Assumptions!$F$86 -> 27 | D20: =D5*Assumptions!$F$87 -> 180 | E20: =SUM(B20:D20) -> 208.35 | F20: =F5*Assumptions!$F$85 -> 450 | G20: =G5*Assumptions!$F$86 -> 4500 | H20: =H5*Assumptions!$F$87 -> 18750 | I20: =SUM(F20:H20) -> 23700 | J20: =J5*Assumptions!$F$85 -> 2700 | K20: =K5*Assumptions!$F$86 -> 16000 | L20: =L5*Assumptions!$F$87 -> 45000 | M20: =SUM(J20:L20) -> 63700 | N20: =N5*Assumptions!$F$85 -> 27000 | O20: =O5*Assumptions!$F$86 -> 96000 | P20: =P5*Assumptions!$F$87 -> 180000 | Q20: =SUM(N20:P20) -> 303000 | R20: =R5*Assumptions!$F$85 -> 63000 | S20: =S5*Assumptions!$F$86 -> 150000 | T20: =T5*Assumptions!$F$87 -> 225000 | U20: =SUM(R20:T20) -> 438000
A21: Support cost | B21: =B5*Assumptions!$F$88 -> 0.9 | C21: =C5*Assumptions!$F$89 -> 8.1 | D21: =D5*Assumptions!$F$90 -> 24 | E21: =SUM(B21:D21) -> 33 | F21: =F5*Assumptions!$F$88 -> 300 | G21: =G5*Assumptions!$F$89 -> 1350 | H21: =H5*Assumptions!$F$90 -> 2500 | I21: =SUM(F21:H21) -> 4150 | J21: =J5*Assumptions!$F$88 -> 1800 | K21: =K5*Assumptions!$F$89 -> 4800 | L21: =L5*Assumptions!$F$90 -> 6000 | M21: =SUM(J21:L21) -> 12600 | N21: =N5*Assumptions!$F$88 -> 18000 | O21: =O5*Assumptions!$F$89 -> 28800 | P21: =P5*Assumptions!$F$90 -> 24000 | Q21: =SUM(N21:P21) -> 70800 | R21: =R5*Assumptions!$F$88 -> 42000 | S21: =S5*Assumptions!$F$89 -> 45000 | T21: =T5*Assumptions!$F$90 -> 30000 | U21: =SUM(R21:T21) -> 117000
A22: Dispute handling cost | B22: =B16*Assumptions!$F$94 -> 1.08 | C22: =C16*Assumptions!$F$95 -> 16.2 | D22: =D16*Assumptions!$F$96 -> 84 | E22: =SUM(B22:D22) -> 101.28 | F22: =F16*Assumptions!$F$94 -> 360 | G22: =G16*Assumptions!$F$95 -> 2700 | H22: =H16*Assumptions!$F$96 -> 8750 | I22: =SUM(F22:H22) -> 11810 | J22: =J16*Assumptions!$F$94 -> 2160 | K22: =K16*Assumptions!$F$95 -> 9600 | L22: =L16*Assumptions!$F$96 -> 21000 | M22: =SUM(J22:L22) -> 32760 | N22: =N16*Assumptions!$F$94 -> 21600 | O22: =O16*Assumptions!$F$95 -> 57600 | P22: =P16*Assumptions!$F$96 -> 84000 | Q22: =SUM(N22:P22) -> 163200 | R22: =R16*Assumptions!$F$94 -> 50400 | S22: =S16*Assumptions!$F$95 -> 90000 | T22: =T16*Assumptions!$F$96 -> 105000 | U22: =SUM(R22:T22) -> 245400
A23: Total tier-specific COGS | B23: =SUM(B19:B22) -> 4.68 | C23: =SUM(C19:C22) -> 64.8 | D23: =SUM(D19:D22) -> 468 | E23: =SUM(B23:D23) -> 537.48 | F23: =SUM(F19:F22) -> 1560 | G23: =SUM(G19:G22) -> 10800 | H23: =SUM(H19:H22) -> 48750 | I23: =SUM(F23:H23) -> 61110 | J23: =SUM(J19:J22) -> 9360 | K23: =SUM(K19:K22) -> 38400 | L23: =SUM(L19:L22) -> 117000 | M23: =SUM(J23:L23) -> 164760 | N23: =SUM(N19:N22) -> 93600 | O23: =SUM(O19:O22) -> 230400 | P23: =SUM(P19:P22) -> 468000 | Q23: =SUM(N23:P23) -> 792000 | R23: =SUM(R19:R22) -> 218400 | S23: =SUM(S19:S22) -> 360000 | T23: =SUM(T19:T22) -> 585000 | U23: =SUM(R23:T23) -> 1163400
A24: Tier revenue | B24: =SUM(B12,B14,B18) -> 139.05 | C24: =SUM(C12,C14,C18) -> 756 | D24: =SUM(D12,D14,D18) -> 1560 | E24: =SUM(B24:D24) -> 2455.05 | F24: =SUM(F12,F14,F18) -> 50550 | G24: =SUM(G12,G14,G18) -> 134100 | H24: =SUM(H12,H14,H18) -> 168125 | I24: =SUM(F24:H24) -> 352775 | J24: =SUM(J12,J14,J18) -> 331020 | K24: =SUM(K12,K14,K18) -> 507904 | L24: =SUM(L12,L14,L18) -> 417675 | M24: =SUM(J24:L24) -> 1256599 | N24: =SUM(N12,N14,N18) -> 3615120 | O24: =SUM(O12,O14,O18) -> 3248977.9 | P24: =SUM(P12,P14,P18) -> 1730235 | Q24: =SUM(N24:P24) -> 8594332.9 | R24: =SUM(R12,R14,R18) -> 9217908 | S24: =SUM(S12,S14,S18) -> 5416650.2 | T24: =SUM(T12,T14,T18) -> 2240933.4 | U24: =SUM(R24:T24) -> 16875492
A25: Gross profit before shared COGS | B25: =B24-B23 -> 134.37 | C25: =C24-C23 -> 691.2 | D25: =D24-D23 -> 1092 | E25: =E24-E23 -> 1917.57 | F25: =F24-F23 -> 48990 | G25: =G24-G23 -> 123300 | H25: =H24-H23 -> 119375 | I25: =I24-I23 -> 291665 | ... U25: =U24-U23 -> 15712092
A26: Gross margin | B26: =IF(B24=0,0,B25/B24) -> 0.96634304 | C26: =IF(C24=0,0,C25/C24) -> 0.91428571 | D26: =IF(D24=0,0,D25/D24) -> 0.7 | E26: =IF(E24=0,0,E25/E24) -> 0.78107167 | F26: =IF(F24=0,0,F25/F24) -> 0.96913947 | G26: =IF(G24=0,0,G25/G24) -> 0.91946309 | H26: =IF(H24=0,0,H25/H24) -> 0.71003717 | I26: =IF(I24=0,0,I25/I24) -> 0.82677344 | ... U26: =IF(U24=0,0,U25/U24) -> 0.93105979
A27: Weighted risk score | B27: =B4*Assumptions!$F$97 -> 0.15 | C27: =C4*Assumptions!$F$98 -> 1.35 | D27: =D4*Assumptions!$F$99 -> 2 | E27: =SUM(B27:D27) -> 3.5 | F27: =F4*Assumptions!$F$97 -> 0.3 | G27: =G4*Assumptions!$F$98 -> 1.35 | H27: =H4*Assumptions!$F$99 -> 1.25 | I27: =SUM(F27:H27) -> 2.9 | J27: =J4*Assumptions!$F$97 -> 0.45 | K27: =K4*Assumptions!$F$98 -> 1.2 | L27: =L4*Assumptions!$F$99 -> 0.75 | M27: =SUM(J27:L27) -> 2.4 | N27: =N4*Assumptions!$F$97 -> 0.6 | O27: =O4*Assumptions!$F$98 -> 0.96 | P27: =P4*Assumptions!$F$99 -> 0.4 | Q27: =SUM(N27:P27) -> 1.96 | R27: =R4*Assumptions!$F$97 -> 0.7 | S27: =S4*Assumptions!$F$98 -> 0.75 | T27: =T4*Assumptions!$F$99 -> 0.25 | U27: =SUM(R27:T27) -> 1.7
A28: SLA days | B28: =Assumptions!$F$100 -> 0.05 | C28: =Assumptions!$F$101 -> 0.5 | D28: =Assumptions!$F$102 -> 7 | E28: =IF(E5=0,0,SUM(B5*B28,C5*C28,D5*D28)/E5) -> 3.0325 | F28: =Assumptions!$F$100 -> 0.05 | G28: =Assumptions!$F$101 -> 0.5 | H28: =Assumptions!$F$102 -> 7 | I28: =IF(I5=0,0,SUM(F5*F28,G5*G28,H5*H28)/I5) -> 1.99 | J28: =Assumptions!$F$100 -> 0.05 | K28: =Assumptions!$F$101 -> 0.5 | L28: =Assumptions!$F$102 -> 7 | M28: =IF(M5=0,0,SUM(J5*J28,K5*K28,L5*L28)/M5) -> 1.2725 | N28: =Assumptions!$F$100 -> 0.05 | O28: =Assumptions!$F$101 -> 0.5 | P28: =Assumptions!$F$102 -> 7 | Q28: =IF(Q5=0,0,SUM(N5*N28,O5*O28,P5*P28)/Q5) -> 0.75 | R28: =Assumptions!$F$100 -> 0.05 | S28: =Assumptions!$F$101 -> 0.5 | T28: =Assumptions!$F$102 -> 7 | U28: =IF(U5=0,0,SUM(R5*R28,S5*S28,T5*T28)/U5) -> 0.51
A29: Tier mix sums check | E29: =IF(ABS(E4-1)<0.0001,"OK","CHECK MIX") -> OK | I29: =IF(ABS(I4-1)<0.0001,"OK","CHECK MIX") -> OK | M29: =IF(ABS(M4-1)<0.0001,"OK","CHECK MIX") -> OK | Q29: =IF(ABS(Q4-1)<0.0001,"OK","CHECK MIX") -> OK | U29: =IF(ABS(U4-1)<0.0001,"OK","CHECK MIX") -> OK
A30: Pricing / risk profile | B30: Fastest / lowest risk | C30: Core verified tier | D30: Highest cost / highest risk | E30: Portfolio blend | F30: Fastest / lowest risk | G30: Core verified tier | H30: Highest cost / highest risk | I30: Portfolio blend | J30: Fastest / lowest risk | K30: Core verified tier | L30: Highest cost / highest risk | M30: Portfolio blend | N30: Fastest / lowest risk | O30: Core verified tier | P30: Highest cost / highest risk | Q30: Portfolio blend | R30: Fastest / lowest risk | S30: Core verified tier | T30: Highest cost / highest risk | U30: Portfolio blend
A32: Notes | Q32: Source
A33: *Year-1 deal values (£35k Tier A; £30k Tier B/C) and 10%/8%/5% annual growth are triangulated planning averages, not observed tier-level transaction data. The research report documents the proxies, judgement and confidence limits. | Q33: ../docs/Blockmediary_Deal_Value_Research_Report.pdf
A34: **Take rates of 0.8%/1.5%/3.0% are management pricing choices informed by Tazapay, Truzo, XREX, Escrow.com and bank-LC comparables. They are paid-pilot hypotheses, not competitor quotations. | Q34: ../docs/Competitor-analysis.md
A35: ***Minimum fees (£150/£250/£500) are internal floors intended to protect contribution margin on smaller deals; no external tariff is being claimed. Validate conversion and willingness-to-pay in the pilot. | Q35: Management assumption — pilot validation required

Sheet Revenue Risk Add-Ons
A1: Revenue add-ons and retained-risk offsets
A3: Line item | B3: Year 1 | C3: Year 2 | D3: Year 3 | E3: Year 4 | F3: Year 5 | G3: Logic / note
A4: REVENUE ADD-ONS
A5: Less: first-deal discounts and credits | B5: =IFERROR(ROUND(-'P&L 5yr'!C70*('P&L 5yr'!C14/'P&L 5yr'!C7)*Assumptions!$F$112,0),0) -> -302 | C5: =IFERROR(ROUND(-MAX(0,'P&L 5yr'!D70-'P&L 5yr'!C70)*('P&L 5yr'!D14/'P&L 5yr'!D7)*Assumptions!$F$112,0),0) -> -33936 | D5: =IFERROR(ROUND(-MAX(0,'P&L 5yr'!E70-'P&L 5yr'!D70)*('P&L 5yr'!E14/'P&L 5yr'!E7)*Assumptions!$F$112,0),0) -> -53255 | E5: =IFERROR(ROUND(-MAX(0,'P&L 5yr'!F70-'P&L 5yr'!E70)*('P&L 5yr'!F14/'P&L 5yr'!F7)*Assumptions!$F$112,0),0) -> -376441 | F5: =IFERROR(ROUND(-MAX(0,'P&L 5yr'!G70-'P&L 5yr'!F70)*('P&L 5yr'!G14/'P&L 5yr'!G7)*Assumptions!$F$112,0),0) -> -278278
A6: Expedited review fees | B6: =ROUND('Tier Economics'!C5*Assumptions!$F$113*Assumptions!$F$115+'Tier Economics'!D5*Assumptions!$F$114*Assumptions!$F$116,0) -> 92 | C6: =ROUND('Tier Economics'!G5*Assumptions!$F$113*Assumptions!$F$115+'Tier Economics'!H5*Assumptions!$F$114*Assumptions!$F$116,0) -> 10875 | D6: =ROUND('Tier Economics'!K5*Assumptions!$F$113*Assumptions!$F$115+'Tier Economics'!L5*Assumptions!$F$114*Assumptions!$F$116,0) -> 30000 | E6: =ROUND('Tier Economics'!O5*Assumptions!$F$113*Assumptions!$F$115+'Tier Economics'!P5*Assumptions!$F$114*Assumptions!$F$116,0) -> 144000 | F6: =ROUND('Tier Economics'!S5*Assumptions!$F$113*Assumptions!$F$115+'Tier Economics'!T5*Assumptions!$F$114*Assumptions!$F$116,0) -> 202500
A7: KYC/KYB onboarding fees | B7: =ROUND('P&L 5yr'!C11*Assumptions!$F$117,0) -> 45 | C7: =ROUND('P&L 5yr'!D11*Assumptions!$F$117,0) -> 7500 | D7: =ROUND('P&L 5yr'!E11*Assumptions!$F$117,0) -> 30000 | E7: =ROUND('P&L 5yr'!F11*Assumptions!$F$117,0) -> 225000 | F7: =ROUND('P&L 5yr'!G11*Assumptions!$F$117,0) -> 450000 | G7: Fresh onboarding only; repeat counterparties not recharged every deal
A8: Tier C forensics pass-through margin | B8: =ROUND('Tier Economics'!D19*Assumptions!$F$118,0) -> 36 | C8: =ROUND('Tier Economics'!H19*Assumptions!$F$118,0) -> 3750 | D8: =ROUND('Tier Economics'!L19*Assumptions!$F$118,0) -> 9000 | E8: =ROUND('Tier Economics'!P19*Assumptions!$F$118,0) -> 36000 | F8: =ROUND('Tier Economics'!T19*Assumptions!$F$118,0) -> 45000
A9: Tier C courier/original handling fees | B9: =ROUND('Tier Economics'!D5*Assumptions!$F$119,0) -> 90 | C9: =ROUND('Tier Economics'!H5*Assumptions!$F$119,0) -> 9375 | D9: =ROUND('Tier Economics'!L5*Assumptions!$F$119,0) -> 22500 | E9: =ROUND('Tier Economics'!P5*Assumptions!$F$119,0) -> 90000 | F9: =ROUND('Tier Economics'!T5*Assumptions!$F$119,0) -> 112500
A10: Discrepancy cure / waiver fees | B10: =ROUND('P&L 5yr'!C12*Assumptions!$F$121*Assumptions!$F$120,0) -> 24 | C10: =ROUND('P&L 5yr'!D12*Assumptions!$F$121*Assumptions!$F$120,0) -> 3210 | D10: =ROUND('P&L 5yr'!E12*Assumptions!$F$121*Assumptions!$F$120,0) -> 10560 | E10: =ROUND('P&L 5yr'!F12*Assumptions!$F$121*Assumptions!$F$120,0) -> 64800 | F10: =ROUND('P&L 5yr'!G12*Assumptions!$F$121*Assumptions!$F$120,0) -> 113400
A11: Partner setup / integration fees | B11: =ROUND(0,0) -> 0 | C11: =ROUND(Assumptions!$F$14*Assumptions!$F$122,0) -> 22500 | D11: =ROUND(MAX(0,Assumptions!$F$110-Assumptions!$F$14)*Assumptions!$F$122,0) -> 22500 | E11: =ROUND(MAX(0,Assumptions!$F$155-Assumptions!$F$110)*Assumptions!$F$122,0) -> 30000 | F11: =ROUND(MAX(0,Assumptions!$F$156-Assumptions!$F$155)*Assumptions!$F$122,0) -> 60000 | G11: Setup fees charged on net-new partners only
A12: Monthly minimum / committed volume fees | B12: =ROUND(0,0) -> 0 | C12: =ROUND(Assumptions!$F$14*Assumptions!$F$123*12,0) -> 27000 | D12: =ROUND(Assumptions!$F$110*Assumptions!$F$123*12,0) -> 54000 | E12: =ROUND(Assumptions!$F$155*Assumptions!$F$123*12,0) -> 90000 | F12: =ROUND(Assumptions!$F$156*Assumptions!$F$123*12,0) -> 162000 | G12: Monthly minimum uses live partner count by year
A13: Archive / audit record fees | B13: =ROUND('P&L 5yr'!C7*Assumptions!$F$124,0) -> 9 | C13: =ROUND('P&L 5yr'!D7*Assumptions!$F$124,0) -> 1500 | D13: =ROUND('P&L 5yr'!E7*Assumptions!$F$124,0) -> 6000 | E13: =ROUND('P&L 5yr'!F7*Assumptions!$F$124,0) -> 45000 | F13: =ROUND('P&L 5yr'!G7*Assumptions!$F$124,0) -> 90000
A15: Total additional revenue | B15: =ROUND(SUM(B5:B14),0) -> -6 | C15: =ROUND(SUM(C5:C14),0) -> 51774 | D15: =ROUND(SUM(D5:D14),0) -> 131305 | E15: =ROUND(SUM(E5:E14),0) -> 348359 | F15: =ROUND(SUM(F5:F14),0) -> 957122
A17: RETAINED-RISK VARIABLE COSTS
A18: QA sampling + >£50k mandatory review | B18: =ROUND('P&L 5yr'!C12*Assumptions!$F$131*Assumptions!$F$132+'P&L 5yr'!C7*Assumptions!$F$176*Assumptions!$F$181,0) -> 24 | C18: =ROUND('P&L 5yr'!D12*Assumptions!$F$131*Assumptions!$F$132+'P&L 5yr'!D7*Assumptions!$F$177*Assumptions!$F$181,0) -> 7757 | D18: =ROUND('P&L 5yr'!E12*Assumptions!$F$131*Assumptions!$F$132+'P&L 5yr'!E7*Assumptions!$F$178*Assumptions!$F$181,0) -> 53345 | E18: =ROUND('P&L 5yr'!F12*Assumptions!$F$131*Assumptions!$F$132+'P&L 5yr'!F7*Assumptions!$F$179*Assumptions!$F$181,0) -> 567684 | F18: =ROUND('P&L 5yr'!G12*Assumptions!$F$131*Assumptions!$F$132+'P&L 5yr'!G7*Assumptions!$F$180*Assumptions!$F$181,0) -> 1471572 | G18: QA sampling plus deal count × share above £50k × incremental review cost
A19: External dispute forum cost | B19: =ROUND('P&L 5yr'!C12*Assumptions!$F$133*Assumptions!$F$134,0) -> 88 | C19: =ROUND('P&L 5yr'!D12*Assumptions!$F$133*Assumptions!$F$134,0) -> 12038 | D19: =ROUND('P&L 5yr'!E12*Assumptions!$F$133*Assumptions!$F$134,0) -> 39600 | E19: =ROUND('P&L 5yr'!F12*Assumptions!$F$133*Assumptions!$F$134,0) -> 243000 | F19: =ROUND('P&L 5yr'!G12*Assumptions!$F$133*Assumptions!$F$134,0) -> 425250
A20: Operational error / wrongful-release reserve | B20: =ROUND('P&L 5yr'!C18*Assumptions!$F$135,0) -> 24 | C20: =ROUND('P&L 5yr'!D18*Assumptions!$F$135,0) -> 4045 | D20: =ROUND('P&L 5yr'!E18*Assumptions!$F$135,0) -> 13879 | E20: =ROUND('P&L 5yr'!F18*Assumptions!$F$135,0) -> 89427 | F20: =ROUND('P&L 5yr'!G18*Assumptions!$F$135,0) -> 178326
A21: Partner/channel commission | B21: 0 | C21: =ROUND('P&L 5yr'!D18*Assumptions!$F$159*Assumptions!$F$139,0) -> 6068 | D21: =ROUND('P&L 5yr'!E18*Assumptions!$F$159*Assumptions!$F$139,0) -> 20819 | E21: =ROUND('P&L 5yr'!F18*Assumptions!$F$159*Assumptions!$F$139,0) -> 134140 | F21: =ROUND('P&L 5yr'!G18*Assumptions!$F$159*Assumptions!$F$139,0) -> 267489
A22: Fee collection leakage | B22: =ROUND((B7+B10+B12)*Assumptions!$F$140,0) -> 1 | C22: =ROUND((C7+C10+C12)*Assumptions!$F$140,0) -> 377 | D22: =ROUND((D7+D10+D12)*Assumptions!$F$140,0) -> 946 | E22: =ROUND((E7+E10+E12)*Assumptions!$F$140,0) -> 3798 | F22: =ROUND((F7+F10+F12)*Assumptions!$F$140,0) -> 7254
A23: Partner/API outage fallback | B23: =ROUND('Tier Economics'!C5*Assumptions!$F$141*Assumptions!$F$142,0) -> 3 | C23: =ROUND('Tier Economics'!G5*Assumptions!$F$141*Assumptions!$F$142,0) -> 506 | D23: =ROUND('Tier Economics'!K5*Assumptions!$F$141*Assumptions!$F$142,0) -> 1800 | E23: =ROUND('Tier Economics'!O5*Assumptions!$F$141*Assumptions!$F$142,0) -> 10800 | F23: =ROUND('Tier Economics'!S5*Assumptions!$F$141*Assumptions!$F$142,0) -> 16875
A24: Total variable retained-risk costs | B24: =ROUND(SUM(B18:B23),0) -> 140 | C24: =ROUND(SUM(C18:C23),0) -> 30791 | D24: =ROUND(SUM(D18:D23),0) -> 130389 | E24: =ROUND(SUM(E18:E23),0) -> 1048849 | F24: =ROUND(SUM(F18:F23),0) -> 2366766
A26: RETAINED-RISK FIXED COSTS
A27: Carrier/eBL integration maintenance | B27: =ROUND(Assumptions!$F$127*1,0) -> 15000 | C27: =ROUND(Assumptions!$F$127*1.25,0) -> 18750 | D27: =ROUND(Assumptions!$F$127*1.5,0) -> 22500 | E27: =ROUND(Assumptions!$F$127*1.75,0) -> 26250 | F27: =ROUND(Assumptions!$F$127*2,0) -> 30000
A28: Forensics partner retainer | B28: =ROUND(Assumptions!$F$128*1,0) -> 20000 | C28: =ROUND(Assumptions!$F$128*1.25,0) -> 25000 | D28: =ROUND(Assumptions!$F$128*1.5,0) -> 30000 | E28: =ROUND(Assumptions!$F$128*1.75,0) -> 35000 | F28: =ROUND(Assumptions!$F$128*2,0) -> 40000
A29: Fraud database build / governance | B29: =ROUND(Assumptions!$F$129+Assumptions!$F$130,0) -> 55000 | C29: =ROUND(Assumptions!$F$130,0) -> 15000 | D29: =ROUND(Assumptions!$F$130,0) -> 15000 | E29: =ROUND(Assumptions!$F$130,0) -> 15000 | F29: =ROUND(Assumptions!$F$130,0) -> 15000
A30: KMS / multisig / key security ops | B30: =ROUND(Assumptions!$F$137*1,0) -> 12000 | C30: =ROUND(Assumptions!$F$137*1.25,0) -> 15000 | D30: =ROUND(Assumptions!$F$137*1.5,0) -> 18000 | E30: =ROUND(Assumptions!$F$137*1.75,0) -> 21000 | F30: =ROUND(Assumptions!$F$137*2,0) -> 24000
A31: Regulatory reporting ops | B31: =ROUND(Assumptions!$F$138*1,0) -> 18000 | C31: =ROUND(Assumptions!$F$138*1.25,0) -> 22500 | D31: =ROUND(Assumptions!$F$138*1.5,0) -> 27000 | E31: =ROUND(Assumptions!$F$138*1.75,0) -> 31500 | F31: =ROUND(Assumptions!$F$138*2,0) -> 36000
A32: Insurance deductible reserve | B32: =ROUND(Assumptions!$F$136,0) -> 15000 | C32: =ROUND(Assumptions!$F$136,0) -> 15000 | D32: =ROUND(Assumptions!$F$136,0) -> 15000 | E32: =ROUND(Assumptions!$F$136,0) -> 15000 | F32: =ROUND(Assumptions!$F$136,0) -> 15000
A33: Smart contract incident reserve | B33: =ROUND(Assumptions!$F$143*1,0) -> 30000 | C33: =ROUND(Assumptions!$F$143*1,0) -> 30000 | D33: =ROUND(Assumptions!$F$143*1,0) -> 30000 | E33: =ROUND(Assumptions!$F$143*1.25,0) -> 37500 | F33: =ROUND(Assumptions!$F$143*1.5,0) -> 45000
A34: Liability wording legal review | B34: =ROUND(Assumptions!$F$144,0) -> 7500 | C34: =ROUND(0,0) -> 0 | D34: =ROUND(0,0) -> 0 | E34: =ROUND(0,0) -> 0 | F34: =ROUND(0,0) -> 0
A35: Document-source indemnity legal review | B35: =ROUND(Assumptions!$F$145,0) -> 7500 | C35: =ROUND(0,0) -> 0 | D35: =ROUND(0,0) -> 0 | E35: =ROUND(0,0) -> 0 | F35: =ROUND(0,0) -> 0
A36: Total fixed retained-risk costs | B36: =ROUND(SUM(B27:B35),0) -> 180000 | C36: =ROUND(SUM(C27:C35),0) -> 141250 | D36: =ROUND(SUM(D27:D35),0) -> 157500 | E36: =ROUND(SUM(E27:E35),0) -> 181250 | F36: =ROUND(SUM(F27:F35),0) -> 205000

Sheet P&L 5yr
B2: 5-Year P&L (annual) - driven by Assumptions sheet
B3: All figures GBP. Revenue & COGS scale with deal volume. Active scenario shown; change Assumptions!C4.
B5: Line item | C5: Year 1 | D5: Year 2 | E5: Year 3 | F5: Year 4 | G5: Year 5 | H5: Unit / note
B6: VOLUME & DRIVERS
B7: Deals processed | C7: =ROUND(Assumptions!$F$10*'Launch Readiness'!$B$28,0) -> 3 | D7: =ROUND(Assumptions!$F$11*'Launch Readiness'!$C$28,0) -> 500 | E7: =ROUND(Assumptions!$F$12*'Launch Readiness'!$D$28,0) -> 2000 | F7: =ROUND(Assumptions!$F$147*'Launch Readiness'!$E$28,0) -> 15000 | G7: =ROUND(Assumptions!$F$148*'Launch Readiness'!$F$28,0) -> 30000 | H7: From Assumptions
B8: Avg deal value (£) | C8: =IF(C7=0,0,C9/C7) -> 30750 | D8: =IF(D7=0,0,D9/D7) -> 34005 | E8: =IF(E7=0,0,E9/E7) -> 38015.55 | F8: =IF(F7=0,0,F9/F7) -> 42822.535 | G8: =IF(G7=0,0,G9/G7) -> 47897.377 | H8: GMV per deal
B9: Gross trade value processed (GMV) | C9: ='Tier Economics'!E9 -> 92250 | D9: ='Tier Economics'!I9 -> 17002500 | E9: ='Tier Economics'!M9 -> 76031100 | F9: ='Tier Economics'!Q9 -> 6.4233803e+08 | G9: ='Tier Economics'!U9 -> 1.4369213e+09 | H9: Deals × avg value (NOT revenue)
B10: Documents processed | C10: ='Tier Economics'!E7 -> 20.25 | D10: ='Tier Economics'!I7 -> 2925 | E10: ='Tier Economics'!M7 -> 10200 | F10: ='Tier Economics'!Q7 -> 66600 | G10: ='Tier Economics'!U7 -> 121500 | H10: Tier-weighted docs/deal from Tier Economics
B11: New counterparties onboarded | C11: =C7*Assumptions!$F$13*Assumptions!$F$59 -> 3 | D11: =D7*Assumptions!$F$13*Assumptions!$F$59 -> 500 | E11: =E7*Assumptions!$F$13*Assumptions!$F$59 -> 2000 | F11: =F7*Assumptions!$F$13*Assumptions!$F$59 -> 15000 | G11: =G7*Assumptions!$F$13*Assumptions!$F$59 -> 30000 | H11: Deals x parties/deal x new-counterparty onboarding share
B12: Disputed/amended deals | C12: ='Tier Economics'!E16 -> 0.393 | D12: ='Tier Economics'!I16 -> 53.5 | E12: ='Tier Economics'!M16 -> 176 | F12: ='Tier Economics'!Q16 -> 1080 | G12: ='Tier Economics'!U16 -> 1890 | H12: Tier-weighted dispute rates
B13: REVENUE
B14: Gross escrow transaction fees | C14: ='Tier Economics'!E12 -> 1813.5 | D14: ='Tier Economics'!I12 -> 273675 | E14: ='Tier Economics'!M12 -> 1022499 | F14: ='Tier Economics'!Q12 -> 7325332.9 | G14: ='Tier Economics'!U12 -> 14841492 | H14: Tiered fee by A/B/C mix, before launch discounts
B15: Less: first-deal discounts and credits | C15: ='Revenue Risk Add-Ons'!B5 -> -302 | D15: ='Revenue Risk Add-Ons'!C5 -> -33936 | E15: ='Revenue Risk Add-Ons'!D5 -> -53255 | F15: ='Revenue Risk Add-Ons'!E5 -> -376441 | G15: ='Revenue Risk Add-Ons'!F5 -> -278278 | H15: Shown separately so discounts do not make add-on revenue negative
B16: Document + dispute / amendment fees | C16: ='Tier Economics'!E14+'Tier Economics'!E18 -> 641.55 | D16: ='Tier Economics'!I14+'Tier Economics'!I18 -> 79100 | E16: ='Tier Economics'!M14+'Tier Economics'!M18 -> 234100 | F16: ='Tier Economics'!Q14+'Tier Economics'!Q18 -> 1269000 | G16: ='Tier Economics'!U14+'Tier Economics'!U18 -> 2034000 | H16: Tiered document and dispute / amendment fees
B17: Partner/API + other operating add-ons | C17: ='Revenue Risk Add-Ons'!B15-'Revenue Risk Add-Ons'!B5 -> 296 | D17: ='Revenue Risk Add-Ons'!C15-'Revenue Risk Add-Ons'!C5 -> 85710 | E17: ='Revenue Risk Add-Ons'!D15-'Revenue Risk Add-Ons'!D5 -> 184560 | F17: ='Revenue Risk Add-Ons'!E15-'Revenue Risk Add-Ons'!E5 -> 724800 | G17: ='Revenue Risk Add-Ons'!F15-'Revenue Risk Add-Ons'!F5 -> 1235400 | H17: SaaS/API, setup/minimums, KYC, archive, expedited and Tier C pass-through
B18: Total revenue | C18: =SUM(C14:C17) -> 2449.05 | D18: =SUM(D14:D17) -> 404549 | E18: =SUM(E14:E17) -> 1387904 | F18: =SUM(F14:F17) -> 8942691.9 | G18: =SUM(G14:G17) -> 17832614 | H18: Sum of revenue lines
B19: COGS / VARIABLE COSTS
B20: Claude API (doc extraction) | C20: =C10*Assumptions!$F$23/Assumptions!$F$8 -> 4.7460938 | D20: =D10*Assumptions!$F$23/Assumptions!$F$8 -> 685.54688 | E20: =E10*Assumptions!$F$23/Assumptions!$F$8 -> 2390.625 | F20: =F10*Assumptions!$F$23/Assumptions!$F$8 -> 15609.375 | G20: =G10*Assumptions!$F$23/Assumptions!$F$8 -> 28476.562 | H20: USD→GBP
B21: KYB business onboarding | C21: =C11*Assumptions!$F$24/Assumptions!$F$8 -> 8.203125 | D21: =D11*Assumptions!$F$24/Assumptions!$F$8 -> 1367.1875 | E21: =E11*Assumptions!$F$24/Assumptions!$F$8 -> 5468.75 | F21: =F11*Assumptions!$F$24/Assumptions!$F$8 -> 41015.625 | G21: =G11*Assumptions!$F$24/Assumptions!$F$8 -> 82031.25 | H21: Fresh KYB only for new counterparties
B22: KYC/UBO + sanctions onboarding | C22: =C11*Assumptions!$F$25/Assumptions!$F$8 -> 3.1640625 | D22: =D11*Assumptions!$F$25/Assumptions!$F$8 -> 527.34375 | E22: =E11*Assumptions!$F$25/Assumptions!$F$8 -> 2109.375 | F22: =F11*Assumptions!$F$25/Assumptions!$F$8 -> 15820.312 | G22: =G11*Assumptions!$F$25/Assumptions!$F$8 -> 31640.625 | H22: Fresh KYC/KYB only for new counterparties
B23: Tiered document verification ops | C23: =CHOOSE(Assumptions!$C$4,'Scenario Engine'!B36,'Scenario Engine'!H36,'Scenario Engine'!N36) -> 403.2 | D23: =CHOOSE(Assumptions!$C$4,'Scenario Engine'!C36,'Scenario Engine'!I36,'Scenario Engine'!O36) -> 45150 | E23: =CHOOSE(Assumptions!$C$4,'Scenario Engine'!D36,'Scenario Engine'!J36,'Scenario Engine'!P36) -> 119400 | F23: =CHOOSE(Assumptions!$C$4,'Scenario Engine'!E36,'Scenario Engine'!K36,'Scenario Engine'!Q36) -> 558000 | G23: =CHOOSE(Assumptions!$C$4,'Scenario Engine'!F36,'Scenario Engine'!L36,'Scenario Engine'!R36) -> 801000 | H23: External eBL/API/paper + human examiner cost
B24: Blockchain gas | C24: =C7*Assumptions!$F$26/Assumptions!$F$8 -> 0.46875 | D24: =D7*Assumptions!$F$26/Assumptions!$F$8 -> 78.125 | E24: =E7*Assumptions!$F$26/Assumptions!$F$8 -> 312.5 | F24: =F7*Assumptions!$F$26/Assumptions!$F$8 -> 2343.75 | G24: =G7*Assumptions!$F$26/Assumptions!$F$8 -> 4687.5 | H24: Base L2 USD→GBP
B25: RPC / node provider | C25: =C7*Assumptions!$F$27/Assumptions!$F$8 -> 0.0234375 | D25: =D7*Assumptions!$F$27/Assumptions!$F$8 -> 3.90625 | E25: =E7*Assumptions!$F$27/Assumptions!$F$8 -> 15.625 | F25: =F7*Assumptions!$F$27/Assumptions!$F$8 -> 117.1875 | G25: =G7*Assumptions!$F$27/Assumptions!$F$8 -> 234.375 | H25: Deals x RPC cost; USD to GBP
B26: Document / ledger storage | C26: =C7*Assumptions!$F$28/Assumptions!$F$8 -> 0.0703125 | D26: =D7*Assumptions!$F$28/Assumptions!$F$8 -> 11.71875 | E26: =E7*Assumptions!$F$28/Assumptions!$F$8 -> 46.875 | F26: =F7*Assumptions!$F$28/Assumptions!$F$8 -> 351.5625 | G26: =G7*Assumptions!$F$28/Assumptions!$F$8 -> 703.125 | H26: Deals x storage cost; USD to GBP
B27: Customer support | C27: =CHOOSE(Assumptions!$C$4,'Scenario Engine'!B40,'Scenario Engine'!H40,'Scenario Engine'!N40) -> 33 | D27: =CHOOSE(Assumptions!$C$4,'Scenario Engine'!C40,'Scenario Engine'!I40,'Scenario Engine'!O40) -> 4150 | E27: =CHOOSE(Assumptions!$C$4,'Scenario Engine'!D40,'Scenario Engine'!J40,'Scenario Engine'!P40) -> 12600 | F27: =CHOOSE(Assumptions!$C$4,'Scenario Engine'!E40,'Scenario Engine'!K40,'Scenario Engine'!Q40) -> 70800 | G27: =CHOOSE(Assumptions!$C$4,'Scenario Engine'!F40,'Scenario Engine'!L40,'Scenario Engine'!R40) -> 117000 | H27: Tiered support load
B28: Dispute handling + retained-risk variable costs | C28: =CHOOSE(Assumptions!$C$4,SUM('Scenario Engine'!B41:B46),SUM('Scenario Engine'!H41:H46),SUM('Scenario Engine'!N41:N46)) -> 254.28 | D28: =CHOOSE(Assumptions!$C$4,SUM('Scenario Engine'!C41:C46),SUM('Scenario Engine'!I41:I46),SUM('Scenario Engine'!O41:O46)) -> 44744 | E28: =CHOOSE(Assumptions!$C$4,SUM('Scenario Engine'!D41:D46),SUM('Scenario Engine'!J41:J46),SUM('Scenario Engine'!P41:P46)) -> 171904 | F28: =CHOOSE(Assumptions!$C$4,SUM('Scenario Engine'!E41:E46),SUM('Scenario Engine'!K41:K46),SUM('Scenario Engine'!Q41:Q46)) -> 1278865 | G28: =CHOOSE(Assumptions!$C$4,SUM('Scenario Engine'!F41:F46),SUM('Scenario Engine'!L41:L46),SUM('Scenario Engine'!R41:R46)) -> 2747094 | H28: Dispute handling plus QA, forum, reserves, commissions, fallback, leakage
B29: Total COGS | C29: =SUM(C20:C28) -> 707.15578 | D29: =SUM(D20:D28) -> 96717.828 | E29: =SUM(E20:E28) -> 314247.75 | F29: =SUM(F20:F28) -> 1982922.8 | G29: =SUM(G20:G28) -> 3812867.4 | H29: Sum of COGS lines
B30: Gross profit | C30: =C18-C29 -> 1741.8942 | D30: =D18-D29 -> 307831.17 | E30: =E18-E29 -> 1073656.2 | F30: =F18-F29 -> 6959769.1 | G30: =G18-G29 -> 14019746 | H30: Total revenue minus total COGS
