Workbook

Sheet README
B2: Blockmediary - 5-Year Financial Model & Assumptions Pack
B3: Programmable documentary escrow layer for SME cross-border trade (UK / EU / Middle East). Built June 2026.
B5: SCOPE
B6: Blockmediary is a documentary escrow + document-verification SERVICE. It is NOT a lending / financing product.
B7: EXCLUDED by design: lending capital, credit losses, financing spread, invoice advances, FX trading revenue, balance-sheet funding costs.
B8: Buyer prefunds stablecoin into smart-contract escrow; funds release when document rules are satisfied. Blockmediary never takes balance-sheet credit risk.
B10: HOW TO USE
B11: 1. 'Assumptions' is the single control sheet. Blue cells are inputs you change. Black cells are formulas.
B12: 2. The yellow 'Scenario' switch (Assumptions!C4) drives the whole model: 1=Low, 2=Base, 3=High.
B13: 3. 'Startup_6mo' details the first 6 months one-off + ramp costs. 'P&L_5yr' is the annual five-year P&L and 'Cash_Flow_Statement' shows operating cash flow, financing, and break-even.
B14: 4. 'Driver_Tables' holds every researched cost/revenue driver with Low/Base/High, source URL and source quality.
B15: 5. 'Sensitivity' lists the 10 assumptions that move the model most. 'Risk_Register' flags items needing legal/regulatory sign-off.
... B66: Operating cash flow excludes any working-capital timing. Receipts are recognised in the month the annual revenue is smoothed into, with no lag between deal completion and fee collection. In reality there's a gap (and you model "fee collection leakage" at 1% but not timing). A 30–60 day receipts lag would deepen the month-24 trough. Given how thin that trough already is, I'd add even a crude lag to test it.

Sheet Dashboard
B2: ■ INVESTOR DASHBOARD
B4: The base case works if repeat usage compounds before overhead does.
B6: Slide-ready view of the current model: base-case path to EBITDA, monthly cash-flow break-even, funding use, and the downside/base/upside runway spread.
R9: Pitch deck metrics linked to model
C10: =MAX(Scenario_Base_PL!C66:G66)/1000000 -> 1.650223 | G10: =Cash_Flow_Statement!B46 -> Y4 M5 | K10: =Scenario_Base_PL!G18/1000000 -> 14.740255 | O10: =Scenario_Base_PL!G70 -> 1800 | R10: Slide | S10: Metric | T10: Model value | U10: Pitch-copy output | V10: Source / model link | W10: Deck slot
C11: Base funding ask | G11: Base monthly break-even | K11: Y5 annual revenue | O11: Y5 active customers | R11: 7 | S11: Settlement fee range | T11: =ROUND(MIN(Assumptions!$F$73:$F$75)*100,1)&"%-"&ROUND(MAX(Assumptions!$F$73:$F$75)*100,1)&"%" -> 0.6%-1.5% | U11: =T11&" per trade, tier-dependent" -> 0.6%-1.5% per trade, tier-dependent | V11: Assumptions!F73:F75 | W11: Business model card A
C12: peak cash need incl. contingency | G12: cumulative operating cash before financing | K12: base case; escrow + document fees | O12: implied repeat-usage customer base | R12: 7 | S12: Blended gross margin | T12: =ROUND(Scenario_Base_PL!$C$31*100,0)&"%-"&ROUND(Scenario_Base_PL!$G$31*100,0)&"%" -> 57%-83% | U12: =T12&" blended gross margin, base Y1-Y5" -> 57%-83% blended gross margin, base Y1-Y5 | V12: Scenario_Base_PL!C31:G31 | W12: Bottom KPI
R13: 7 | S13: Average ticket | T13: ="GBP "&ROUND(Scenario_Base_PL!$C$8/1000,0)&"K -> GBP "&ROUND(Scenario_Base_PL!$E$8/1000,0)&"K" -> GBP 30K -> GBP 55K | U13: =T13&" average ticket, Y1 to Y3; GBP "&ROUND(Scenario_Base_PL!$G$8/1000,0)&"K by Y5" -> GBP 30K -> GBP 55K average ticket, Y1 to Y3; GBP 100K by Y5 | V13: Scenario_Base_PL!C8:G8 | W13: Bottom KPI
R14: 7 | S14: Processed deals | T14: =ROUND(Scenario_Base_PL!$C$7,0)&" -> "&ROUND(Scenario_Base_PL!$E$7,0) -> 180 -> 3000 | U14: =T14&" processed deals, Y1 to Y3 base case" -> 180 -> 3000 processed deals, Y1 to Y3 base case | V14: Scenario_Base_PL!C7:E7 | W14: Bottom KPI
R15: 11 | S15: Y3 annual revenue range | T15: ="GBP "&ROUND(Scenario_Low_PL!$E$18/1000000,1)&"M-GBP "&ROUND(Scenario_High_PL!$E$18/1000000,1)&"M" -> GBP 0.8M-GBP 4.3M | U15: =T15&" Y3 annual revenue; base GBP "&ROUND(Scenario_Base_PL!$E$18/1000000,1)&"M" -> GBP 0.8M-GBP 4.3M Y3 annual revenue; base GBP 2M | V15: Scenario_*_PL!E18 | W15: Top KPI card
R16: 11 | S16: Y3 active customers range | T16: =ROUND(Scenario_Low_PL!$E$70,0)&"-"&ROUND(Scenario_High_PL!$E$70,0) -> 360-800 | U16: =T16&" Y3 active customers; base "&ROUND(Scenario_Base_PL!$E$70,0) -> 360-800 Y3 active customers; base 500 | V16: Scenario_*_PL!E70 | W16: Top KPI card
C17: Base path to profitability (£m) | K17: Use of funds from Base ask | R17: 11 | S17: Monthly cash-flow breakeven | T17: =Cash_Flow_Statement!$B$46 -> Y4 M5 | U17: ="Base monthly cash-flow break-even: "&T17&"; scenario range "&Cash_Flow_Statement!$B$47&" to "&Cash_Flow_Statement!$B$45 -> Base monthly cash-flow break-even: Y4 M5; scenario range Y3 M5 to Y5 M9 | V17: Cash_Flow_Statement!B45:B47 | W17: Top KPI card
B18: Revenue and EBITDA in GBP millions, by fiscal year. | C18: Revenue scales before the payroll/opex curve catches up. | J18: Use of funds in GBP millions, tied to the modelled funding requirement. | K18: Allocation is tied to the modelled peak funding requirement. | R18: 11 | S18: Seed ask / funding need | T18: ="GBP "&ROUND(Cash_Flow_Statement!$F$46/1000000,2)&"M" -> GBP 1.65M | U18: =T18&" base seed ask; downside funding case GBP "&ROUND(Cash_Flow_Statement!$F$45/1000000,2)&"M" -> GBP 1.65M base seed ask; downside funding case GBP 2.98M | V18: Cash_Flow_Statement!F45:F47 | W18: Top KPI card
R19: 11 | S19: Blended escrow take rate | T19: =ROUND(Tier_Economics!$E$12/Tier_Economics!$E$9*100,1)&"% / "&ROUND(Tier_Economics!$M$12/Tier_Economics!$M$9*100,1)&"% / "&ROUND(Tier_Economics!$U$12/Tier_Economics!$U$9*100,1)&"%" -> 1.1% / 0.8% / 0.7% | U19: =T19&" blended escrow take rate, base Y1 / Y3 / Y5" -> 1.1% / 0.8% / 0.7% blended escrow take rate, base Y1 / Y3 / Y5 | V19: Tier_Economics total escrow fee / GMV | W19: Key assumptions
R20: 11 | S20: Tier A adoption | T20: =ROUND(Assumptions!$D$64*100,0)&"% -> "&ROUND(Assumptions!$D$160*100,0)&"%" -> 15% -> 70% | U20: =T20&" Tier A eBL mix, base Y1 to Y5" -> 15% -> 70% Tier A eBL mix, base Y1 to Y5 | V20: Assumptions!D64,D160 | W20: Key assumptions
R21: 13 | S21: Total seed raise | T21: ="GBP "&ROUND(MAX(Scenario_Base_PL!$C$66:$G$66)/1000000,2)&"M" -> GBP 1.65M | U21: =T21&" total seed raise" -> GBP 1.65M total seed raise | V21: MAX(Scenario_Base_PL!C66:G66) | W21: Total seed raise
R22: 13 | S22: Engineering & product | T22: =ROUND($H$58*100,0)&"% GBP "&ROUND($G$58*1000,0)&"K" -> 40% GBP 660K | U22: =T22 -> 40% GBP 660K | V22: Dashboard!G58:H58 | W22: Use of funds
R23: 13 | S23: Ops, people & G&A | T23: =ROUND($H$59*100,0)&"% GBP "&ROUND($G$59*1000,0)&"K" -> 22% GBP 363K | U23: =T23 -> 22% GBP 363K | V23: Dashboard!G59:H59 | W23: Use of funds
R24: 13 | S24: Compliance, legal & regulatory | T24: =ROUND($H$60*100,0)&"% GBP "&ROUND($G$60*1000,0)&"K" -> 18% GBP 297K | U24: =T24 -> 18% GBP 297K | V24: Dashboard!G60:H60 | W24: Use of funds
R25: 13 | S25: GTM & acquisition | T25: =ROUND($H$61*100,0)&"% GBP "&ROUND($G$61*1000,0)&"K" -> 15% GBP 248K | U25: =T25 -> 15% GBP 248K | V25: Dashboard!G61:H61 | W25: Use of funds
R26: 13 | S26: Working capital + contingency | T26: =ROUND($H$62*100,0)&"% GBP "&ROUND($G$62*1000,0)&"K" -> 5% GBP 83K | U26: =T26 -> 5% GBP 83K | V26: Dashboard!G62:H62 | W26: Use of funds
C35: Monthly cumulative operating cash (£m) | K35: Scenario readout
B36: Ending cash balance in GBP millions at 6-month checkpoints. | C36: Six-month checkpoints avoid unreadable 60-label charts. | J36: Break-even timing and funding gap by scenario. | K36: Break-even timing and funding gap by case.
J37: Case | K37: Monthly BE | L37: Peak gap | M37: M60 cash | N37: Funding ask
J38: Low | K38: =Cash_Flow_Statement!B45 -> Y5 M9 | L38: =Cash_Flow_Statement!C45/1000000 -> 2.2904747 | M38: =Cash_Flow_Statement!D45/1000000 -> 0.98335342 | N38: =Cash_Flow_Statement!F45/1000000 -> 2.977617
J39: Base | K39: =Cash_Flow_Statement!B46 -> Y4 M5 | L39: =Cash_Flow_Statement!C46/1000000 -> 1.2694021 | M39: =Cash_Flow_Statement!D46/1000000 -> 12.220136 | N39: =Cash_Flow_Statement!F46/1000000 -> 1.650223
J40: High | K40: =Cash_Flow_Statement!B47 -> Y3 M5 | L40: =Cash_Flow_Statement!C47/1000000 -> 0.76667051 | M40: =Cash_Flow_Statement!D47/1000000 -> 31.816705 | N40: =Cash_Flow_Statement!F47/1000000 -> 1.236672
K43: ="- Base reaches monthly cash-flow break-even in "&Cash_Flow_Statement!$B$46&"; High reaches "&Cash_Flow_Statement!$B$47&"." -> - Base reaches monthly cash-flow break-even in Y4 M5; High reaches Y3 M5.
K44: ="- Low reaches monthly cash-flow break-even in "&Cash_Flow_Statement!$B$45&"; base Month 60 operating cash is GBP "&ROUND(Cash_Flow_Statement!$D$46/1000000,1)&"M." -> - Low reaches monthly cash-flow break-even in Y5 M9; base Month 60 operating cash is GBP 12.2M.
K45: • No lending spread, FX trading revenue, or balance-sheet credit risk is modelled.
K46: • Tier C paper collection is a priced fallback, not the strategic scale path.
B56: Base path helper | F56: Use of funds helper
B57: Year | C57: Revenue | D57: EBITDA | F57: Category | G57: Amount | H57: %
B58: Y1 | C58: =Scenario_Base_PL!C18/1000000 -> 0.107505 | D58: =Scenario_Base_PL!C61/1000000 -> -0.57636506 | F58: Engineering/product | G58: =MAX(Scenario_Base_PL!C66:G66)*H58/1000000 -> 0.6600892 | H58: 0.4
B59: Y2 | C59: =Scenario_Base_PL!D18/1000000 -> 0.59877675 | D59: =Scenario_Base_PL!D61/1000000 -> -0.45192455 | F59: Ops/people/G&A | G59: =MAX(Scenario_Base_PL!C66:G66)*H59/1000000 -> 0.36304906 | H59: 0.22
B60: Y3 | C60: =Scenario_Base_PL!E18/1000000 -> 1.9593487 | D60: =Scenario_Base_PL!E61/1000000 -> 0.30703247 | F60: Compliance/legal | G60: =MAX(Scenario_Base_PL!C66:G66)*H60/1000000 -> 0.29704014 | H60: 0.18
B61: Y4 | C61: =Scenario_Base_PL!F18/1000000 -> 5.2198545 | D61: =Scenario_Base_PL!F61/1000000 -> 2.6945588 | F61: GTM/acquisition | G61: =MAX(Scenario_Base_PL!C66:G66)*H61/1000000 -> 0.24753345 | H61: 0.15
B62: Y5 | C62: =Scenario_Base_PL!G18/1000000 -> 14.740255 | D62: =Scenario_Base_PL!G61/1000000 -> 10.487947 | F62: Contingency | G62: =MAX(Scenario_Base_PL!C66:G66)*H62/1000000 -> 0.08251115 | H62: 0.05
B66: Cash runway helper
B67: Checkpoint | C67: Low | D67: Base | E67: High
...

Sheet Assumptions
B2: Assumptions — Control Panel
B3: Scenario columns are only used for true adoption/mix drivers. Fixed inputs use one value in column F and flow through every downstream sheet.
B4: SCENARIO SWITCH (1/2/3) | C4: 2 | D4: =CHOOSE($C$4,"LOW","BASE","HIGH") -> BASE
B6: Assumption | C6: Low scenario | D6: Base scenario | E6: High scenario | F6: Active / fixed value | G6: Unit | H6: Notes / source quality
B7: -- GLOBAL --
B8: GBP:USD FX rate | F8: 1.28 | G8: $/£ | H8: Fixed input; not scenario-driven. Planning rate; verify at build time (estimate)
B9: Months modelled per year | F9: 12 | G9: months | H9: Fixed input; not scenario-driven.
B10: -- DEAL VOLUME / CORE OPERATING DRIVERS --
B11: Year 1 deals (total) | C11: 60 | D11: 180 | E11: 400 | F11: =CHOOSE($C$4,C11,D11,E11) -> 180 | G11: deals/yr | H11: Pilot→paid ramp. Pre-seed B2B fintech (estimate)
B12: Year 2 deals (total) | C12: 300 | D12: 900 | E12: 2200 | F12: =CHOOSE($C$4,C12,D12,E12) -> 900 | G12: deals/yr | H12: estimate
B13: Year 3 deals (total) | C13: 900 | D13: 3000 | E13: 8000 | F13: =CHOOSE($C$4,C13,D13,E13) -> 3000 | G13: deals/yr | H13: estimate
B14: Avg intitial deal (trade) value (first year) | F14: 30000 | G14: £/deal | H14: Fixed input; not scenario-driven. Avg SME cross-border invoice (estimate)
B15: Avg deal (trade) value growth (yearly) | F15: 0.35 | G15: %/yr | H15: Fixed input; annual growth applied to avg deal value in active and scenario P&L models.
B16: Avg counterparties / deal before repeat adjustment | F16: 2 | G16: parties/deal | H16: Fixed input; not scenario-driven. Buyer + seller before repeat-customer onboarding adjustment
B17: Partner count Yr2 | C17: 0 | D17: 3 | E17: 10 | F17: =CHOOSE($C$4,C17,D17,E17) -> 3 | G17: partners | H17: API/platform partners live by Year 2
B18: -- TRANSACTION COGS --
B19: Claude API cost / document | F19: 0.03 | G19: $/doc | H19: Fixed input; not scenario-driven. Haiku/Sonnet extraction. Anthropic $1/$5–$3/$15 MTok (vendor)
B20: KYB screening / business party | F20: 3.5 | G20: $/party | H20: Fixed input; not scenario-driven. Didit fr $2, Sumsub tier (vendor)
B21: KYC/UBO+sanctions / person | F21: 1.35 | G21: $/person | H21: Fixed input; not scenario-driven. Didit $0.30 / Sumsub $1.35 (vendor)
B22: Blockchain gas / deal (multi-tx) | F22: 0.2 | G22: $/deal | H22: Fixed input; not scenario-driven. Base L2, several txns/deal (official: Base docs)
B23: RPC/node provider / deal | F23: 0.01 | G23: $/deal | H23: Fixed input; not scenario-driven. Alchemy/QuickNode metered (vendor/estimate)
B24: Doc + audit-ledger storage / deal | F24: 0.03 | G24: $/deal | H24: Fixed input; not scenario-driven. S3/object storage per deal (vendor/estimate)
B25: -- FIXED OPEX --
B26: Cloud hosting (Vercel/AWS) | F26: 250 | G26: £/mo | H26: Fixed input; not scenario-driven. Vercel Pro $20/seat + AWS/usage (vendor)
B27: Database + object storage | F27: 120 | G27: £/mo | H27: Fixed input; not scenario-driven. Managed Postgres + S3 (vendor/estimate)
B28: Monitoring/logging/security tools | F28: 150 | G28: £/mo | H28: Fixed input; not scenario-driven. Sentry/Datadog/Snyk tiers (vendor/estimate)
B29: GitHub + dev SaaS | F29: 60 | G29: £/mo | H29: Fixed input; not scenario-driven. GitHub $4–21/user (vendor)
B30: Google Workspace / collab | F30: 90 | G30: £/mo | H30: Fixed input; not scenario-driven. ~£12/user Business Standard (vendor)
B31: CRM + BD tooling | F31: 80 | G31: £/mo | H31: Fixed input; not scenario-driven. HubSpot/Pipedrive (vendor/estimate)
B32: Accounting/payroll/bookkeeping | F32: 350 | G32: £/mo | H32: Fixed input; not scenario-driven. Outsourced (estimate)
B33: Legal retainer (ongoing) | F33: 600 | G33: £/mo | H33: Fixed input; not scenario-driven. Commercial + regulatory queries (estimate)
B34: Compliance / MLRO support | F34: 1200 | G34: £/mo | H34: Fixed input; not scenario-driven. Fractional MLRO/consultant (benchmark/estimate)
B35: Marketing / conferences / partnerships | F35: 1500 | G35: £/mo | H35: Fixed input; not scenario-driven. Trade events, content (estimate)
B36: Office / coworking | F36: 400 | G36: £/mo | H36: Fixed input; not scenario-driven. Hot-desk → small office (estimate)
B37: Insurance (PI+cyber+D&O) / mo | F37: 700 | G37: £/mo | H37: Fixed input; not scenario-driven. Annualised /12; fintech loading (benchmark/estimate)
B38: -- HEADCOUNT BASELINE --
B39: Founders (FTE) | F39: 2 | G39: FTE | H39: Fixed input; not scenario-driven.
B40: Engineers Yr1 baseline | F40: 2 | G40: FTE Yr1 | H40: Fixed input; not scenario-driven. Scaled in P&L by year (benchmark)
B41: Compliance/ops Yr1 baseline | F41: 1 | G41: FTE Yr1 | H41: Fixed input; not scenario-driven. Compliance/ops baseline headcount starts at one FTE.
B42: Sales/BD + CS Yr1 baseline | F42: 1 | G42: FTE Yr1 | H42: Fixed input; not scenario-driven. (benchmark)
...

Sheet Startup_6mo
B2: First 6 Months — Startup Costs (one-off + setup ramp)
B3: One-off costs incurred in months 0-6. Recurring opex/payroll lives in P&L_5yr. Scenario-driven (Low/Base/High).
B5: Cost driver | C5: Low | D5: Base | E5: High | F5: Active | G5: Cur | H5: Notes / source quality
B6: COMPANY FORMATION & FILINGS
B7: Companies House digital incorporation | C7: 100 | D7: 100 | E7: 100 | F7: =CHOOSE(Assumptions!$C$4,C7,D7,E7) -> 100 | G7: £ | H7: £100 from 1 Feb 2026 (official: Companies House)
B8: Registered office / address service (6mo) | C8: 30 | D8: 90 | E8: 180 | F8: =CHOOSE(Assumptions!$C$4,C8,D8,E8) -> 90 | G8: £ | H8: Virtual office (vendor/estimate)
B9: Director ID verification / ACSP | C9: 0 | D9: 63 | E9: 63 | F9: =CHOOSE(Assumptions!$C$4,C9,D9,E9) -> 63 | G9: £ | H9: ACSP £63; One Login free (official)
B10: Confirmation statement (annual) | C10: 50 | D10: 50 | E10: 50 | F10: =CHOOSE(Assumptions!$C$4,C10,D10,E10) -> 50 | G10: £ | H10: £50 digital from Feb 2026 (official)
B11: LEGAL SETUP
B12: Shareholder agreement | C12: 375 | D12: 1500 | E12: 3000 | F12: =CHOOSE(Assumptions!$C$4,C12,D12,E12) -> 1500 | G12: £ | H12: £375–£3,000 fixed-fee (benchmark)
B13: IP assignment (founders/contractors) | C13: 200 | D13: 600 | E13: 1500 | F13: =CHOOSE(Assumptions!$C$4,C13,D13,E13) -> 600 | G13: £ | H13: Assign IP into company (estimate)
B14: Articles / cap table / SAFE setup | C14: 0 | D14: 1000 | E14: 3000 | F14: =CHOOSE(Assumptions!$C$4,C14,D14,E14) -> 1000 | G14: £ | H14: SAFE/ASA template + review (estimate)
B15: Website terms + privacy policy | C15: 300 | D15: 900 | E15: 2500 | F15: =CHOOSE(Assumptions!$C$4,C15,D15,E15) -> 900 | G15: £ | H15: Bespoke for fintech (estimate)
B16: Trade Escrow Agreement template (bespoke) | C16: 3000 | D16: 8000 | E16: 18000 | F16: =CHOOSE(Assumptions!$C$4,C16,D16,E16) -> 8000 | G16: £ | H16: Core product contract; bespoke drafting (estimate)
B17: REGULATORY & COMPLIANCE SETUP
B18: Regulatory perimeter advice (crypto/stablecoin escrow) | C18: 8000 | D18: 25000 | E18: 60000 | F18: =CHOOSE(Assumptions!$C$4,C18,D18,E18) -> 25000 | G18: £ | H18: HIGH RISK. FCA crypto regime 2027; safeguarding may be in-scope (estimate)
B19: AML/KYC/sanctions policy + procedures | C19: 2000 | D19: 6000 | E19: 15000 | F19: =CHOOSE(Assumptions!$C$4,C19,D19,E19) -> 6000 | G19: £ | H19: MLR 2017 policy pack + MLRO setup (estimate)
B20: Data protection / GDPR setup (DPIA, ROPA) | C20: 1000 | D20: 3000 | E20: 8000 | F20: =CHOOSE(Assumptions!$C$4,C20,D20,E20) -> 3000 | G20: £ | H20: ICO registration £40–60 + advice (official+estimate)
B21: ICO data protection fee | C21: 52 | D21: 60 | E21: 60 | F21: =CHOOSE(Assumptions!$C$4,C21,D21,E21) -> 60 | G21: £ | H21: ICO annual fee tier (official: ICO)
B22: SECURITY
B23: Smart-contract audit / security review | C23: 12000 | D23: 30000 | E23: 60000 | F23: =CHOOSE(Assumptions!$C$4,C23,D23,E23) -> 30000 | G23: £ | H23: Moderate-complexity escrow contracts (benchmark)
B24: Penetration test (web app) | C24: 3000 | D24: 7000 | E24: 15000 | F24: =CHOOSE(Assumptions!$C$4,C24,D24,E24) -> 7000 | G24: £ | H24: Pre-launch pentest (vendor/estimate)
B25: PRODUCT BUILD (one-off, pre-revenue)
B26: Smart-contract development (contract) | C26: 15000 | D26: 40000 | E26: 90000 | F26: =CHOOSE(Assumptions!$C$4,C26,D26,E26) -> 40000 | G26: £ | H26: Solidity build; days × day-rate (estimate)
B27: Web app / full-stack build (contract) | C27: 20000 | D27: 50000 | E27: 110000 | F27: =CHOOSE(Assumptions!$C$4,C27,D27,E27) -> 50000 | G27: £ | H27: MVP build incl. integrations (estimate)
B28: UI/UX design | C28: 3000 | D28: 9000 | E28: 20000 | F28: =CHOOSE(Assumptions!$C$4,C28,D28,E28) -> 9000 | G28: £ | H28: (estimate)
B29: BRAND, DECK & WEB
B30: Pitch deck + brand identity | C30: 1500 | D30: 5000 | E30: 12000 | F30: =CHOOSE(Assumptions!$C$4,C30,D30,E30) -> 5000 | G30: £ | H30: (estimate)
B31: Marketing website | C31: 1000 | D31: 4000 | E31: 10000 | F31: =CHOOSE(Assumptions!$C$4,C31,D31,E31) -> 4000 | G31: £ | H31: (estimate)
B32: Domain + email + initial SaaS | C32: 100 | D32: 300 | E32: 800 | F32: =CHOOSE(Assumptions!$C$4,C32,D32,E32) -> 300 | G32: £ | H32: Domain, Workspace setup (vendor)
B33: BUSINESS DEVELOPMENT (setup)
B34: Pilot outreach / travel (UK/EU/ME) | C34: 1000 | D34: 5000 | E34: 15000 | F34: =CHOOSE(Assumptions!$C$4,C34,D34,E34) -> 5000 | G34: £ | H34: ME travel pushes high end (estimate)
B35: Conferences / trade events (first 6mo) | C35: 1000 | D35: 4000 | E35: 12000 | F35: =CHOOSE(Assumptions!$C$4,C35,D35,E35) -> 4000 | G35: £ | H35: (estimate)
B36: INSURANCE (first-year, paid upfront)
B37: Professional indemnity (annual) | C37: 1200 | D37: 3500 | E37: 9000 | F37: =CHOOSE(Assumptions!$C$4,C37,D37,E37) -> 3500 | G37: £ | H37: Prepaid first-year insurance; do not also include Year 1 monthly insurance in P&L.
B38: Cyber insurance (annual) | C38: 1000 | D38: 3000 | E38: 8000 | F38: =CHOOSE(Assumptions!$C$4,C38,D38,E38) -> 3000 | G38: £ | H38: Prepaid first-year insurance; do not also include Year 1 monthly insurance in P&L.
B39: D&O insurance (annual) | C39: 800 | D39: 2500 | E39: 7000 | F39: =CHOOSE(Assumptions!$C$4,C39,D39,E39) -> 2500 | G39: £ | H39: Prepaid first-year insurance; do not also include Year 1 monthly insurance in P&L.
B40: CONTINGENCY
B41: Contingency on one-off costs | C41: 0.1 | D41: 0.15 | E41: 0.2 | F41: =CHOOSE(Assumptions!$C$4,C41,D41,E41) -> 0.15 | G41: % | H41: Applied to subtotal (estimate)
B42: Subtotal one-off costs (ex-contingency) | F42: =SUMIF($G$6:$G$40,"£",$F$6:$F$40) -> 209663
...

Sheet Cash_Flow_Statement
A1: Cash Flow Statement - monthly 60-month projection
A2: Active scenario is controlled by Assumptions!C4. Year 1 revenue/COGS are phased after the pre-revenue months; startup costs are paid over months 1-6; financing is staged as the implied funding ask steps up.
G3: Peak cumulative operating deficit | J3: Month 60 operating cash
A4: Active scenario | B4: =Assumptions!$D$4 -> BASE | D4: Cash-flow break-even month | E4: =IF(MAX(B38:BI38)<0,"Beyond Month 60",INDEX($B$9:$BI$9,1,MATCH(TRUE,INDEX(B38:BI38>=0,0),0))) -> Y4 M5 | H4: =-MIN(0,B38:BI38) -> 1269402.1 | K4: =BI38 -> 12220136
A6: Month # | B6: 1 | C6: 2 | D6: 3 | E6: 4 | F6: 5 | G6: 6 | H6: 7 | I6: 8 | J6: 9 | K6: 10 | L6: 11 | M6: 12 | N6: 13 | O6: 14 | P6: 15 | Q6: 16 | R6: 17 | S6: 18 | T6: 19 | U6: 20 | V6: 21 | W6: 22 | X6: 23 | Y6: 24 | Z6: 25 | AA6: 26 | AB6: 27 | AC6: 28 | AD6: 29 | AE6: 30 | AF6: 31 | AG6: 32 | AH6: 33 | AI6: 34 | AJ6: 35 | AK6: 36 | AL6: 37 | AM6: 38 | AN6: 39 | AO6: 40 | AP6: 41 | AQ6: 42 | AR6: 43 | AS6: 44 | AT6: 45 | AU6: 46 | AV6: 47 | AW6: 48 | AX6: 49 | AY6: 50 | AZ6: 51 | BA6: 52 | BB6: 53 | BC6: 54 | BD6: 55 | BE6: 56 | BF6: 57 | BG6: 58 | BH6: 59 | BI6: 60 | BK6: Logic / note
A7: Model year | B7: =ROUNDUP(B$6/12,0) -> 1 | C7: =ROUNDUP(C$6/12,0) -> 1 | D7: =ROUNDUP(D$6/12,0) -> 1 | E7: =ROUNDUP(E$6/12,0) -> 1 | F7: =ROUNDUP(F$6/12,0) -> 1 | G7: =ROUNDUP(G$6/12,0) -> 1 | H7: =ROUNDUP(H$6/12,0) -> 1 | I7: =ROUNDUP(I$6/12,0) -> 1 | ... BI7: =ROUNDUP(BI$6/12,0) -> 5
A8: Month in year | B8: =MOD(B$6-1,12)+1 -> 1 | C8: =MOD(C$6-1,12)+1 -> 2 | D8: =MOD(D$6-1,12)+1 -> 3 | E8: =MOD(E$6-1,12)+1 -> 4 | F8: =MOD(F$6-1,12)+1 -> 5 | G8: =MOD(G$6-1,12)+1 -> 6 | H8: =MOD(H$6-1,12)+1 -> 7 | I8: =MOD(I$6-1,12)+1 -> 8 | ... BI8: =MOD(BI$6-1,12)+1 -> 12
A9: Period | B9: ="Y"&B$7&" M"&B$8 -> Y1 M1 | C9: ="Y"&C$7&" M"&C$8 -> Y1 M2 | D9: ="Y"&D$7&" M"&D$8 -> Y1 M3 | E9: ="Y"&E$7&" M"&E$8 -> Y1 M4 | F9: ="Y"&F$7&" M"&F$8 -> Y1 M5 | G9: ="Y"&G$7&" M"&G$8 -> Y1 M6 | H9: ="Y"&H$7&" M"&H$8 -> Y1 M7 | I9: ="Y"&I$7&" M"&I$8 -> Y1 M8 | ... BI9: ="Y"&BI$7&" M"&BI$8 -> Y5 M12
A11: CASH FLOWS FROM OPERATING ACTIVITIES
A12: Customer receipts | B12: =IF(B$7=1,IF(B$8<=Assumptions!$F$59,0,INDEX('P&L_5yr'!$C$18:$G$18,1,B$7)/MAX(1,12-Assumptions!$F$59)),INDEX('P&L_5yr'!$C$18:$G$18,1,B$7)/12) -> 0 | C12: =IF(C$7=1,IF(C$8<=Assumptions!$F$59,0,INDEX('P&L_5yr'!$C$18:$G$18,1,C$7)/MAX(1,12-Assumptions!$F$59)),INDEX('P&L_5yr'!$C$18:$G$18,1,C$7)/12) -> 0 | D12: =IF(D$7=1,IF(D$8<=Assumptions!$F$59,0,INDEX('P&L_5yr'!$C$18:$G$18,1,D$7)/MAX(1,12-Assumptions!$F$59)),INDEX('P&L_5yr'!$C$18:$G$18,1,D$7)/12) -> 0 | E12: =IF(E$7=1,IF(E$8<=Assumptions!$F$59,0,INDEX('P&L_5yr'!$C$18:$G$18,1,E$7)/MAX(1,12-Assumptions!$F$59)),INDEX('P&L_5yr'!$C$18:$G$18,1,E$7)/12) -> 0 | F12: =IF(F$7=1,IF(F$8<=Assumptions!$F$59,0,INDEX('P&L_5yr'!$C$18:$G$18,1,F$7)/MAX(1,12-Assumptions!$F$59)),INDEX('P&L_5yr'!$C$18:$G$18,1,F$7)/12) -> 0 | G12: =IF(G$7=1,IF(G$8<=Assumptions!$F$59,0,INDEX('P&L_5yr'!$C$18:$G$18,1,G$7)/MAX(1,12-Assumptions!$F$59)),INDEX('P&L_5yr'!$C$18:$G$18,1,G$7)/12) -> 0 | H12: =IF(H$7=1,IF(H$8<=Assumptions!$F$59,0,INDEX('P&L_5yr'!$C$18:$G$18,1,H$7)/MAX(1,12-Assumptions!$F$59)),INDEX('P&L_5yr'!$C$18:$G$18,1,H$7)/12) -> 17917.5 | I12: =IF(I$7=1,IF(I$8<=Assumptions!$F$59,0,INDEX('P&L_5yr'!$C$18:$G$18,1,I$7)/MAX(1,12-Assumptions!$F$59)),INDEX('P&L_5yr'!$C$18:$G$18,1,I$7)/12) -> 17917.5 | ... BI12: =IF(BI$7=1,IF(BI$8<=Assumptions!$F$59,0,INDEX('P&L_5yr'!$C$18:$G$18,1,BI$7)/MAX(1,12-Assumptions!$F$59)),INDEX('P&L_5yr'!$C$18:$G$18,1,BI$7)/12) -> 1228354.6 | BK12: Revenue receipts are phased after Year 1 pre-revenue months; Years 2-5 are straight-lined monthly.
A13: Variable COGS cash payments | B13: =-IF(B$7=1,IF(B$8<=Assumptions!$F$59,0,INDEX('P&L_5yr'!$C$29:$G$29,1,B$7)/MAX(1,12-Assumptions!$F$59)),INDEX('P&L_5yr'!$C$29:$G$29,1,B$7)/12) -> 0 | C13: =-IF(C$7=1,IF(C$8<=Assumptions!$F$59,0,INDEX('P&L_5yr'!$C$29:$G$29,1,C$7)/MAX(1,12-Assumptions!$F$59)),INDEX('P&L_5yr'!$C$29:$G$29,1,C$7)/12) -> 0 | D13: =-IF(D$7=1,IF(D$8<=Assumptions!$F$59,0,INDEX('P&L_5yr'!$C$29:$G$29,1,D$7)/MAX(1,12-Assumptions!$F$59)),INDEX('P&L_5yr'!$C$29:$G$29,1,D$7)/12) -> 0 | E13: =-IF(E$7=1,IF(E$8<=Assumptions!$F$59,0,INDEX('P&L_5yr'!$C$29:$G$29,1,E$7)/MAX(1,12-Assumptions!$F$59)),INDEX('P&L_5yr'!$C$29:$G$29,1,E$7)/12) -> 0 | F13: =-IF(F$7=1,IF(F$8<=Assumptions!$F$59,0,INDEX('P&L_5yr'!$C$29:$G$29,1,F$7)/MAX(1,12-Assumptions!$F$59)),INDEX('P&L_5yr'!$C$29:$G$29,1,F$7)/12) -> 0 | G13: =-IF(G$7=1,IF(G$8<=Assumptions!$F$59,0,INDEX('P&L_5yr'!$C$29:$G$29,1,G$7)/MAX(1,12-Assumptions!$F$59)),INDEX('P&L_5yr'!$C$29:$G$29,1,G$7)/12) -> 0 | H13: =-IF(H$7=1,IF(H$8<=Assumptions!$F$59,0,INDEX('P&L_5yr'!$C$29:$G$29,1,H$7)/MAX(1,12-Assumptions!$F$59)),INDEX('P&L_5yr'!$C$29:$G$29,1,H$7)/12) -> -7745.0096 | I13: =-IF(I$7=1,IF(I$8<=Assumptions!$F$59,0,INDEX('P&L_5yr'!$C$29:$G$29,1,I$7)/MAX(1,12-Assumptions!$F$59)),INDEX('P&L_5yr'!$C$29:$G$29,1,I$7)/12) -> -7745.0096 | ... BI13: =-IF(BI$7=1,IF(BI$8<=Assumptions!$F$59,0,INDEX('P&L_5yr'!$C$29:$G$29,1,BI$7)/MAX(1,12-Assumptions!$F$59)),INDEX('P&L_5yr'!$C$29:$G$29,1,BI$7)/12) -> -211688.98 | BK13: COGS follows the same revenue phasing.
A14: Gross operating cash margin | B14: =SUM(B12:B13) -> 0 | C14: =SUM(C12:C13) -> 0 | D14: =SUM(D12:D13) -> 0 | E14: =SUM(E12:E13) -> 0 | F14: =SUM(F12:F13) -> 0 | G14: =SUM(G12:G13) -> 0 | H14: =SUM(H12:H13) -> 10172.49 | I14: =SUM(I12:I13) -> 10172.49 | ... BI14: =SUM(BI12:BI13) -> 1016665.6
A15: Payroll cash payments | B15: =-INDEX('P&L_5yr'!$C$42:$G$42,1,B$7)/12 -> -33316.667 | C15: =-INDEX('P&L_5yr'!$C$42:$G$42,1,C$7)/12 -> -33316.667 | D15: =-INDEX('P&L_5yr'!$C$42:$G$42,1,D$7)/12 -> -33316.667 | E15: =-INDEX('P&L_5yr'!$C$42:$G$42,1,E$7)/12 -> -33316.667 | F15: =-INDEX('P&L_5yr'!$C$42:$G$42,1,F$7)/12 -> -33316.667 | G15: =-INDEX('P&L_5yr'!$C$42:$G$42,1,G$7)/12 -> -33316.667 | H15: =-INDEX('P&L_5yr'!$C$42:$G$42,1,H$7)/12 -> -33316.667 | I15: =-INDEX('P&L_5yr'!$C$42:$G$42,1,I$7)/12 -> -33316.667 | ... BI15: =-INDEX('P&L_5yr'!$C$42:$G$42,1,BI$7)/12 -> -105766.67 | BK15: Annual payroll from P&L_5yr divided by 12.
A16: Fixed opex cash payments | B16: =-INDEX('P&L_5yr'!$C$56:$G$56,1,B$7)/12 -> -19800 | C16: =-INDEX('P&L_5yr'!$C$56:$G$56,1,C$7)/12 -> -19800 | D16: =-INDEX('P&L_5yr'!$C$56:$G$56,1,D$7)/12 -> -19800 | E16: =-INDEX('P&L_5yr'!$C$56:$G$56,1,E$7)/12 -> -19800 | F16: =-INDEX('P&L_5yr'!$C$56:$G$56,1,F$7)/12 -> -19800 | G16: =-INDEX('P&L_5yr'!$C$56:$G$56,1,G$7)/12 -> -19800 | H16: =-INDEX('P&L_5yr'!$C$56:$G$56,1,H$7)/12 -> -19800 | I16: =-INDEX('P&L_5yr'!$C$56:$G$56,1,I$7)/12 -> -19800 | ... BI16: =-INDEX('P&L_5yr'!$C$56:$G$56,1,BI$7)/12 -> -36903.333 | BK16: Annual fixed opex from P&L_5yr divided by 12.
A17: Startup / one-off cash payments | B17: =-IF(B$6<=6,'P&L_5yr'!$C$58/6,0) -> -40185.408 | C17: =-IF(C$6<=6,'P&L_5yr'!$C$58/6,0) -> -40185.408 | D17: =-IF(D$6<=6,'P&L_5yr'!$C$58/6,0) -> -40185.408 | E17: =-IF(E$6<=6,'P&L_5yr'!$C$58/6,0) -> -40185.408 | F17: =-IF(F$6<=6,'P&L_5yr'!$C$58/6,0) -> -40185.408 | G17: =-IF(G$6<=6,'P&L_5yr'!$C$58/6,0) -> -40185.408 | H17: =-IF(H$6<=6,'P&L_5yr'!$C$58/6,0) -> 0 | I17: =-IF(I$6<=6,'P&L_5yr'!$C$58/6,0) -> 0 | ... BI17: =-IF(BI$6<=6,'P&L_5yr'!$C$58/6,0) -> 0 | BK17: Startup_6mo / Year 1 one-off spend paid over months 1-6.
A18: Working capital / settlement float | B18: =0 -> 0 | C18: =0 -> 0 | D18: =0 -> 0 | E18: =0 -> 0 | F18: =0 -> 0 | G18: =0 -> 0 | H18: =0 -> 0 | I18: =0 -> 0 | ... BI18: =0 -> 0 | BK18: Client escrow funds remain restricted/off-balance-sheet; no settlement float benefit is modelled.
A19: Net cash from operating activities | B19: =B14+SUM(B15:B18) -> -93302.075 | C19: =C14+SUM(C15:C18) -> -93302.075 | D19: =D14+SUM(D15:D18) -> -93302.075 | E19: =E14+SUM(E15:E18) -> -93302.075 | F19: =F14+SUM(F15:F18) -> -93302.075 | G19: =G14+SUM(G15:G18) -> -93302.075 | H19: =H14+SUM(H15:H18) -> -42944.176 | I19: =I14+SUM(I15:I18) -> -42944.176 | ... BI19: =BI14+SUM(BI15:BI18) -> 873995.58
A21: CASH FLOWS FROM INVESTING ACTIVITIES
A22: Capitalised development / capex | B22: =0 -> 0 | C22: =0 -> 0 | D22: =0 -> 0 | E22: =0 -> 0 | F22: =0 -> 0 | G22: =0 -> 0 | H22: =0 -> 0 | I22: =0 -> 0 | ... BI22: =0 -> 0
A23: Net cash from investing activities | B23: =B22 -> 0 | C23: =C22 -> 0 | D23: =D22 -> 0 | E23: =E22 -> 0 | F23: =F22 -> 0 | G23: =G22 -> 0 | H23: =H22 -> 0 | I23: =I22 -> 0 | ... BI23: =BI22 -> 0
A25: CASH FLOWS FROM FINANCING ACTIVITIES
A26: External funding raised | B26: =IF(B$8=1,IF(B$7=1,'P&L_5yr'!$C$66,MAX(0,INDEX('P&L_5yr'!$C$66:$G$66,1,B$7)-INDEX('P&L_5yr'!$C$66:$G$66,1,B$7-1))),0) -> 1302721 | C26: =IF(C$8=1,IF(C$7=1,'P&L_5yr'!$C$66,MAX(0,INDEX('P&L_5yr'!$C$66:$G$66,1,C$7)-INDEX('P&L_5yr'!$C$66:$G$66,1,C$7-1))),0) -> 0 | D26: =IF(D$8=1,IF(D$7=1,'P&L_5yr'!$C$66,MAX(0,INDEX('P&L_5yr'!$C$66:$G$66,1,D$7)-INDEX('P&L_5yr'!$C$66:$G$66,1,D$7-1))),0) -> 0 | E26: =IF(E$8=1,IF(E$7=1,'P&L_5yr'!$C$66,MAX(0,INDEX('P&L_5yr'!$C$66:$G$66,1,E$7)-INDEX('P&L_5yr'!$C$66:$G$66,1,E$7-1))),0) -> 0 | F26: =IF(F$8=1,IF(F$7=1,'P&L_5yr'!$C$66,MAX(0,INDEX('P&L_5yr'!$C$66:$G$66,1,F$7)-INDEX('P&L_5yr'!$C$66:$G$66,1,F$7-1))),0) -> 0 | G26: =IF(G$8=1,IF(G$7=1,'P&L_5yr'!$C$66,MAX(0,INDEX('P&L_5yr'!$C$66:$G$66,1,G$7)-INDEX('P&L_5yr'!$C$66:$G$66,1,G$7-1))),0) -> 0 | H26: =IF(H$8=1,IF(H$7=1,'P&L_5yr'!$C$66,MAX(0,INDEX('P&L_5yr'!$C$66:$G$66,1,H$7)-INDEX('P&L_5yr'!$C$66:$G$66,1,H$7-1))),0) -> 0 | I26: =IF(I$8=1,IF(I$7=1,'P&L_5yr'!$C$66,MAX(0,INDEX('P&L_5yr'!$C$66:$G$66,1,I$7)-INDEX('P&L_5yr'!$C$66:$G$66,1,I$7-1))),0) -> 0 | ... BI26: =IF(BI$8=1,IF(BI$7=1,'P&L_5yr'!$C$66,MAX(0,INDEX('P&L_5yr'!$C$66:$G$66,1,BI$7)-INDEX('P&L_5yr'!$C$66:$G$66,1,BI$7-1))),0) -> 0 | BK26: Raised in month 1 of any year when the cumulative funding ask steps up.
A27: Restricted contingency reserve set aside | B27: =IF(B$8=1,-INDEX('P&L_5yr'!$C$65:$G$65,1,B$7),0) -> -240000 | C27: =IF(C$8=1,-INDEX('P&L_5yr'!$C$65:$G$65,1,C$7),0) -> 0 | D27: =IF(D$8=1,-INDEX('P&L_5yr'!$C$65:$G$65,1,D$7),0) -> 0 | E27: =IF(E$8=1,-INDEX('P&L_5yr'!$C$65:$G$65,1,E$7),0) -> 0 | F27: =IF(F$8=1,-INDEX('P&L_5yr'!$C$65:$G$65,1,F$7),0) -> 0 | G27: =IF(G$8=1,-INDEX('P&L_5yr'!$C$65:$G$65,1,G$7),0) -> 0 | H27: =IF(H$8=1,-INDEX('P&L_5yr'!$C$65:$G$65,1,H$7),0) -> 0 | I27: =IF(I$8=1,-INDEX('P&L_5yr'!$C$65:$G$65,1,I$7),0) -> 0 | ... BI27: =IF(BI$8=1,-INDEX('P&L_5yr'!$C$65:$G$65,1,BI$7),0) -> 0 | BK27: Funding-only contingency reserve is separated from unrestricted operating cash.
A28: Net cash from financing activities | B28: =SUM(B26:B27) -> 1062721 | C28: =SUM(C26:C27) -> 0 | D28: =SUM(D26:D27) -> 0 | E28: =SUM(E26:E27) -> 0 | F28: =SUM(F26:F27) -> 0 | G28: =SUM(G26:G27) -> 0 | H28: =SUM(H26:H27) -> 0 | I28: =SUM(I26:I27) -> 0 | ... BI28: =SUM(BI26:BI27) -> 0
A30: CASH RECONCILIATION
A31: Opening unrestricted cash | B31: 0 | C31: =B33 -> 969418.93 | D31: =C33 -> 876116.85 | E31: =D33 -> 782814.78 | F31: =E33 -> 689512.7 | G31: =F33 -> 596210.63 | H31: =G33 -> 502908.55 | I31: =H33 -> 459964.37 | J31: =I33 -> 417020.2 | ... BI31: =BH33 -> 12756364
A32: Net change in unrestricted cash | B32: =B19+B23+B28 -> 969418.93 | C32: =C19+C23+C28 -> -93302.075 | D32: =D19+D23+D28 -> -93302.075 | E32: =E19+E23+E28 -> -93302.075 | F32: =F19+F23+F28 -> -93302.075 | G32: =G19+G23+G28 -> -93302.075 | H32: =H19+H23+H28 -> -42944.176 | I32: =I19+I23+I28 -> -42944.176 | ... BI32: =BI19+BI23+BI28 -> 873995.58
A33: Closing unrestricted cash | B33: =B31+B32 -> 969418.93 | C33: =C31+C32 -> 876116.85 | D33: =D31+D32 -> 782814.78 | E33: =E31+E32 -> 689512.7 | F33: =F31+F32 -> 596210.63 | G33: =G31+G32 -> 502908.55 | H33: =H31+H32 -> 459964.37 | I33: =I31+I32 -> 417020.2 | ... BI33: =BI31+BI32 -> 13630359
A34: Restricted contingency reserve held | B34: =-B27 -> 240000 | C34: =B34-C27 -> 240000 | D34: =C34-D27 -> 240000 | E34: =D34-E27 -> 240000 | F34: =E34-F27 -> 240000 | G34: =F34-G27 -> 240000 | H34: =G34-H27 -> 240000 | I34: =H34-I27 -> 240000 | J34: =I34-J27 -> 240000 | ... BI34: =BH34-BI27 -> 240000
A35: Closing cash incl. restricted reserve | B35: =B33+B34 -> 1209418.9 | C35: =C33+C34 -> 1116116.9 | D35: =D33+D34 -> 1022814.8 | E35: =E33+E34 -> 929512.7 | F35: =F33+F34 -> 836210.63 | G35: =G33+G34 -> 742908.55 | H35: =H33+H34 -> 699964.37 | I35: =I33+I34 -> 657020.2 | ... BI35: =BI33+BI34 -> 13870359
A37: BREAKEVEN / RUNWAY
A38: Operating cumulative cash flow before financing | B38: =B19 -> -93302.075 | C38: =B38+C19 -> -186604.15 | D38: =C38+D19 -> -279906.22 | E38: =D38+E19 -> -373208.3 | F38: =E38+F19 -> -466510.38 | G38: =F38+G19 -> -559812.45 | H38: =G38+H19 -> -602756.63 | I38: =H38+I19 -> -645700.8 | J38: =I38+J19 -> -688644.98 | ... BI38: =BH38+BI19 -> 12220136 | BK38: This is the monthly cash-flow break-even test before external financing.
A39: Cash-flow break-even status | B39: =IF(B38>=0,"Reached","Not yet") -> Not yet | C39: =IF(C38>=0,"Reached","Not yet") -> Not yet | D39: =IF(D38>=0,"Reached","Not yet") -> Not yet | E39: =IF(E38>=0,"Reached","Not yet") -> Not yet | F39: =IF(F38>=0,"Reached","Not yet") -> Not yet | G39: =IF(G38>=0,"Reached","Not yet") -> Not yet | H39: =IF(H38>=0,"Reached","Not yet") -> Not yet | I39: =IF(I38>=0,"Reached","Not yet") -> Not yet | ... BI39: =IF(BI38>=0,"Reached","Not yet") -> Reached
A40: Runway warning | B40: =IF(B33<0,"Cash shortfall","Funded") -> Funded | C40: =IF(C33<0,"Cash shortfall","Funded") -> Funded | D40: =IF(D33<0,"Cash shortfall","Funded") -> Funded | E40: =IF(E33<0,"Cash shortfall","Funded") -> Funded | F40: =IF(F33<0,"Cash shortfall","Funded") -> Funded | G40: =IF(G33<0,"Cash shortfall","Funded") -> Funded | H40: =IF(H33<0,"Cash shortfall","Funded") -> Funded | I40: =IF(I33<0,"Cash shortfall","Funded") -> Funded | ... BI40: =IF(BI33<0,"Cash shortfall","Funded") -> Funded
A43: Scenario comparison - monthly cash-flow break-even
A44: Scenario | B44: Cash-flow break-even month | C44: Peak cumulative operating deficit | D44: Month 60 cumulative operating cash | E44: EBITDA break-even | F44: Funding ask incl. contingency
A45: Low | B45: =IF(MAX(B52:BI52)<0,"Beyond Month 60",INDEX($B$9:$BI$9,1,MATCH(TRUE,INDEX(B52:BI52>=0,0),0))) -> Y5 M9 | C45: =-MIN(0,B52:BI52) -> 2290474.7 | D45: =BI52 -> 983353.42 | E45: =IF(Scenario_Low_PL!C61>=0,"Year 1",IF(Scenario_Low_PL!D61>=0,"Year 2",IF(Scenario_Low_PL!E61>=0,"Year 3",IF(Scenario_Low_PL!F61>=0,"Year 4",IF(Scenario_Low_PL!G61>=0,"Year 5","Beyond Year 5"))))) -> Year 5 | F45: =MAX(Scenario_Low_PL!C66:G66) -> 2977617
A46: Base | B46: =IF(MAX(B53:BI53)<0,"Beyond Month 60",INDEX($B$9:$BI$9,1,MATCH(TRUE,INDEX(B53:BI53>=0,0),0))) -> Y4 M5 | C46: =-MIN(0,B53:BI53) -> 1269402.1 | D46: =BI53 -> 12220136 | E46: =IF(Scenario_Base_PL!C61>=0,"Year 1",IF(Scenario_Base_PL!D61>=0,"Year 2",IF(Scenario_Base_PL!E61>=0,"Year 3",IF(Scenario_Base_PL!F61>=0,"Year 4",IF(Scenario_Base_PL!G61>=0,"Year 5","Beyond Year 5"))))) -> Year 3 | F46: =MAX(Scenario_Base_PL!C66:G66) -> 1650223
A47: High | B47: =IF(MAX(B54:BI54)<0,"Beyond Month 60",INDEX($B$9:$BI$9,1,MATCH(TRUE,INDEX(B54:BI54>=0,0),0))) -> Y3 M5 | C47: =-MIN(0,B54:BI54) -> 766670.51 | D47: =BI54 -> 31816705 | E47: =IF(Scenario_High_PL!C61>=0,"Year 1",IF(Scenario_High_PL!D61>=0,"Year 2",IF(Scenario_High_PL!E61>=0,"Year 3",IF(Scenario_High_PL!F61>=0,"Year 4",IF(Scenario_High_PL!G61>=0,"Year 5","Beyond Year 5"))))) -> Year 2 | F47: =MAX(Scenario_High_PL!C66:G66) -> 1236672
A49: Scenario cumulative operating cash flow before financing - monthly
...

Sheet P&L_5yr
B2: 5-Year P&L (annual) - driven by Assumptions sheet
B3: All figures GBP. Revenue & COGS scale with deal volume. Active scenario shown; change Assumptions!C4.
B5: Line item | C5: Year 1 | D5: Year 2 | E5: Year 3 | F5: Year 4 | G5: Year 5 | H5: Unit / note
B6: VOLUME & DRIVERS
B7: Deals processed | C7: =Assumptions!$F$11 -> 180 | D7: =Assumptions!$F$12 -> 900 | E7: =Assumptions!$F$13 -> 3000 | F7: =Assumptions!$F$155 -> 7500 | G7: =Assumptions!$F$156 -> 18000 | H7: From Assumptions
B8: Avg deal value (£) | C8: =Assumptions!$F$14 -> 30000 | D8: =C8*(1+Assumptions!$F$15) -> 40500 | E8: =D8*(1+Assumptions!$F$15) -> 54675 | F8: =E8*(1+Assumptions!$F$15) -> 73811.25 | G8: =F8*(1+Assumptions!$F$15) -> 99645.188 | H8: GMV per deal
B9: Gross trade value processed (GMV) | C9: =C7*C8 -> 5400000 | D9: =D7*D8 -> 36450000 | E9: =E7*E8 -> 164025000 | F9: =F7*F8 -> 553584375 | G9: =G7*G8 -> 1793613375 | H9: Deals × avg value (NOT revenue)
B10: Documents processed | C10: =Tier_Economics!E7 -> 1215 | D10: =Tier_Economics!I7 -> 5265 | E10: =Tier_Economics!M7 -> 15300 | F10: =Tier_Economics!Q7 -> 33300 | G10: =Tier_Economics!U7 -> 72900 | H10: Tier-weighted docs/deal from Tier_Economics
B11: New counterparties onboarded | C11: =C7*Assumptions!$F$16*Assumptions!$F$62 -> 180 | D11: =D7*Assumptions!$F$16*Assumptions!$F$62 -> 900 | E11: =E7*Assumptions!$F$16*Assumptions!$F$62 -> 3000 | F11: =F7*Assumptions!$F$16*Assumptions!$F$62 -> 7500 | G11: =G7*Assumptions!$F$16*Assumptions!$F$62 -> 18000 | H11: Deals x parties/deal x new-counterparty onboarding share
B12: Disputed/amended deals | C12: =Tier_Economics!E16 -> 23.58 | D12: =Tier_Economics!I16 -> 96.3 | E12: =Tier_Economics!M16 -> 264 | F12: =Tier_Economics!Q16 -> 540 | G12: =Tier_Economics!U16 -> 1134 | H12: Tier-weighted dispute rates
B13: REVENUE
B14: Escrow transaction fees | C14: =Tier_Economics!E12 -> 61515 | D14: =Tier_Economics!I12 -> 341718.75 | E14: =Tier_Economics!M12 -> 1369608.8 | F14: =Tier_Economics!Q12 -> 4162954.5 | G14: =Tier_Economics!U12 -> 12689815 | H14: Tiered fee by A/B/C mix
B15: Document review fees | C15: =Tier_Economics!E14 -> 29565 | D15: =Tier_Economics!I14 -> 110700 | E15: =Tier_Economics!M14 -> 276750 | F15: =Tier_Economics!Q14 -> 508500 | G15: =Tier_Economics!U14 -> 990000 | H15: Tiered document/review fee
B16: Dispute/amendment fees | C16: =Tier_Economics!E18 -> 8928 | D16: =Tier_Economics!I18 -> 31680 | E16: =Tier_Economics!M18 -> 74400 | F16: =Tier_Economics!Q18 -> 126000 | G16: =Tier_Economics!U18 -> 230400 | H16: Tiered dispute/amendment fee
B17: Partner/API + add-on revenue streams | C17: =Revenue_Risk_AddOns!B15 -> 7497 | D17: =Revenue_Risk_AddOns!C15 -> 114678 | E17: =Revenue_Risk_AddOns!D15 -> 238590 | F17: =Revenue_Risk_AddOns!E15 -> 422400 | G17: =Revenue_Risk_AddOns!F15 -> 830040 | H17: SaaS/API, setup/minimums, KYC fees, archive, expedited, Tier C pass-through, less first-deal discount
B18: Total revenue | C18: =SUM(C14:C17) -> 107505 | D18: =SUM(D14:D17) -> 598776.75 | E18: =SUM(E14:E17) -> 1959348.8 | F18: =SUM(F14:F17) -> 5219854.5 | G18: =SUM(G14:G17) -> 14740255 | H18: Sum of revenue lines
B19: COGS / VARIABLE COSTS
B20: Claude API (doc extraction) | C20: =C10*Assumptions!$F$19/Assumptions!$F$8 -> 28.476562 | D20: =D10*Assumptions!$F$19/Assumptions!$F$8 -> 123.39844 | E20: =E10*Assumptions!$F$19/Assumptions!$F$8 -> 358.59375 | F20: =F10*Assumptions!$F$19/Assumptions!$F$8 -> 780.46875 | G20: =G10*Assumptions!$F$19/Assumptions!$F$8 -> 1708.5938 | H20: USD→GBP
B21: KYB business onboarding | C21: =C11*Assumptions!$F$20/Assumptions!$F$8 -> 492.1875 | D21: =D11*Assumptions!$F$20/Assumptions!$F$8 -> 2460.9375 | E21: =E11*Assumptions!$F$20/Assumptions!$F$8 -> 8203.125 | F21: =F11*Assumptions!$F$20/Assumptions!$F$8 -> 20507.812 | G21: =G11*Assumptions!$F$20/Assumptions!$F$8 -> 49218.75 | H21: Fresh KYB only for new counterparties
B22: KYC/UBO + sanctions onboarding | C22: =C11*Assumptions!$F$21/Assumptions!$F$8 -> 189.84375 | D22: =D11*Assumptions!$F$21/Assumptions!$F$8 -> 949.21875 | E22: =E11*Assumptions!$F$21/Assumptions!$F$8 -> 3164.0625 | F22: =F11*Assumptions!$F$21/Assumptions!$F$8 -> 7910.1562 | G22: =G11*Assumptions!$F$21/Assumptions!$F$8 -> 18984.375 | H22: Fresh KYC/KYB only for new counterparties
B23: Tiered document verification ops | C23: =Tier_Economics!E19+Tier_Economics!E20 -> 22032 | D23: =Tier_Economics!I19+Tier_Economics!I20 -> 74520 | E23: =Tier_Economics!M19+Tier_Economics!M20 -> 165600 | F23: =Tier_Economics!Q19+Tier_Economics!Q20 -> 261000 | G23: =Tier_Economics!U19+Tier_Economics!U20 -> 453600 | H23: External eBL/API/paper + human examiner cost
B24: Blockchain gas | C24: =C7*Assumptions!$F$22/Assumptions!$F$8 -> 28.125 | D24: =D7*Assumptions!$F$22/Assumptions!$F$8 -> 140.625 | E24: =E7*Assumptions!$F$22/Assumptions!$F$8 -> 468.75 | F24: =F7*Assumptions!$F$22/Assumptions!$F$8 -> 1171.875 | G24: =G7*Assumptions!$F$22/Assumptions!$F$8 -> 2812.5 | H24: Base L2 USD→GBP
B25: RPC / node provider | C25: =C7*Assumptions!$F$23/Assumptions!$F$8 -> 1.40625 | D25: =D7*Assumptions!$F$23/Assumptions!$F$8 -> 7.03125 | E25: =E7*Assumptions!$F$23/Assumptions!$F$8 -> 23.4375 | F25: =F7*Assumptions!$F$23/Assumptions!$F$8 -> 58.59375 | G25: =G7*Assumptions!$F$23/Assumptions!$F$8 -> 140.625 | H25: Deals x RPC cost; USD to GBP
B26: Document / ledger storage | C26: =C7*Assumptions!$F$24/Assumptions!$F$8 -> 4.21875 | D26: =D7*Assumptions!$F$24/Assumptions!$F$8 -> 21.09375 | E26: =E7*Assumptions!$F$24/Assumptions!$F$8 -> 70.3125 | F26: =F7*Assumptions!$F$24/Assumptions!$F$8 -> 175.78125 | G26: =G7*Assumptions!$F$24/Assumptions!$F$8 -> 421.875 | H26: Deals x storage cost; USD to GBP
B27: Customer support | C27: =Tier_Economics!E21 -> 1980 | D27: =Tier_Economics!I21 -> 7470 | E27: =Tier_Economics!M21 -> 18900 | F27: =Tier_Economics!Q21 -> 35400 | G27: =Tier_Economics!U21 -> 70200 | H27: Tiered support load
B28: Dispute handling + retained-risk variable costs | C28: =Tier_Economics!E22+Revenue_Risk_AddOns!B24 -> 21713.8 | D28: =Tier_Economics!I22+Revenue_Risk_AddOns!C24 -> 103379 | E28: =Tier_Economics!M22+Revenue_Risk_AddOns!D24 -> 319948 | F28: =Tier_Economics!Q22+Revenue_Risk_AddOns!E24 -> 776041 | G28: =Tier_Economics!U22+Revenue_Risk_AddOns!F24 -> 1943181 | H28: Dispute handling plus QA, forum, reserves, commissions, fallback, leakage
B29: Total COGS | C29: =SUM(C20:C28) -> 46470.058 | D29: =SUM(D20:D28) -> 189071.3 | E29: =SUM(E20:E28) -> 516736.28 | F29: =SUM(F20:F28) -> 1103045.7 | G29: =SUM(G20:G28) -> 2540267.7 | H29: Sum of COGS lines
B30: Gross profit | C30: =C18-C29 -> 61034.942 | D30: =D18-D29 -> 409705.45 | E30: =E18-E29 -> 1442612.5 | F30: =F18-F29 -> 4116808.8 | G30: =G18-G29 -> 12199987 | H30: Total revenue minus total COGS
B31: Gross margin % | C31: =IF(C18=0,0,C30/C18) -> 0.5677405 | D31: =IF(D18=0,0,D30/D18) -> 0.6842374 | E31: =IF(E18=0,0,E30/E18) -> 0.73627141 | F31: =IF(F18=0,0,F30/F18) -> 0.78868268 | G31: =IF(G18=0,0,G30/G18) -> 0.8276646 | H31: Gross profit / revenue
B32: HEADCOUNT & PAYROLL
B33: Founders (FTE) | C33: =Assumptions!$F$39 -> 2 | D33: =Assumptions!$F$39 -> 2 | E33: =Assumptions!$F$39 -> 2 | F33: =Assumptions!$F$39 -> 2 | G33: =Assumptions!$F$39 -> 2 | H33: Founder headcount held flat
B34: Engineers (FTE) | C34: =Assumptions!$F$40+0 -> 2 | D34: =Assumptions!$F$40+1 -> 3 | E34: =Assumptions!$F$40+2 -> 4 | F34: =Assumptions!$F$40+3 -> 5 | G34: =Assumptions!$F$40+4 -> 6 | H34: Ramp +1/yr
B35: Compliance/ops (FTE) | C35: =Assumptions!$F$41+0 -> 1 | D35: =Assumptions!$F$41+1 -> 2 | E35: =Assumptions!$F$41+2 -> 3 | F35: =Assumptions!$F$41+3 -> 4 | G35: =Assumptions!$F$41+4 -> 5 | H35: Ramp
B36: Sales/BD/CS (FTE) | C36: =Assumptions!$F$42+0 -> 1 | D36: =Assumptions!$F$42+1 -> 2 | E36: =Assumptions!$F$42+2 -> 3 | F36: =Assumptions!$F$42+3 -> 4 | G36: =Assumptions!$F$42+4 -> 5 | H36: Ramp
B37: Total FTE | C37: =C33+C34+C35+C36 -> 6 | D37: =D33+D34+D35+D36 -> 9 | E37: =E33+E34+E35+E36 -> 12 | F37: =F33+F34+F35+F36 -> 15 | G37: =G33+G34+G35+G36 -> 18 | H37: Founders + engineers + compliance/ops + sales/BD/CS
B38: Gross salaries | C38: =C33*Assumptions!$F$44+C34*Assumptions!$F$45+C35*Assumptions!$F$46+C36*Assumptions!$F$47 -> 340000 | D38: =D33*Assumptions!$F$44+D34*Assumptions!$F$45+D35*Assumptions!$F$46+D36*Assumptions!$F$47 -> 520000 | E38: =E33*Assumptions!$F$44+E34*Assumptions!$F$45+E35*Assumptions!$F$46+E36*Assumptions!$F$47 -> 700000 | F38: =F33*Assumptions!$F$44+F34*Assumptions!$F$45+F35*Assumptions!$F$46+F36*Assumptions!$F$47 -> 880000 | G38: =G33*Assumptions!$F$44+G34*Assumptions!$F$45+G35*Assumptions!$F$46+G36*Assumptions!$F$47 -> 1060000 | H38: FTE × salary
B39: Employer NI | C39: =MAX(0,(C38-Assumptions!$F$49*C37)*Assumptions!$F$48-Assumptions!$F$60) -> 36000 | D39: =MAX(0,(D38-Assumptions!$F$49*D37)*Assumptions!$F$48-Assumptions!$F$60) -> 60750 | E39: =MAX(0,(E38-Assumptions!$F$49*E37)*Assumptions!$F$48-Assumptions!$F$60) -> 85500 | F39: =MAX(0,(F38-Assumptions!$F$49*F37)*Assumptions!$F$48-Assumptions!$F$60) -> 110250 | G39: =MAX(0,(G38-Assumptions!$F$49*G37)*Assumptions!$F$48-Assumptions!$F$60) -> 135000 | H39: 15% above threshold, less Employment Allowance; confirm eligibility
B40: Employer pension | C40: =C38*Assumptions!$F$50 -> 13600 | D40: =D38*Assumptions!$F$50 -> 20800 | E40: =E38*Assumptions!$F$50 -> 28000 | F40: =F38*Assumptions!$F$50 -> 35200 | G40: =G38*Assumptions!$F$50 -> 42400 | H40: Gross salaries x pension contribution
B41: Other employment on-costs | C41: =C38*Assumptions!$F$51 -> 10200 | D41: =D38*Assumptions!$F$51 -> 15600 | E41: =E38*Assumptions!$F$51 -> 21000 | F41: =F38*Assumptions!$F$51 -> 26400 | G41: =G38*Assumptions!$F$51 -> 31800 | H41: Gross salaries x other employment on-costs
B42: Total payroll cost | C42: =C38+C39+C40+C41 -> 399800 | D42: =D38+D39+D40+D41 -> 617150 | E42: =E38+E39+E40+E41 -> 834500 | F42: =F38+F39+F40+F41 -> 1051850 | G42: =G38+G39+G40+G41 -> 1269200 | H42: Gross salaries + employer NI + pension + other on-costs
...

Sheet Tier_Economics
A1: Tier Economics - revenue, cost and risk by document-intake tier
A3: Metric | B3: Tier A eBL Y1 | C3: Tier B API Y1 | D3: Tier C Paper Y1 | E3: Total Y1 | F3: Tier A eBL Y2 | G3: Tier B API Y2 | H3: Tier C Paper Y2 | I3: Total Y2 | J3: Tier A eBL Y3 | K3: Tier B API Y3 | L3: Tier C Paper Y3 | M3: Total Y3 | N3: Tier A eBL Y4 | O3: Tier B API Y4 | P3: Tier C Paper Y4 | Q3: Total Y4 | R3: Tier A eBL Y5 | S3: Tier B API Y5 | T3: Tier C Paper Y5 | U3: Total Y5
A4: Tier mix | B4: =Assumptions!$F$64 -> 0.15 | C4: =Assumptions!$F$65 -> 0.45 | D4: =Assumptions!$F$66 -> 0.4 | E4: =SUM(B4:D4) -> 1 | F4: =Assumptions!$F$67 -> 0.3 | G4: =Assumptions!$F$68 -> 0.45 | H4: =Assumptions!$F$69 -> 0.25 | I4: =SUM(F4:H4) -> 1 | J4: =Assumptions!$F$70 -> 0.45 | K4: =Assumptions!$F$71 -> 0.4 | L4: =Assumptions!$F$72 -> 0.15 | M4: =SUM(J4:L4) -> 1 | N4: =Assumptions!$F$157 -> 0.6 | O4: =Assumptions!$F$158 -> 0.32 | P4: =Assumptions!$F$159 -> 0.08 | Q4: =SUM(N4:P4) -> 1 | R4: =Assumptions!$F$160 -> 0.7 | S4: =Assumptions!$F$161 -> 0.25 | T4: =Assumptions!$F$162 -> 0.05 | U4: =SUM(R4:T4) -> 1
A5: Deals | B5: ='P&L_5yr'!$C$7*B4 -> 27 | C5: ='P&L_5yr'!$C$7*C4 -> 81 | D5: ='P&L_5yr'!$C$7*D4 -> 72 | E5: =SUM(B5:D5) -> 180 | F5: ='P&L_5yr'!$D$7*F4 -> 270 | G5: ='P&L_5yr'!$D$7*G4 -> 405 | H5: ='P&L_5yr'!$D$7*H4 -> 225 | I5: =SUM(F5:H5) -> 900 | J5: ='P&L_5yr'!$E$7*J4 -> 1350 | K5: ='P&L_5yr'!$E$7*K4 -> 1200 | L5: ='P&L_5yr'!$E$7*L4 -> 450 | M5: =SUM(J5:L5) -> 3000 | N5: ='P&L_5yr'!$F$7*N4 -> 4500 | O5: ='P&L_5yr'!$F$7*O4 -> 2400 | P5: ='P&L_5yr'!$F$7*P4 -> 600 | Q5: =SUM(N5:P5) -> 7500 | R5: ='P&L_5yr'!$G$7*R4 -> 12600 | S5: ='P&L_5yr'!$G$7*S4 -> 4500 | T5: ='P&L_5yr'!$G$7*T4 -> 900 | U5: =SUM(R5:T5) -> 18000
A6: Docs per deal | B6: =Assumptions!$F$106 -> 3 | C6: =Assumptions!$F$107 -> 6 | D6: =Assumptions!$F$108 -> 9 | E6: =IF(E5=0,0,E7/E5) -> 6.75 | F6: =Assumptions!$F$106 -> 3 | G6: =Assumptions!$F$107 -> 6 | H6: =Assumptions!$F$108 -> 9 | I6: =IF(I5=0,0,I7/I5) -> 5.85 | J6: =Assumptions!$F$106 -> 3 | K6: =Assumptions!$F$107 -> 6 | L6: =Assumptions!$F$108 -> 9 | M6: =IF(M5=0,0,M7/M5) -> 5.1 | N6: =Assumptions!$F$106 -> 3 | O6: =Assumptions!$F$107 -> 6 | P6: =Assumptions!$F$108 -> 9 | Q6: =IF(Q5=0,0,Q7/Q5) -> 4.44 | R6: =Assumptions!$F$106 -> 3 | S6: =Assumptions!$F$107 -> 6 | T6: =Assumptions!$F$108 -> 9 | U6: =IF(U5=0,0,U7/U5) -> 4.05
A7: Documents processed | B7: =B5*B6 -> 81 | C7: =C5*C6 -> 486 | D7: =D5*D6 -> 648 | E7: =SUM(B7:D7) -> 1215 | F7: =F5*F6 -> 810 | G7: =G5*G6 -> 2430 | H7: =H5*H6 -> 2025 | I7: =SUM(F7:H7) -> 5265 | J7: =J5*J6 -> 4050 | K7: =K5*K6 -> 7200 | L7: =L5*L6 -> 4050 | M7: =SUM(J7:L7) -> 15300 | N7: =N5*N6 -> 13500 | O7: =O5*O6 -> 14400 | P7: =P5*P6 -> 5400 | Q7: =SUM(N7:P7) -> 33300 | R7: =R5*R6 -> 37800 | S7: =S5*S6 -> 27000 | T7: =T5*T6 -> 8100 | U7: =SUM(R7:T7) -> 72900
A8: Avg deal value | B8: ='P&L_5yr'!$C$8 -> 30000 | C8: ='P&L_5yr'!$C$8 -> 30000 | D8: ='P&L_5yr'!$C$8 -> 30000 | E8: ='P&L_5yr'!$C$8 -> 30000 | F8: ='P&L_5yr'!$D$8 -> 40500 | G8: ='P&L_5yr'!$D$8 -> 40500 | H8: ='P&L_5yr'!$D$8 -> 40500 | I8: ='P&L_5yr'!$D$8 -> 40500 | J8: ='P&L_5yr'!$E$8 -> 54675 | K8: ='P&L_5yr'!$E$8 -> 54675 | L8: ='P&L_5yr'!$E$8 -> 54675 | M8: ='P&L_5yr'!$E$8 -> 54675 | N8: ='P&L_5yr'!$F$8 -> 73811.25 | O8: ='P&L_5yr'!$F$8 -> 73811.25 | P8: ='P&L_5yr'!$F$8 -> 73811.25 | Q8: ='P&L_5yr'!$F$8 -> 73811.25 | R8: ='P&L_5yr'!$G$8 -> 99645.188 | S8: ='P&L_5yr'!$G$8 -> 99645.188 | T8: ='P&L_5yr'!$G$8 -> 99645.188 | U8: ='P&L_5yr'!$G$8 -> 99645.188
A9: GMV | B9: =B5*B8 -> 810000 | C9: =C5*C8 -> 2430000 | D9: =D5*D8 -> 2160000 | E9: =SUM(B9:D9) -> 5400000 | F9: =F5*F8 -> 10935000 | G9: =G5*G8 -> 16402500 | H9: =H5*H8 -> 9112500 | I9: =SUM(F9:H9) -> 36450000 | J9: =J5*J8 -> 73811250 | K9: =K5*K8 -> 65610000 | L9: =L5*L8 -> 24603750 | M9: =SUM(J9:L9) -> 164025000 | N9: =N5*N8 -> 332150625 | O9: =O5*O8 -> 177147000 | P9: =P5*P8 -> 44286750 | Q9: =SUM(N9:P9) -> 553584375 | R9: =R5*R8 -> 1.2555294e+09 | S9: =S5*S8 -> 4.4840334e+08 | T9: =T5*T8 -> 89680669 | U9: =SUM(R9:T9) -> 1793613375
A10: Escrow take rate | B10: =Assumptions!$F$73 -> 0.006 | C10: =Assumptions!$F$74 -> 0.0085 | D10: =Assumptions!$F$75 -> 0.015 | E10: =IF(E9=0,0,SUM(B9*B10,C9*C10,D9*D10)/E9) -> 0.010725 | F10: =Assumptions!$F$73 -> 0.006 | G10: =Assumptions!$F$74 -> 0.0085 | H10: =Assumptions!$F$75 -> 0.015 | I10: =IF(I9=0,0,SUM(F9*F10,G9*G10,H9*H10)/I9) -> 0.009375 | J10: =Assumptions!$F$73 -> 0.006 | K10: =Assumptions!$F$74 -> 0.0085 | L10: =Assumptions!$F$75 -> 0.015 | M10: =IF(M9=0,0,SUM(J9*J10,K9*K10,L9*L10)/M9) -> 0.00835 | N10: =Assumptions!$F$73 -> 0.006 | O10: =Assumptions!$F$74 -> 0.0085 | P10: =Assumptions!$F$75 -> 0.015 | Q10: =IF(Q9=0,0,SUM(N9*N10,O9*O10,P9*P10)/Q9) -> 0.00752 | R10: =Assumptions!$F$73 -> 0.006 | S10: =Assumptions!$F$74 -> 0.0085 | T10: =Assumptions!$F$75 -> 0.015 | U10: =IF(U9=0,0,SUM(R9*R10,S9*S10,T9*T10)/U9) -> 0.007075
A11: Minimum escrow fee | B11: =Assumptions!$F$76 -> 150 | C11: =Assumptions!$F$77 -> 250 | D11: =Assumptions!$F$78 -> 500 | E11: =IF(E5=0,0,SUM(B5*B11,C5*C11,D5*D11)/E5) -> 335 | F11: =Assumptions!$F$76 -> 150 | G11: =Assumptions!$F$77 -> 250 | H11: =Assumptions!$F$78 -> 500 | I11: =IF(I5=0,0,SUM(F5*F11,G5*G11,H5*H11)/I5) -> 282.5 | J11: =Assumptions!$F$76 -> 150 | K11: =Assumptions!$F$77 -> 250 | L11: =Assumptions!$F$78 -> 500 | M11: =IF(M5=0,0,SUM(J5*J11,K5*K11,L5*L11)/M5) -> 242.5 | N11: =Assumptions!$F$76 -> 150 | O11: =Assumptions!$F$77 -> 250 | P11: =Assumptions!$F$78 -> 500 | Q11: =IF(Q5=0,0,SUM(N5*N11,O5*O11,P5*P11)/Q5) -> 210 | R11: =Assumptions!$F$76 -> 150 | S11: =Assumptions!$F$77 -> 250 | T11: =Assumptions!$F$78 -> 500 | U11: =IF(U5=0,0,SUM(R5*R11,S5*S11,T5*T11)/U5) -> 192.5
A12: Escrow fee revenue | B12: =B5*MAX(B8*B10,B11) -> 4860 | C12: =C5*MAX(C8*C10,C11) -> 20655 | D12: =D5*MAX(D8*D10,D11) -> 36000 | E12: =SUM(B12:D12) -> 61515 | F12: =F5*MAX(F8*F10,F11) -> 65610 | G12: =G5*MAX(G8*G10,G11) -> 139421.25 | H12: =H5*MAX(H8*H10,H11) -> 136687.5 | I12: =SUM(F12:H12) -> 341718.75 | J12: =J5*MAX(J8*J10,J11) -> 442867.5 | K12: =K5*MAX(K8*K10,K11) -> 557685 | L12: =L5*MAX(L8*L10,L11) -> 369056.25 | M12: =SUM(J12:L12) -> 1369608.8 | N12: =N5*MAX(N8*N10,N11) -> 1992903.8 | O12: =O5*MAX(O8*O10,O11) -> 1505749.5 | P12: =P5*MAX(P8*P10,P11) -> 664301.25 | Q12: =SUM(N12:P12) -> 4162954.5 | R12: =R5*MAX(R8*R10,R11) -> 7533176.2 | S12: =S5*MAX(S8*S10,S11) -> 3811428.4 | T12: =T5*MAX(T8*T10,T11) -> 1345210 | U12: =SUM(R12:T12) -> 12689815
A13: Doc/review fee per deal | B13: =Assumptions!$F$79 -> 25 | C13: =Assumptions!$F$80 -> 90 | D13: =Assumptions!$F$81 -> 300 | E13: =IF(E5=0,0,SUM(B5*B13,C5*C13,D5*D13)/E5) -> 164.25 | F13: =Assumptions!$F$79 -> 25 | G13: =Assumptions!$F$80 -> 90 | H13: =Assumptions!$F$81 -> 300 | I13: =IF(I5=0,0,SUM(F5*F13,G5*G13,H5*H13)/I5) -> 123 | J13: =Assumptions!$F$79 -> 25 | K13: =Assumptions!$F$80 -> 90 | L13: =Assumptions!$F$81 -> 300 | M13: =IF(M5=0,0,SUM(J5*J13,K5*K13,L5*L13)/M5) -> 92.25 | N13: =Assumptions!$F$79 -> 25 | O13: =Assumptions!$F$80 -> 90 | P13: =Assumptions!$F$81 -> 300 | Q13: =IF(Q5=0,0,SUM(N5*N13,O5*O13,P5*P13)/Q5) -> 67.8 | R13: =Assumptions!$F$79 -> 25 | S13: =Assumptions!$F$80 -> 90 | T13: =Assumptions!$F$81 -> 300 | U13: =IF(U5=0,0,SUM(R5*R13,S5*S13,T5*T13)/U5) -> 55
A14: Doc/review revenue | B14: =B5*B13 -> 675 | C14: =C5*C13 -> 7290 | D14: =D5*D13 -> 21600 | E14: =SUM(B14:D14) -> 29565 | F14: =F5*F13 -> 6750 | G14: =G5*G13 -> 36450 | H14: =H5*H13 -> 67500 | I14: =SUM(F14:H14) -> 110700 | J14: =J5*J13 -> 33750 | K14: =K5*K13 -> 108000 | L14: =L5*L13 -> 135000 | M14: =SUM(J14:L14) -> 276750 | N14: =N5*N13 -> 112500 | O14: =O5*O13 -> 216000 | P14: =P5*P13 -> 180000 | Q14: =SUM(N14:P14) -> 508500 | R14: =R5*R13 -> 315000 | S14: =S5*S13 -> 405000 | T14: =T5*T13 -> 270000 | U14: =SUM(R14:T14) -> 990000
A15: Dispute rate | B15: =Assumptions!$F$94 -> 0.04 | C15: =Assumptions!$F$95 -> 0.1 | D15: =Assumptions!$F$96 -> 0.2 | E15: =IF(E5=0,0,E16/E5) -> 0.131 | F15: =Assumptions!$F$94 -> 0.04 | G15: =Assumptions!$F$95 -> 0.1 | H15: =Assumptions!$F$96 -> 0.2 | I15: =IF(I5=0,0,I16/I5) -> 0.107 | J15: =Assumptions!$F$94 -> 0.04 | K15: =Assumptions!$F$95 -> 0.1 | L15: =Assumptions!$F$96 -> 0.2 | M15: =IF(M5=0,0,M16/M5) -> 0.088 | N15: =Assumptions!$F$94 -> 0.04 | O15: =Assumptions!$F$95 -> 0.1 | P15: =Assumptions!$F$96 -> 0.2 | Q15: =IF(Q5=0,0,Q16/Q5) -> 0.072 | R15: =Assumptions!$F$94 -> 0.04 | S15: =Assumptions!$F$95 -> 0.1 | T15: =Assumptions!$F$96 -> 0.2 | U15: =IF(U5=0,0,U16/U5) -> 0.063
A16: Disputed deals | B16: =B5*B15 -> 1.08 | C16: =C5*C15 -> 8.1 | D16: =D5*D15 -> 14.4 | E16: =SUM(B16:D16) -> 23.58 | F16: =F5*F15 -> 10.8 | G16: =G5*G15 -> 40.5 | H16: =H5*H15 -> 45 | I16: =SUM(F16:H16) -> 96.3 | J16: =J5*J15 -> 54 | K16: =K5*K15 -> 120 | L16: =L5*L15 -> 90 | M16: =SUM(J16:L16) -> 264 | N16: =N5*N15 -> 180 | O16: =O5*O15 -> 240 | P16: =P5*P15 -> 120 | Q16: =SUM(N16:P16) -> 540 | R16: =R5*R15 -> 504 | S16: =S5*S15 -> 450 | T16: =T5*T15 -> 180 | U16: =SUM(R16:T16) -> 1134
A17: Dispute/amendment fee | B17: =Assumptions!$F$82 -> 100 | C17: =Assumptions!$F$83 -> 200 | D17: =Assumptions!$F$84 -> 500 | E17: =IF(E16=0,0,SUM(B16*B17,C16*C17,D16*D17)/E16) -> 378.62595 | F17: =Assumptions!$F$82 -> 100 | G17: =Assumptions!$F$83 -> 200 | H17: =Assumptions!$F$84 -> 500 | I17: =IF(I16=0,0,SUM(F16*F17,G16*G17,H16*H17)/I16) -> 328.97196 | J17: =Assumptions!$F$82 -> 100 | K17: =Assumptions!$F$83 -> 200 | L17: =Assumptions!$F$84 -> 500 | M17: =IF(M16=0,0,SUM(J16*J17,K16*K17,L16*L17)/M16) -> 281.81818 | N17: =Assumptions!$F$82 -> 100 | O17: =Assumptions!$F$83 -> 200 | P17: =Assumptions!$F$84 -> 500 | Q17: =IF(Q16=0,0,SUM(N16*N17,O16*O17,P16*P17)/Q16) -> 233.33333 | R17: =Assumptions!$F$82 -> 100 | S17: =Assumptions!$F$83 -> 200 | T17: =Assumptions!$F$84 -> 500 | U17: =IF(U16=0,0,SUM(R16*R17,S16*S17,T16*T17)/U16) -> 203.1746
A18: Dispute/amendment revenue | B18: =B16*B17 -> 108 | C18: =C16*C17 -> 1620 | D18: =D16*D17 -> 7200 | E18: =SUM(B18:D18) -> 8928 | F18: =F16*F17 -> 1080 | G18: =G16*G17 -> 8100 | H18: =H16*H17 -> 22500 | I18: =SUM(F18:H18) -> 31680 | J18: =J16*J17 -> 5400 | K18: =K16*K17 -> 24000 | L18: =L16*L17 -> 45000 | M18: =SUM(J18:L18) -> 74400 | N18: =N16*N17 -> 18000 | O18: =O16*O17 -> 48000 | P18: =P16*P17 -> 60000 | Q18: =SUM(N18:P18) -> 126000 | R18: =R16*R17 -> 50400 | S18: =S16*S17 -> 90000 | T18: =T16*T17 -> 90000 | U18: =SUM(R18:T18) -> 230400
A19: External eBL/API/paper cost | B19: =B5*Assumptions!$F$85 -> 81 | C19: =C5*Assumptions!$F$86 -> 810 | D19: =D5*Assumptions!$F$87 -> 10800 | E19: =SUM(B19:D19) -> 11691 | F19: =F5*Assumptions!$F$85 -> 810 | G19: =G5*Assumptions!$F$86 -> 4050 | H19: =H5*Assumptions!$F$87 -> 33750 | I19: =SUM(F19:H19) -> 38610 | J19: =J5*Assumptions!$F$85 -> 4050 | K19: =K5*Assumptions!$F$86 -> 12000 | L19: =L5*Assumptions!$F$87 -> 67500 | M19: =SUM(J19:L19) -> 83550 | N19: =N5*Assumptions!$F$85 -> 13500 | O19: =O5*Assumptions!$F$86 -> 24000 | P19: =P5*Assumptions!$F$87 -> 90000 | Q19: =SUM(N19:P19) -> 127500 | R19: =R5*Assumptions!$F$85 -> 37800 | S19: =S5*Assumptions!$F$86 -> 45000 | T19: =T5*Assumptions!$F$87 -> 135000 | U19: =SUM(R19:T19) -> 217800
A20: Human review cost | B20: =B5*Assumptions!$F$88 -> 81 | C20: =C5*Assumptions!$F$89 -> 1620 | D20: =D5*Assumptions!$F$90 -> 8640 | E20: =SUM(B20:D20) -> 10341 | F20: =F5*Assumptions!$F$88 -> 810 | G20: =G5*Assumptions!$F$89 -> 8100 | H20: =H5*Assumptions!$F$90 -> 27000 | I20: =SUM(F20:H20) -> 35910 | J20: =J5*Assumptions!$F$88 -> 4050 | K20: =K5*Assumptions!$F$89 -> 24000 | L20: =L5*Assumptions!$F$90 -> 54000 | M20: =SUM(J20:L20) -> 82050 | N20: =N5*Assumptions!$F$88 -> 13500 | O20: =O5*Assumptions!$F$89 -> 48000 | P20: =P5*Assumptions!$F$90 -> 72000 | Q20: =SUM(N20:P20) -> 133500 | R20: =R5*Assumptions!$F$88 -> 37800 | S20: =S5*Assumptions!$F$89 -> 90000 | T20: =T5*Assumptions!$F$90 -> 108000 | U20: =SUM(R20:T20) -> 235800
A21: Support cost | B21: =B5*Assumptions!$F$91 -> 54 | C21: =C5*Assumptions!$F$92 -> 486 | D21: =D5*Assumptions!$F$93 -> 1440 | E21: =SUM(B21:D21) -> 1980 | F21: =F5*Assumptions!$F$91 -> 540 | G21: =G5*Assumptions!$F$92 -> 2430 | H21: =H5*Assumptions!$F$93 -> 4500 | I21: =SUM(F21:H21) -> 7470 | J21: =J5*Assumptions!$F$91 -> 2700 | K21: =K5*Assumptions!$F$92 -> 7200 | L21: =L5*Assumptions!$F$93 -> 9000 | M21: =SUM(J21:L21) -> 18900 | N21: =N5*Assumptions!$F$91 -> 9000 | O21: =O5*Assumptions!$F$92 -> 14400 | P21: =P5*Assumptions!$F$93 -> 12000 | Q21: =SUM(N21:P21) -> 35400 | R21: =R5*Assumptions!$F$91 -> 25200 | S21: =S5*Assumptions!$F$92 -> 27000 | T21: =T5*Assumptions!$F$93 -> 18000 | U21: =SUM(R21:T21) -> 70200
A22: Dispute handling cost | B22: =B16*Assumptions!$F$97 -> 64.8 | C22: =C16*Assumptions!$F$98 -> 972 | D22: =D16*Assumptions!$F$99 -> 5040 | E22: =SUM(B22:D22) -> 6076.8 | F22: =F16*Assumptions!$F$97 -> 648 | G22: =G16*Assumptions!$F$98 -> 4860 | H22: =H16*Assumptions!$F$99 -> 15750 | I22: =SUM(F22:H22) -> 21258 | J22: =J16*Assumptions!$F$97 -> 3240 | K22: =K16*Assumptions!$F$98 -> 14400 | L22: =L16*Assumptions!$F$99 -> 31500 | M22: =SUM(J22:L22) -> 49140 | N22: =N16*Assumptions!$F$97 -> 10800 | O22: =O16*Assumptions!$F$98 -> 28800 | P22: =P16*Assumptions!$F$99 -> 42000 | Q22: =SUM(N22:P22) -> 81600 | R22: =R16*Assumptions!$F$97 -> 30240 | S22: =S16*Assumptions!$F$98 -> 54000 | T22: =T16*Assumptions!$F$99 -> 63000 | U22: =SUM(R22:T22) -> 147240
A23: Total tier-specific COGS | B23: =SUM(B19:B22) -> 280.8 | C23: =SUM(C19:C22) -> 3888 | D23: =SUM(D19:D22) -> 25920 | E23: =SUM(B23:D23) -> 30088.8 | F23: =SUM(F19:F22) -> 2808 | G23: =SUM(G19:G22) -> 19440 | H23: =SUM(H19:H22) -> 81000 | I23: =SUM(F23:H23) -> 103248 | J23: =SUM(J19:J22) -> 14040 | K23: =SUM(K19:K22) -> 57600 | L23: =SUM(L19:L22) -> 162000 | M23: =SUM(J23:L23) -> 233640 | N23: =SUM(N19:N22) -> 46800 | O23: =SUM(O19:O22) -> 115200 | P23: =SUM(P19:P22) -> 216000 | Q23: =SUM(N23:P23) -> 378000 | R23: =SUM(R19:R22) -> 131040 | S23: =SUM(S19:S22) -> 216000 | T23: =SUM(T19:T22) -> 324000 | U23: =SUM(R23:T23) -> 671040
