Workbook

Sheet Master Gantt
A1: Blockmediary — Master Governance Gantt
A2: Reporting period 8 June–14 August 2026 | Status date 12 August 2026 | Pre-remediation snapshot | Individual-assignment work excluded
A4: DONE | M4: REVIEW | Y4: DOING | AK4: TO DO | AW4: DEFERRED | BI4: ACTIVE COMPLETE
A5: =COUNTIF($J$11:$J$62,"Done") -> 24 | M5: =COUNTIF($J$11:$J$62,"Review") -> 8 | Y5: =COUNTIF($J$11:$J$62,"Doing") -> 6 | AK5: =COUNTIF($J$11:$J$62,"To Do") -> 6 | AW5: =COUNTIF($J$11:$J$62,"Deferred") -> 8 | BI5: =COUNTIF($J$11:$J$62,"Done")/COUNTIF($J$11:$J$62,"<>Deferred") -> 0.54545455
A8: ◆ Milestone column | ◆ Zero float | ● Critical path | Gantt finish uses current due for active work, otherwise baseline finish | M8: ◆ | BR8: ◆ | BY8: ◆ | BZ8: ◆ | CB8: ◆
M9: June 2026 | AJ9: July 2026 | BO9: August 2026
B10: Task ID | C10: Workstream | D10: Task | E10: Responsible | F10: Accountable | G10: Start | H10: Finish | I10: Days | J10: Status | K10: Dependencies | L10: Evidence / acceptance | M10: 46181 | N10: 46182 | O10: 46183 | P10: 46184 | Q10: 46185 | R10: 46186 | S10: 46187 | T10: 46188 | U10: 46189 | V10: 46190 | W10: 46191 | X10: 46192 | Y10: 46193 | Z10: 46194 | AA10: 46195 | AB10: 46196 | AC10: 46197 | AD10: 46198 | AE10: 46199 | AF10: 46200 | AG10: 46201 | AH10: 46202 | AI10: 46203 | AJ10: 46204 | AK10: 46205 | AL10: 46206 | AM10: 46207 | AN10: 46208 | AO10: 46209 | AP10: 46210 | AQ10: 46211 | AR10: 46212 | AS10: 46213 | AT10: 46214 | AU10: 46215 | AV10: 46216 | AW10: 46217 | AX10: 46218 | AY10: 46219 | AZ10: 46220 | BA10: 46221 | BB10: 46222 | BC10: 46223 | BD10: 46224 | BE10: 46225 | BF10: 46226 | BG10: 46227 | BH10: 46228 | BI10: 46229 | BJ10: 46230 | BK10: 46231 | BL10: 46232 | BM10: 46233 | BN10: 46234 | BO10: 46235 | BP10: 46236 | BQ10: 46237 | BR10: 46238 | BS10: 46239 | BT10: 46240 | BU10: 46241 | BV10: 46242 | BW10: 46243 | BX10: 46244 | BY10: 46245 | BZ10: 46246 | CA10: 46247 | CB10: 46248
B11: GOV-01 | C11: GOV | D11: Proposal handoff and assessed build gate established | E11: Tamer | F11: Tamer | G11: 46181 | H11: 46181 | I11: =IF(OR(G11="",H11=""),"",H11-G11+1) -> 1 | J11: Done | L11: Proposal artifact and fixed deadline retained — proposal/Pitch-Deck-June-8.pptx; T1
B12: GOV-02 | C12: GOV | D12: Initial governance framework created | E12: Tamer, Dan | F12: Tamer | G12: 46182 | H12: 46189 | I12: =IF(OR(G12="",H12=""),"",H12-G12+1) -> 8 | J12: Done | L12: Kanban, Gantt and RACI committed — Commit 5c4daba; T7, T8, D3
B13: GOV-03 | C13: GOV | D13: BRD v1.0 reconciled to delivered prototype | E13: Nick | F13: Tamer | G13: 46182 | H13: 46194 | I13: =IF(OR(G13="",H13=""),"",H13-G13+1) -> 13 | J13: Done | L13: Versioned BRD baseline exists — docs/business-requirements.md; 3b3e82e; T1
B14: PRD-01 | C14: PRD | D14: End-to-end operating workflow documented | E14: Dan | F14: Dan | G14: 46182 | H14: 46194 | I14: =IF(OR(G14="",H14=""),"",H14-G14+1) -> 13 | J14: Done | L14: Happy path and verification layers documented — docs/Flow Guidance/operational-flow-v1.md; D1
B15: PRD-02 | C15: PRD | D15: Deal, state and deterministic release rules implemented | E15: Nick, Dan | F15: Dan | G15: 46188 | H15: 46201 | I15: =IF(OR(G15="",H15=""),"",H15-G15+1) -> 14 | J15: Done | L15: app/lib/escrow/rules.ts contains 428 lines and grades DOC-01–DOC-06 using GRADE, CROSS and FLAG rule kinds; relevant application tests pass — Commit 73f1bf7; N4, D1
B16: TEC-01 | C16: TEC | D16: Escrow smart contract implemented | E16: Nick, Dan | F16: Nick | G16: 46188 | H16: 46208 | I16: =IF(OR(G16="",H16=""),"",H16-G16+1) -> 21 | J16: Done | L16: contracts/contracts/Escrow.sol, tests and Ignition deployment module exist; forced compilation from source succeeds — 36222dd; N1
B17: TEC-02 | C17: TEC | D17: Contract tests and unfunded cancellation path authored | E17: Dan | F17: Nick | G17: 46202 | H17: 46213 | I17: =IF(OR(G17="",H17=""),"",H17-G17+1) -> 12 | J17: Done | L17: Six test files cover happy path, access control, state guards, refund, release/pause and cancellation; 21/21 pass in the standard compiled run — 36222dd, a186f98; verified 12 Aug; N1
B18: TEC-03 | C18: TEC | D18: Off-chain store, API and rule-engine core implemented | E18: Nick, Dan | F18: Nick | G18: 46195 | H18: 46222 | I18: =IF(OR(G18="",H18=""),"",H18-G18+1) -> 28 | J18: Done | L18: 28 API route handlers and the lifecycle/rules core exist — 73f1bf7, 6515a51; N2, N3, D5
B19: TEC-04 | C19: TEC | D19: Buyer/seller lifecycle wired to real deal state | E19: Nick, Dan | F19: Nick | G19: 46209 | H19: 46222 | I19: =IF(OR(G19="",H19=""),"",H19-G19+1) -> 14 | J19: Done | L19: Fund, submit and verdict journeys merged — 06efff6, fcdfaad; N2, N3
B20: TEC-05 | C20: TEC | D20: Objection, refund and audit paths implemented | E20: Dan | F20: Nick | G20: 46223 | H20: 46236 | I20: =IF(OR(G20="",H20=""),"",H20-G20+1) -> 14 | J20: Done | L20: Objection withdrawal, refund and audit commits exist — 5688cc3, 77cf5f6; N2, D5
B21: TEC-06 | C21: TEC | D21: SQL persistence, account auth and SIWE implemented | E21: Dan, Nick | F21: Nick | G21: 46216 | H21: 46236 | I21: =IF(OR(G21="",H21=""),"",H21-G21+1) -> 21 | J21: Done | L21: Prisma persistence, server sessions and SIWE wallet linking are present; application suite passes — f8cc7a9, 3123538, a2052a2; N2, N3
B22: TEC-07 | C22: TEC | D22: Base Sepolia deployment evidence created | E22: Dan | F22: Nick | G22: 46203 | H22: 46208 | I22: =IF(OR(G22="",H22=""),"",H22-G22+1) -> 6 | J22: Done | L22: Deployment record identifies Base Sepolia chain ID 84532 and real test USDC configuration — c4887db, 3e9b4ed; N1
... B34: BUS-06 | C34: BUS | D34: Original Business Model Canvas produced | E34: Tamer, Conrad, Mo | F34: Conrad | G34: 46181 | H34: 46181 | I34: =IF(OR(G34="",H34=""),"",H34-G34+1) -> 1 | J34: Done | L34: Eight-block canvas exists with opportunity, market, revenue, cost, channels and competition — proposal/business-model-slide.md; T2
A35: ◆ | B35: GOV-04 | C35: GOV | D35: TRD and A1–A8 acceptance baseline reconciled | E35: Nick | F35: Tamer | G35: 46188 | H35: 46246 | I35: =IF(OR(G35="",H35=""),"",H35-G35+1) -> 59 | J35: Review | L35: Run and record every acceptance case; remove any remaining delivered-status contradiction — docs/technical-requirements.md; 42aa948; T1
A36: ◆ | B36: PRD-03 | C36: PRD | D36: Full document-pack and corridor release rules aligned | E36: Nick, Badhri | F36: Dan | G36: 46195 | H36: 46246 | I36: =IF(OR(G36="",H36=""),"",H36-G36+1) -> 52 | J36: Review | L36: Cold test required documents and reconcile BRD language with implemented pack — 9e697cf, f9bbd27, 498751d; N4/B5
A37: ◆ | B37: PRD-04 | C37: PRD | D37: Final product-to-pitch traceability approved | E37: Dan, Tamer | F37: Dan | G37: 46230 | H37: 46246 | I37: =IF(OR(G37="",H37=""),"",H37-G37+1) -> 17 | J37: Review | L37: Every script claim maps to delivered evidence or roadmap label — BRD/TRD reconciliation; commit 42aa948; saved claims register still pending under DEC-13; T5
A38: ◆ | B38: TEC-09 | C38: TEC | D38: Technical acceptance A1–A8 completed | E38: Nick, Dan | F38: Nick | G38: 46237 | H38: 46246 | I38: =IF(OR(G38="",H38=""),"",H38-G38+1) -> 10 | J38: Review | L38: A1 achieved: forced source compile and 21/21 contract tests pass. Supporting evidence: 187/187 application tests pass. Open: A2–A7 integrated authenticated walkthrough, A8 control record, production build and lint — Test/compile evidence 12 Aug; TRD Section 11; N1–N4/D5
A39: ◆ | B39: TEC-10 | C39: TEC | D39: Repository sync and clean-build reproducibility verified | E39: Nick | F39: Nick | G39: 46244 | H39: 46246 | I39: =IF(OR(G39="",H39=""),"",H39-G39+1) -> 3 | J39: Review | L39: Known failing: Prisma postinstall loads untracked app/.env; no app-level example exists; npm and pnpm lockfiles compete; production build and focused lint fail — Configuration/build/lint evidence 12 Aug; D3
A40: ◆ | B40: RISK-06 | C40: RISK | D40: Legal/compliance claims and delivery boundary signed off | E40: Badhri, Tamer | F40: Badhri | G40: 46237 | H40: 46246 | I40: =IF(OR(G40="",H40=""),"",H40-G40+1) -> 10 | J40: Review | L40: No legal-advice claim; live screening, TEA and examiner functions labelled roadmap — Legal and document sources; B1–B4
B41: BUS-03 | C41: BUS | D41: Competitor analysis verified for pitch use | E41: Badhri, Mo | F41: Mo | G41: 46188 | H41: 46246 | I41: =IF(OR(G41="",H41=""),"",H41-G41+1) -> 59 | J41: Review | L41: Fees, automation and corridor claims are source-checked and not overstated — docs/Competitor-analysis.md; 9b9601b; T10
B42: BUS-04 | C42: BUS | D42: Pricing, unit economics, funding ask and beachhead approved | E42: Conrad, Mo | F42: Conrad | G42: 46188 | H42: 46246 | I42: =IF(OR(G42="",H42=""),"",H42-G42+1) -> 59 | J42: Review | L42: One assumption set is recorded and used consistently in deck and script — Financial model and customer research; C2–C4/M5/M8
B43: GOV-05 | C43: GOV | D43: Governance, decision, risk and blocker control maintained through submission | E43: Tamer, Dan | F43: Tamer | G43: 46182 | H43: 46248 | I43: =IF(OR(G43="",H43=""),"",H43-G43+1) -> 67 | J43: Doing | K43: All workstreams; T7, T8, D3 | L43: Daily critical-path update; decisions and variances reflected in all reports
A44: ◆ | B44: UX-04 | C44: UX | D44: /dashboard approved as the single recorded product route | E44: Mo, Dan | F44: Mo | G44: 46237 | H44: 46245 | I44: =IF(OR(G44="",H44=""),"",H44-G44+1) -> 9 | J44: Doing | K44: TEC-09; M1–M3 | L44: Overdue at 12 Aug: team decision, route allowlist, demo accounts and exact click path must be recorded; legacy/dev/admin navigation must be excluded
A45: ◆ | B45: UX-05 | C45: UX | D45: Demo polish, empty/error states and accessibility pass completed | E45: Mo | F45: Mo | G45: 46237 | H45: 46246 | I45: =IF(OR(G45="",H45=""),"",H45-G45+1) -> 10 | J45: Doing | K45: UX-04, TEC-09; M4 | L45: Recorded path has no broken/legacy navigation; key text and states are legible
A46: ◆ | B46: BUS-05 | C46: BUS | D46: Final real-value and commercial narrative locked | E46: Conrad, Mo, Tamer | F46: Conrad | G46: 46230 | H46: 46246 | I46: =IF(OR(G46="",H46=""),"",H46-G46+1) -> 17 | J46: Doing | K46: BUS-03, BUS-04; T2, T9 | L46: Problem, beachhead, differentiation, business model, evidence and ask use one approved story
A47: ◆ | B47: BUS-07 | C47: BUS | D47: Evidence-aligned BMC v2 approved for final pitch | E47: Conrad, Tamer, Mo, Badhri | F47: Conrad | G47: 46246 | H47: 46246 | I47: =IF(OR(G47="",H47=""),"",H47-G47+1) -> 1 | J47: Doing | K47: BUS-03, BUS-04, BUS-06; T2 | L47: Zero float: close before SUB-01 or remove unresolved BMC claims; narrow beachhead, financing distinction, minimum-plus-% fee and delivered/roadmap split required
A48: ◆ | B48: SUB-01 | C48: SUB | D48: Five-minute deck and timed script locked | E48: Tamer, all leads | F48: Tamer | G48: 46230 | H48: 46246 | I48: =IF(OR(G48="",H48=""),"",H48-G48+1) -> 17 | J48: Doing | K48: PRD-04, RISK-06, BUS-05; D4 | L48: Script is under five minutes and weights real value above technical detail
A49: ◆ | B49: SUB-02 | C49: SUB | D49: Deterministic demo runbook and seed/reset procedure completed | E49: Dan, Nick | F49: Dan | G49: 46237 | H49: 46246 | I49: =IF(OR(G49="",H49=""),"",H49-G49+1) -> 10 | J49: To Do | K49: TEC-09, UX-04; D4 | L49: Another member can reproduce the happy path without improvisation
A50: ● | B50: SUB-03 | C50: SUB | D50: Two cold end-to-end rehearsals completed | E50: Dan, Mo | F50: Dan | G50: 46244 | H50: 46247 | I50: =IF(OR(G50="",H50=""),"",H50-G50+1) -> 4 | J50: To Do | K50: SUB-01, SUB-02 | L50: Both runs complete within the timed allocation; defects and workarounds logged
A51: ● | B51: SUB-04 | C51: SUB | D51: Primary presentation recorded, edited and captioned | E51: Dan, Mo, Tamer | F51: Dan | G51: 46246 | H51: 46247 | I51: =IF(OR(G51="",H51=""),"",H51-G51+1) -> 2 | J51: To Do | K51: SUB-03 | L51: Final render is clear, below five minutes and uses approved product claims
A52: ● | B52: SUB-05 | C52: SUB | D52: Fallback demo recording retained | E52: Dan, Nick | F52: Dan | G52: 46246 | H52: 46247 | I52: =IF(OR(G52="",H52=""),"",H52-G52+1) -> 2 | J52: To Do | K52: SUB-02, TEC-09 | L52: Standalone fallback opens and shows the approved workflow
A53: ● | B53: SUB-06 | C53: SUB | D53: Video link, PDF and permission QA completed independently | E53: Tamer, independent checker (TBD) | F53: Tamer | G53: 46247 | H53: 46248 | I53: =IF(OR(G53="",H53=""),"",H53-G53+1) -> 2 | J53: To Do | K53: SUB-04, SUB-05 | L53: Link works in private browser; PDF renders; filename and permissions pass
A54: ● | B54: SUB-07 | C54: SUB | D54: Main group video submission completed | E54: Tamer | F54: Tamer | G54: 46248 | H54: 46248 | I54: =IF(OR(G54="",H54=""),"",H54-G54+1) -> 1 | J54: To Do | K54: SUB-06 | L54: Submission receipt and final artifacts preserved
...

Sheet Task Register
A1: Blockmediary — Controlled Task Register
A2: Auditable 12 August 2026 snapshot | Group work only | Authoritative sources: master project plan, Kanban and RACI v2.1
A4: CONTROLLED CARDS | D4: ACTIVE CARDS | G4: DONE | J4: AT ACCEPTANCE | M4: IN FLIGHT | P4: DEFERRED
A5: =COUNTA(A9:A60) -> 52 | D5: =COUNTIF(J9:J60,"<>Deferred") -> 44 | G5: =COUNTIF(J9:J60,"Done") -> 24 | J5: =COUNTIF(J9:J60,"Review") -> 8 | M5: =COUNTIF(J9:J60,"Doing") -> 6 | P5: =COUNTIF(J9:J60,"Deferred") -> 8
A8: Task ID | B8: Workstream | C8: Task / outcome | D8: Responsible owner(s) | E8: Accountable | F8: Baseline start | G8: Baseline finish | H8: Current due | I8: Duration (days) | J8: Status | K8: Progress | L8: Observed date | M8: Source timing | N8: Dependencies / aliases | O8: Acceptance and evidence | P8: Criticality | Q8: Overdue control | R8: Source report
A9: GOV-01 | B9: GOV | C9: Proposal handoff and assessed build gate established | D9: Tamer | E9: Tamer | F9: 46181 | G9: 46181 | I9: =IF(F9="","",IF(H9<>"",H9,G9)-F9+1) -> 1 | J9: Done | K9: =IFERROR(VLOOKUP(J9,'Milestones & Controls'!$A$39:$B$43,2,FALSE),0) -> 1 | L9: 46181 | M9: Planned: 8 Jun | Observed: 8 Jun | O9: Proposal artifact and fixed deadline retained — proposal/Pitch-Deck-June-8.pptx; T1 | Q9: =IF(OR(H9="",J9="Done",J9="Deferred"),"",IF(H9<DATE(2026,8,12),"OVERDUE",IF(H9=DATE(2026,8,12),"DUE",""))) | R9: Master Kanban — Done
A10: GOV-02 | B10: GOV | C10: Initial governance framework created | D10: Tamer, Dan | E10: Tamer | F10: 46182 | G10: 46189 | I10: =IF(F10="","",IF(H10<>"",H10,G10)-F10+1) -> 8 | J10: Done | K10: =IFERROR(VLOOKUP(J10,'Milestones & Controls'!$A$39:$B$43,2,FALSE),0) -> 1 | L10: 46190 | M10: Planned: 9–16 Jun | Observed: 17 Jun | O10: Kanban, Gantt and RACI committed — Commit 5c4daba; T7, T8, D3 | Q10: =IF(OR(H10="",J10="Done",J10="Deferred"),"",IF(H10<DATE(2026,8,12),"OVERDUE",IF(H10=DATE(2026,8,12),"DUE",""))) | R10: Master Kanban — Done
A11: GOV-03 | B11: GOV | C11: BRD v1.0 reconciled to delivered prototype | D11: Nick | E11: Tamer | F11: 46182 | G11: 46194 | I11: =IF(F11="","",IF(H11<>"",H11,G11)-F11+1) -> 13 | J11: Done | K11: =IFERROR(VLOOKUP(J11,'Milestones & Controls'!$A$39:$B$43,2,FALSE),0) -> 1 | L11: 46243 | M11: Planned: 9–21 Jun | Observed: 9 Aug | O11: Versioned BRD baseline exists — docs/business-requirements.md; 3b3e82e; T1 | Q11: =IF(OR(H11="",J11="Done",J11="Deferred"),"",IF(H11<DATE(2026,8,12),"OVERDUE",IF(H11=DATE(2026,8,12),"DUE",""))) | R11: Master Kanban — Done
A12: PRD-01 | B12: PRD | C12: End-to-end operating workflow documented | D12: Dan | E12: Dan | F12: 46182 | G12: 46194 | I12: =IF(F12="","",IF(H12<>"",H12,G12)-F12+1) -> 13 | J12: Done | K12: =IFERROR(VLOOKUP(J12,'Milestones & Controls'!$A$39:$B$43,2,FALSE),0) -> 1 | L12: 46198 | M12: Planned: 9–21 Jun | Observed: 25 Jun | O12: Happy path and verification layers documented — docs/Flow Guidance/operational-flow-v1.md; D1 | Q12: =IF(OR(H12="",J12="Done",J12="Deferred"),"",IF(H12<DATE(2026,8,12),"OVERDUE",IF(H12=DATE(2026,8,12),"DUE",""))) | R12: Master Kanban — Done
A13: PRD-02 | B13: PRD | C13: Deal, state and deterministic release rules implemented | D13: Nick, Dan | E13: Dan | F13: 46188 | G13: 46201 | I13: =IF(F13="","",IF(H13<>"",H13,G13)-F13+1) -> 14 | J13: Done | K13: =IFERROR(VLOOKUP(J13,'Milestones & Controls'!$A$39:$B$43,2,FALSE),0) -> 1 | L13: 46213 | M13: Planned: 15–28 Jun | Observed: 10 Jul | O13: app/lib/escrow/rules.ts contains 428 lines and grades DOC-01–DOC-06 using GRADE, CROSS and FLAG rule kinds; relevant application tests pass — Commit 73f1bf7; N4, D1 | Q13: =IF(OR(H13="",J13="Done",J13="Deferred"),"",IF(H13<DATE(2026,8,12),"OVERDUE",IF(H13=DATE(2026,8,12),"DUE",""))) | R13: Master Kanban — Done
A14: TEC-01 | B14: TEC | C14: Escrow smart contract implemented | D14: Nick, Dan | E14: Nick | F14: 46188 | G14: 46208 | I14: =IF(F14="","",IF(H14<>"",H14,G14)-F14+1) -> 21 | J14: Done | K14: =IFERROR(VLOOKUP(J14,'Milestones & Controls'!$A$39:$B$43,2,FALSE),0) -> 1 | L14: 46208 | M14: Planned: 15 Jun–5 Jul | Observed: 5 Jul | O14: contracts/contracts/Escrow.sol, tests and Ignition deployment module exist; forced compilation from source succeeds — 36222dd; N1 | Q14: =IF(OR(H14="",J14="Done",J14="Deferred"),"",IF(H14<DATE(2026,8,12),"OVERDUE",IF(H14=DATE(2026,8,12),"DUE",""))) | R14: Master Kanban — Done
A15: TEC-02 | B15: TEC | C15: Contract tests and unfunded cancellation path authored | D15: Dan | E15: Nick | F15: 46202 | G15: 46213 | I15: =IF(F15="","",IF(H15<>"",H15,G15)-F15+1) -> 12 | J15: Done | K15: =IFERROR(VLOOKUP(J15,'Milestones & Controls'!$A$39:$B$43,2,FALSE),0) -> 1 | L15: 46213 | M15: Planned: 29 Jun–10 Jul | Observed: 10 Jul | O15: Six test files cover happy path, access control, state guards, refund, release/pause and cancellation; 21/21 pass in the standard compiled run — 36222dd, a186f98; verified 12 Aug; N1 | Q15: =IF(OR(H15="",J15="Done",J15="Deferred"),"",IF(H15<DATE(2026,8,12),"OVERDUE",IF(H15=DATE(2026,8,12),"DUE",""))) | R15: Master Kanban — Done
A16: TEC-03 | B16: TEC | C16: Off-chain store, API and rule-engine core implemented | D16: Nick, Dan | E16: Nick | F16: 46195 | G16: 46222 | I16: =IF(F16="","",IF(H16<>"",H16,G16)-F16+1) -> 28 | J16: Done | K16: =IFERROR(VLOOKUP(J16,'Milestones & Controls'!$A$39:$B$43,2,FALSE),0) -> 1 | L16: 46213 | M16: Planned: 22 Jun–19 Jul | Observed: 10 Jul | O16: 28 API route handlers and the lifecycle/rules core exist — 73f1bf7, 6515a51; N2, N3, D5 | Q16: =IF(OR(H16="",J16="Done",J16="Deferred"),"",IF(H16<DATE(2026,8,12),"OVERDUE",IF(H16=DATE(2026,8,12),"DUE",""))) | R16: Master Kanban — Done
A17: TEC-04 | B17: TEC | C17: Buyer/seller lifecycle wired to real deal state | D17: Nick, Dan | E17: Nick | F17: 46209 | G17: 46222 | I17: =IF(F17="","",IF(H17<>"",H17,G17)-F17+1) -> 14 | J17: Done | K17: =IFERROR(VLOOKUP(J17,'Milestones & Controls'!$A$39:$B$43,2,FALSE),0) -> 1 | L17: 46216 | M17: Planned: 6–19 Jul | Observed: 13 Jul | O17: Fund, submit and verdict journeys merged — 06efff6, fcdfaad; N2, N3 | Q17: =IF(OR(H17="",J17="Done",J17="Deferred"),"",IF(H17<DATE(2026,8,12),"OVERDUE",IF(H17=DATE(2026,8,12),"DUE",""))) | R17: Master Kanban — Done
A18: TEC-05 | B18: TEC | C18: Objection, refund and audit paths implemented | D18: Dan | E18: Nick | F18: 46223 | G18: 46236 | I18: =IF(F18="","",IF(H18<>"",H18,G18)-F18+1) -> 14 | J18: Done | K18: =IFERROR(VLOOKUP(J18,'Milestones & Controls'!$A$39:$B$43,2,FALSE),0) -> 1 | L18: 46234 | M18: Planned: 20 Jul–2 Aug | Observed: 31 Jul | O18: Objection withdrawal, refund and audit commits exist — 5688cc3, 77cf5f6; N2, D5 | Q18: =IF(OR(H18="",J18="Done",J18="Deferred"),"",IF(H18<DATE(2026,8,12),"OVERDUE",IF(H18=DATE(2026,8,12),"DUE",""))) | R18: Master Kanban — Done
A19: TEC-06 | B19: TEC | C19: SQL persistence, account auth and SIWE implemented | D19: Dan, Nick | E19: Nick | F19: 46216 | G19: 46236 | I19: =IF(F19="","",IF(H19<>"",H19,G19)-F19+1) -> 21 | J19: Done | K19: =IFERROR(VLOOKUP(J19,'Milestones & Controls'!$A$39:$B$43,2,FALSE),0) -> 1 | L19: 46239 | M19: Planned: 13 Jul–2 Aug | Observed: 5 Aug | O19: Prisma persistence, server sessions and SIWE wallet linking are present; application suite passes — f8cc7a9, 3123538, a2052a2; N2, N3 | Q19: =IF(OR(H19="",J19="Done",J19="Deferred"),"",IF(H19<DATE(2026,8,12),"OVERDUE",IF(H19=DATE(2026,8,12),"DUE",""))) | R19: Master Kanban — Done
A20: TEC-07 | B20: TEC | C20: Base Sepolia deployment evidence created | D20: Dan | E20: Nick | F20: 46203 | G20: 46208 | I20: =IF(F20="","",IF(H20<>"",H20,G20)-F20+1) -> 6 | J20: Done | K20: =IFERROR(VLOOKUP(J20,'Milestones & Controls'!$A$39:$B$43,2,FALSE),0) -> 1 | L20: 46244 | M20: Planned: 30 Jun–5 Jul | Observed: 4 Aug deployment; 10 Aug merge | O20: Deployment record identifies Base Sepolia chain ID 84532 and real test USDC configuration — c4887db, 3e9b4ed; N1 | Q20: =IF(OR(H20="",J20="Done",J20="Deferred"),"",IF(H20<DATE(2026,8,12),"OVERDUE",IF(H20=DATE(2026,8,12),"DUE",""))) | R20: Master Kanban — Done
... A32: BUS-06 | B32: BUS | C32: Original Business Model Canvas produced | D32: Tamer, Conrad, Mo | E32: Conrad | F32: 46181 | G32: 46181 | I32: =IF(F32="","",IF(H32<>"",H32,G32)-F32+1) -> 1 | J32: Done | K32: =IFERROR(VLOOKUP(J32,'Milestones & Controls'!$A$39:$B$43,2,FALSE),0) -> 1 | L32: 46181 | M32: Planned: G0 handoff | Observed: 8 Jun baseline artifact | O32: Eight-block canvas exists with opportunity, market, revenue, cost, channels and competition — proposal/business-model-slide.md; T2 | Q32: =IF(OR(H32="",J32="Done",J32="Deferred"),"",IF(H32<DATE(2026,8,12),"OVERDUE",IF(H32=DATE(2026,8,12),"DUE",""))) | R32: Master Kanban — Done
A33: GOV-04 | B33: GOV | C33: TRD and A1–A8 acceptance baseline reconciled | D33: Nick | E33: Tamer | F33: 46188 | G33: 46201 | H33: 46246 | I33: =IF(F33="","",IF(H33<>"",H33,G33)-F33+1) -> 59 | J33: Review | K33: =IFERROR(VLOOKUP(J33,'Milestones & Controls'!$A$39:$B$43,2,FALSE),0) -> 0.85 | L33: 46245 | M33: Planned: 15–28 Jun | Observed: 11 Aug | O33: Run and record every acceptance case; remove any remaining delivered-status contradiction — docs/technical-requirements.md; 42aa948; T1 | P33: Zero float | Q33: =IF(OR(H33="",J33="Done",J33="Deferred"),"",IF(H33<DATE(2026,8,12),"OVERDUE",IF(H33=DATE(2026,8,12),"DUE",""))) -> DUE | R33: Master Kanban — Review
A34: PRD-03 | B34: PRD | C34: Full document-pack and corridor release rules aligned | D34: Nick, Badhri | E34: Dan | F34: 46195 | G34: 46208 | H34: 46246 | I34: =IF(F34="","",IF(H34<>"",H34,G34)-F34+1) -> 52 | J34: Review | K34: =IFERROR(VLOOKUP(J34,'Milestones & Controls'!$A$39:$B$43,2,FALSE),0) -> 0.85 | L34: 46243 | M34: Planned: 22 Jun–5 Jul | Observed: 9 Aug | O34: Cold test required documents and reconcile BRD language with implemented pack — 9e697cf, f9bbd27, 498751d; N4/B5 | P34: Zero float | Q34: =IF(OR(H34="",J34="Done",J34="Deferred"),"",IF(H34<DATE(2026,8,12),"OVERDUE",IF(H34=DATE(2026,8,12),"DUE",""))) -> DUE | R34: Master Kanban — Review
A35: PRD-04 | B35: PRD | C35: Final product-to-pitch traceability approved | D35: Dan, Tamer | E35: Dan | F35: 46230 | G35: 46245 | H35: 46246 | I35: =IF(F35="","",IF(H35<>"",H35,G35)-F35+1) -> 17 | J35: Review | K35: =IFERROR(VLOOKUP(J35,'Milestones & Controls'!$A$39:$B$43,2,FALSE),0) -> 0.85 | L35: 46245 | M35: Planned: 27 Jul–11 Aug | Observed: 11 Aug draft | O35: Every script claim maps to delivered evidence or roadmap label — BRD/TRD reconciliation; commit 42aa948; saved claims register still pending under DEC-13; T5 | P35: Zero float | Q35: =IF(OR(H35="",J35="Done",J35="Deferred"),"",IF(H35<DATE(2026,8,12),"OVERDUE",IF(H35=DATE(2026,8,12),"DUE",""))) -> DUE | R35: Master Kanban — Review
A36: TEC-09 | B36: TEC | C36: Technical acceptance A1–A8 completed | D36: Nick, Dan | E36: Nick | F36: 46237 | G36: 46245 | H36: 46246 | I36: =IF(F36="","",IF(H36<>"",H36,G36)-F36+1) -> 10 | J36: Review | K36: =IFERROR(VLOOKUP(J36,'Milestones & Controls'!$A$39:$B$43,2,FALSE),0) -> 0.85 | L36: 46246 | M36: Planned: 3–11 Aug | Observed: Partial on 12 Aug | O36: A1 achieved: forced source compile and 21/21 contract tests pass. Supporting evidence: 187/187 application tests pass. Open: A2–A7 integrated authenticated walkthrough, A8 control record, production build and lint — Test/compile evidence 12 Aug; TRD Section 11; N1–N4/D5 | P36: Zero float | Q36: =IF(OR(H36="",J36="Done",J36="Deferred"),"",IF(H36<DATE(2026,8,12),"OVERDUE",IF(H36=DATE(2026,8,12),"DUE",""))) -> DUE | R36: Master Kanban — Review
A37: TEC-10 | B37: TEC | C37: Repository sync and clean-build reproducibility verified | D37: Nick | E37: Nick | F37: 46244 | G37: 46246 | H37: 46246 | I37: =IF(F37="","",IF(H37<>"",H37,G37)-F37+1) -> 3 | J37: Review | K37: =IFERROR(VLOOKUP(J37,'Milestones & Controls'!$A$39:$B$43,2,FALSE),0) -> 0.85 | L37: 46246 | M37: Planned: 10–12 Aug | Observed: Failure confirmed 12 Aug | O37: Known failing: Prisma postinstall loads untracked app/.env; no app-level example exists; npm and pnpm lockfiles compete; production build and focused lint fail — Configuration/build/lint evidence 12 Aug; D3 | P37: Zero float | Q37: =IF(OR(H37="",J37="Done",J37="Deferred"),"",IF(H37<DATE(2026,8,12),"OVERDUE",IF(H37=DATE(2026,8,12),"DUE",""))) -> DUE | R37: Master Kanban — Review
A38: RISK-06 | B38: RISK | C38: Legal/compliance claims and delivery boundary signed off | D38: Badhri, Tamer | E38: Badhri | F38: 46237 | G38: 46246 | H38: 46246 | I38: =IF(F38="","",IF(H38<>"",H38,G38)-F38+1) -> 10 | J38: Review | K38: =IFERROR(VLOOKUP(J38,'Milestones & Controls'!$A$39:$B$43,2,FALSE),0) -> 0.85 | M38: Planned: 3–12 Aug | Observed: Research exists | O38: No legal-advice claim; live screening, TEA and examiner functions labelled roadmap — Legal and document sources; B1–B4 | P38: Zero float | Q38: =IF(OR(H38="",J38="Done",J38="Deferred"),"",IF(H38<DATE(2026,8,12),"OVERDUE",IF(H38=DATE(2026,8,12),"DUE",""))) -> DUE | R38: Master Kanban — Review
A39: BUS-03 | B39: BUS | C39: Competitor analysis verified for pitch use | D39: Badhri, Mo | E39: Mo | F39: 46188 | G39: 46208 | H39: 46246 | I39: =IF(F39="","",IF(H39<>"",H39,G39)-F39+1) -> 59 | J39: Review | K39: =IFERROR(VLOOKUP(J39,'Milestones & Controls'!$A$39:$B$43,2,FALSE),0) -> 0.85 | L39: 46238 | M39: Planned: 15 Jun–5 Jul | Observed: 4 Aug | O39: Fees, automation and corridor claims are source-checked and not overstated — docs/Competitor-analysis.md; 9b9601b; T10 | Q39: =IF(OR(H39="",J39="Done",J39="Deferred"),"",IF(H39<DATE(2026,8,12),"OVERDUE",IF(H39=DATE(2026,8,12),"DUE",""))) -> DUE | R39: Master Kanban — Review
A40: BUS-04 | B40: BUS | C40: Pricing, unit economics, funding ask and beachhead approved | D40: Conrad, Mo | E40: Conrad | F40: 46188 | G40: 46215 | H40: 46246 | I40: =IF(F40="","",IF(H40<>"",H40,G40)-F40+1) -> 59 | J40: Review | K40: =IFERROR(VLOOKUP(J40,'Milestones & Controls'!$A$39:$B$43,2,FALSE),0) -> 0.85 | M40: Planned: 15 Jun–12 Jul | Observed: Model/research exist | O40: One assumption set is recorded and used consistently in deck and script — Financial model and customer research; C2–C4/M5/M8 | Q40: =IF(OR(H40="",J40="Done",J40="Deferred"),"",IF(H40<DATE(2026,8,12),"OVERDUE",IF(H40=DATE(2026,8,12),"DUE",""))) -> DUE | R40: Master Kanban — Review
A41: GOV-05 | B41: GOV | C41: Governance, decision, risk and blocker control maintained through submission | D41: Tamer, Dan | E41: Tamer | F41: 46182 | G41: 46248 | H41: 46248 | I41: =IF(F41="","",IF(H41<>"",H41,G41)-F41+1) -> 67 | J41: Doing | K41: =IFERROR(VLOOKUP(J41,'Milestones & Controls'!$A$39:$B$43,2,FALSE),0) -> 0.55 | M41: Planned: 9 Jun–14 Aug | N41: All workstreams; T7, T8, D3 | O41: Daily critical-path update; decisions and variances reflected in all reports | Q41: =IF(OR(H41="",J41="Done",J41="Deferred"),"",IF(H41<DATE(2026,8,12),"OVERDUE",IF(H41=DATE(2026,8,12),"DUE",""))) | R41: Master Kanban — Doing
A42: UX-04 | B42: UX | C42: /dashboard approved as the single recorded product route | D42: Mo, Dan | E42: Mo | F42: 46237 | G42: 46243 | H42: 46245 | I42: =IF(F42="","",IF(H42<>"",H42,G42)-F42+1) -> 9 | J42: Doing | K42: =IFERROR(VLOOKUP(J42,'Milestones & Controls'!$A$39:$B$43,2,FALSE),0) -> 0.55 | M42: Planned: 3–9 Aug | N42: TEC-09; M1–M3 | O42: Overdue at 12 Aug: team decision, route allowlist, demo accounts and exact click path must be recorded; legacy/dev/admin navigation must be excluded | P42: Zero float | Q42: =IF(OR(H42="",J42="Done",J42="Deferred"),"",IF(H42<DATE(2026,8,12),"OVERDUE",IF(H42=DATE(2026,8,12),"DUE",""))) -> OVERDUE | R42: Master Kanban — Doing
A43: UX-05 | B43: UX | C43: Demo polish, empty/error states and accessibility pass completed | D43: Mo | E43: Mo | F43: 46237 | G43: 46246 | H43: 46246 | I43: =IF(F43="","",IF(H43<>"",H43,G43)-F43+1) -> 10 | J43: Doing | K43: =IFERROR(VLOOKUP(J43,'Milestones & Controls'!$A$39:$B$43,2,FALSE),0) -> 0.55 | M43: Planned: 3–12 Aug | N43: UX-04, TEC-09; M4 | O43: Recorded path has no broken/legacy navigation; key text and states are legible | P43: Zero float | Q43: =IF(OR(H43="",J43="Done",J43="Deferred"),"",IF(H43<DATE(2026,8,12),"OVERDUE",IF(H43=DATE(2026,8,12),"DUE",""))) -> DUE | R43: Master Kanban — Doing
A44: BUS-05 | B44: BUS | C44: Final real-value and commercial narrative locked | D44: Conrad, Mo, Tamer | E44: Conrad | F44: 46230 | G44: 46246 | H44: 46246 | I44: =IF(F44="","",IF(H44<>"",H44,G44)-F44+1) -> 17 | J44: Doing | K44: =IFERROR(VLOOKUP(J44,'Milestones & Controls'!$A$39:$B$43,2,FALSE),0) -> 0.55 | M44: Planned: 27 Jul–12 Aug | N44: BUS-03, BUS-04; T2, T9 | O44: Problem, beachhead, differentiation, business model, evidence and ask use one approved story | P44: Zero float | Q44: =IF(OR(H44="",J44="Done",J44="Deferred"),"",IF(H44<DATE(2026,8,12),"OVERDUE",IF(H44=DATE(2026,8,12),"DUE",""))) -> DUE | R44: Master Kanban — Doing
A45: BUS-07 | B45: BUS | C45: Evidence-aligned BMC v2 approved for final pitch | D45: Conrad, Tamer, Mo, Badhri | E45: Conrad | F45: 46246 | G45: 46246 | H45: 46246 | I45: =IF(F45="","",IF(H45<>"",H45,G45)-F45+1) -> 1 | J45: Doing | K45: =IFERROR(VLOOKUP(J45,'Milestones & Controls'!$A$39:$B$43,2,FALSE),0) -> 0.55 | M45: Planned: 12 Aug | N45: BUS-03, BUS-04, BUS-06; T2 | O45: Zero float: close before SUB-01 or remove unresolved BMC claims; narrow beachhead, financing distinction, minimum-plus-% fee and delivered/roadmap split required | P45: Zero float | Q45: =IF(OR(H45="",J45="Done",J45="Deferred"),"",IF(H45<DATE(2026,8,12),"OVERDUE",IF(H45=DATE(2026,8,12),"DUE",""))) -> DUE | R45: Master Kanban — Doing
A46: SUB-01 | B46: SUB | C46: Five-minute deck and timed script locked | D46: Tamer, all leads | E46: Tamer | F46: 46230 | G46: 46243 | H46: 46246 | I46: =IF(F46="","",IF(H46<>"",H46,G46)-F46+1) -> 17 | J46: Doing | K46: =IFERROR(VLOOKUP(J46,'Milestones & Controls'!$A$39:$B$43,2,FALSE),0) -> 0.55 | M46: Planned: 27 Jul–9 Aug | N46: PRD-04, RISK-06, BUS-05; D4 | O46: Script is under five minutes and weights real value above technical detail | P46: Zero float | Q46: =IF(OR(H46="",J46="Done",J46="Deferred"),"",IF(H46<DATE(2026,8,12),"OVERDUE",IF(H46=DATE(2026,8,12),"DUE",""))) -> DUE | R46: Master Kanban — Doing
A47: SUB-02 | B47: SUB | C47: Deterministic demo runbook and seed/reset procedure completed | D47: Dan, Nick | E47: Dan | F47: 46237 | G47: 46246 | H47: 46246 | I47: =IF(F47="","",IF(H47<>"",H47,G47)-F47+1) -> 10 | J47: To Do | K47: =IFERROR(VLOOKUP(J47,'Milestones & Controls'!$A$39:$B$43,2,FALSE),0) -> 0 | M47: Planned: 3–12 Aug | N47: TEC-09, UX-04; D4 | O47: Another member can reproduce the happy path without improvisation | P47: Zero float | Q47: =IF(OR(H47="",J47="Done",J47="Deferred"),"",IF(H47<DATE(2026,8,12),"OVERDUE",IF(H47=DATE(2026,8,12),"DUE",""))) -> DUE | R47: Master Kanban — To Do
A48: SUB-03 | B48: SUB | C48: Two cold end-to-end rehearsals completed | D48: Dan, Mo | E48: Dan | F48: 46244 | G48: 46247 | H48: 46247 | I48: =IF(F48="","",IF(H48<>"",H48,G48)-F48+1) -> 4 | J48: To Do | K48: =IFERROR(VLOOKUP(J48,'Milestones & Controls'!$A$39:$B$43,2,FALSE),0) -> 0 | M48: Planned: 10–13 Aug | N48: SUB-01, SUB-02 | O48: Both runs complete within the timed allocation; defects and workarounds logged | P48: Critical path | Q48: =IF(OR(H48="",J48="Done",J48="Deferred"),"",IF(H48<DATE(2026,8,12),"OVERDUE",IF(H48=DATE(2026,8,12),"DUE",""))) | R48: Master Kanban — To Do
A49: SUB-04 | B49: SUB | C49: Primary presentation recorded, edited and captioned | D49: Dan, Mo, Tamer | E49: Dan | F49: 46246 | G49: 46247 | H49: 46247 | I49: =IF(F49="","",IF(H49<>"",H49,G49)-F49+1) -> 2 | J49: To Do | K49: =IFERROR(VLOOKUP(J49,'Milestones & Controls'!$A$39:$B$43,2,FALSE),0) -> 0 | M49: Planned: 12–13 Aug | N49: SUB-03 | O49: Final render is clear, below five minutes and uses approved product claims | P49: Critical path | Q49: =IF(OR(H49="",J49="Done",J49="Deferred"),"",IF(H49<DATE(2026,8,12),"OVERDUE",IF(H49=DATE(2026,8,12),"DUE",""))) | R49: Master Kanban — To Do
A50: SUB-05 | B50: SUB | C50: Fallback demo recording retained | D50: Dan, Nick | E50: Dan | F50: 46246 | G50: 46247 | H50: 46247 | I50: =IF(F50="","",IF(H50<>"",H50,G50)-F50+1) -> 2 | J50: To Do | K50: =IFERROR(VLOOKUP(J50,'Milestones & Controls'!$A$39:$B$43,2,FALSE),0) -> 0 | M50: Planned: 12–13 Aug | N50: SUB-02, TEC-09 | O50: Standalone fallback opens and shows the approved workflow | P50: Critical path | Q50: =IF(OR(H50="",J50="Done",J50="Deferred"),"",IF(H50<DATE(2026,8,12),"OVERDUE",IF(H50=DATE(2026,8,12),"DUE",""))) | R50: Master Kanban — To Do
A51: SUB-06 | B51: SUB | C51: Video link, PDF and permission QA completed independently | D51: Tamer, independent checker (TBD) | E51: Tamer | F51: 46247 | G51: 46248 | H51: 46248 | I51: =IF(F51="","",IF(H51<>"",H51,G51)-F51+1) -> 2 | J51: To Do | K51: =IFERROR(VLOOKUP(J51,'Milestones & Controls'!$A$39:$B$43,2,FALSE),0) -> 0 | M51: Planned: 13–14 Aug | N51: SUB-04, SUB-05 | O51: Link works in private browser; PDF renders; filename and permissions pass | P51: Critical path | Q51: =IF(OR(H51="",J51="Done",J51="Deferred"),"",IF(H51<DATE(2026,8,12),"OVERDUE",IF(H51=DATE(2026,8,12),"DUE",""))) | R51: Master Kanban — To Do
A52: SUB-07 | B52: SUB | C52: Main group video submission completed | D52: Tamer | E52: Tamer | F52: 46248 | G52: 46248 | H52: 46248 | I52: =IF(F52="","",IF(H52<>"",H52,G52)-F52+1) -> 1 | J52: To Do | K52: =IFERROR(VLOOKUP(J52,'Milestones & Controls'!$A$39:$B$43,2,FALSE),0) -> 0 | M52: Planned: 14 Aug | N52: SUB-06 | O52: Submission receipt and final artifacts preserved | P52: Critical path | Q52: =IF(OR(H52="",J52="Done",J52="Deferred"),"",IF(H52<DATE(2026,8,12),"OVERDUE",IF(H52=DATE(2026,8,12),"DUE",""))) | R52: Master Kanban — To Do
A53: DEF-01 | B53: Deferred | C53: AI/OCR document extraction | I53: =IF(F53="","",IF(H53<>"",H53,G53)-F53+1) | J53: Deferred | K53: =IFERROR(VLOOKUP(J53,'Milestones & Controls'!$A$39:$B$43,2,FALSE),0) -> 0 | M53: Planned: not scheduled | O53: Not required for a credible deterministic prototype; delivered claim would be misleading — Extraction accuracy evaluation, failure handling and integrated acceptance | Q53: =IF(OR(H53="",J53="Done",J53="Deferred"),"",IF(H53<DATE(2026,8,12),"OVERDUE",IF(H53=DATE(2026,8,12),"DUE",""))) | R53: Master Kanban — Deferred / post-MVP
A54: DEF-02 | B54: Deferred | C54: Live KYC/KYB and sanctions providers | I54: =IF(F54="","",IF(H54<>"",H54,G54)-F54+1) | J54: Deferred | K54: =IFERROR(VLOOKUP(J54,'Milestones & Controls'!$A$39:$B$43,2,FALSE),0) -> 0 | M54: Planned: not scheduled | O54: Provider, jurisdiction and operational responsibilities are unresolved — Provider selection, contracts, test environment and compliance approval | Q54: =IF(OR(H54="",J54="Done",J54="Deferred"),"",IF(H54<DATE(2026,8,12),"OVERDUE",IF(H54=DATE(2026,8,12),"DUE",""))) | R54: Master Kanban — Deferred / post-MVP
...

Sheet Milestones & Controls
A1: Blockmediary — Milestones & Controls
A2: Submission gates, acceptance conditions, unresolved blockers and workbook-control notes | Honest pre-remediation snapshot at 12 August 2026
A4: MILESTONE GATES
A5: Gate date | B5: Milestone | C5: Accountable | D5: Acceptance condition | E5: Current evidence | F5: Status | G5: Variance / control | H5: Marker
A6: 46181 | B6: Proposal handoff | C6: Tamer | D6: Proposal evidence retained and assessed build window opened | E6: proposal/Pitch-Deck-June-8.pptx retained | F6: Done | G6: On baseline | H6: ◆
A7: 46238 | B7: Base Sepolia deployment evidence | C7: Nick | D7: Deployment address, network and chain evidence retained | E7: Base Sepolia chain ID 84532; deployment record dated 4 Aug | F7: Done | G7: Deployment evidence achieved; integration merge 10 Aug | H7: ◆
A8: 46245 | B8: Scope and demo-route freeze | C8: Tamer | D8: Approved /dashboard route, allowlist and exact click path | E8: Canonical route decision not formally recorded | F8: Overdue | G8: Zero float at status date | H8: ◆
A9: 46246 | B9: Acceptance and claim freeze | C9: Nick / Tamer | D9: A1–A8, build/lint, BMC and domain claims accepted | E9: A1 achieved; A2–A8, build/lint and domain approvals remain open | F9: At risk / Partial | G9: DEL-05 at risk; do not report remediation complete | H9: ◆
A10: 46247 | B10: Recording package | C10: Dan | D10: Two cold rehearsals, primary recording and fallback retained | E10: Not evidenced at status date | F10: To Do | G10: Depends on accepted runbook and claim freeze | H10: ◆
A11: 46248 | B11: Main group submission | C11: Tamer | D11: Link, PDF and permissions independently checked; receipt retained | E11: Future at status date | F11: To Do | G11: Fixed assessment deadline | H11: ◆
A14: CURRENT TECHNICAL AND GOVERNANCE CONTROLS
A15: Control | B15: State | C15: Owner | D15: Evidence at 12 Aug | E15: Open requirement | F15: Impact | G15: Related task / risk | H15: Truth boundary
A16: DEL-05 Technical acceptance baseline | B16: At risk | C16: Nick | D16: A1 achieved; 187/187 app tests support delivered behaviour | E16: Complete A2–A7 walkthrough, A8 control record, clean setup, build and lint | F16: Recording readiness not accepted | G16: DEL-05 / TEC-09 / TEC-10 | H16: Partially achieved only
A17: R-01 Integrated acceptance / reproducibility | B17: Confirmed | C17: Nick | D17: Clean setup/build failures reproduced | E17: Restore reproducibility and integrated evidence | F17: High | G17: R-01 | H17: Confirmed risk remains open
A18: R-08 Cross-machine repository state | B18: Confirmed | C18: Nick | D18: Untracked app/.env dependency; no app example; npm/pnpm locks compete | E18: Correct bootstrap and verify fresh dependency-free checkout | F18: High | G18: R-08 / TEC-10 | H18: Confirmed risk remains open
A19: Contract forced source rebuild | B19: Pass | C19: Nick | D19: solc 0.8.28 forced rebuild; 21/21 tests passed | E19: Retain evidence; does not close app clean-install gate | F19: A1 achieved | G19: TEC-09 | H19: Contract evidence passed
A20: Application unit tests | B20: Pass | C20: Nick | D20: 187/187 tests across 10/10 files | E20: Integrated authenticated walkthrough still required | F20: Supporting evidence | G20: TEC-09 | H20: Tests do not equal full acceptance
A21: Clean installation | B21: Open / Fail | C21: Nick | D21: Prisma postinstall expects untracked app/.env | E21: Add reproducible environment bootstrap and select package manager | F21: High | G21: TEC-10 | H21: Do not mark complete
A22: Production build | B22: Open / Fail | C22: Nick | D22: TypeScript rejected invalid named page export | E22: Correct source and rerun from clean setup | F22: High | G22: TEC-10 | H22: Do not mark complete
A23: Focused source lint | B23: Open / Fail | C23: Nick | D23: 5 errors and 12 warnings | E23: Fix source errors; keep generated output excluded separately | F23: Medium | G23: TEC-09 / TEC-10 | H23: Do not mark complete
A24: Independent walkthrough | B24: Open | C24: Nick / Dan | D24: A2–A7 integrated authenticated run not fully evidenced | E24: Run and record accepted A1–A8 control sequence | F24: High | G24: TEC-09 / SUB-02 | H24: SUB-02 remains To Do
A27: WORKBOOK CONTROL NOTES
A28: 1 | B28: Snapshot is honest as at 12 August 2026 before technical remediation.
A29: 2 | B29: Scope begins at proposal handoff on 8 June and ends at the second group submission on 14 August; individual-assignment work is excluded.
A30: 3 | B30: The Master Gantt uses reconstructed baseline start dates. Active rows extend to their explicit current due dates; the Task Register retains baseline finish and observed timing separately.
A31: 4 | B31: Deferred items are grey, unscheduled and excluded from active completion. No dates have been invented for DEF-01–DEF-08.
A32: 5 | B32: Active completion = Done divided by all non-deferred cards. It is a task-state indicator, not a submission-readiness score.
A33: 6 | B33: Critical-path flags follow the plan's remaining chain. Zero-float flags identify open chain tasks due on or before the 12 August status date.
A34: 7 | B34: The obsolete M0–M8 Gantt is excluded. The controlled IDs are GOV-, PRD-, TEC-, UX-, RISK-, BUS-, SUB- and DEF- rows from the v2.1 Kanban.
A35: 8 | B35: Technical remediation statuses are unchanged: TEC-09 and TEC-10 remain Review; SUB-02 remains To Do; DEL-05 remains at risk.
A38: STATUS PROGRESS MAPPING | E38: STATUS LEGEND
A39: Done | B39: 1 | C39: Task-level acceptance evidence exists | E39: Done | F39: Accepted
A40: Review | B40: 0.85 | C40: Artifact exists; acceptance or sign-off remains | E40: Review | F40: Acceptance open
A41: Doing | B41: 0.55 | C41: Active critical-path work | E41: Doing | F41: Active
A42: To Do | B42: 0 | C42: Defined and ready | E42: To Do | F42: Ready
A43: Deferred | B43: 0 | C43: Outside assessed MVP | E43: Deferred | F43: No schedule
